Workbook

Sheet PRINTING
B1: INVENTORY REPORT
B2: AS OF JULY 2026
B3: PRINTING
B5: SHELF NO. | C5: SHELF DESCRIPTION | D5: BARCODE/ CONTROL NUMBER | E5: PRODUCT NAME | F5: UNIT COST | G5: QUANTITY PER RECORD / ACCPOS | H5: ACTUAL INVENTORY | I5: TOTAL COST - RECORD | J5: TOTAL COST - ACTUAL INVENTORY | K5: VARIANCE - QUANTITY | L5: VARIANCE - COST | M5: REMARKS / CAUSE OF VARIANCE
B6: 20 | C6: OFFICE SUPPLIES | D6: 70002 | E6: PRINTING ADRITE RIBBON INK MEDIUM/BLACK | F6: 13.50 | G6: 253 | H6: 253 | I6: =F6*G6 -> 3415.5 | J6: =F6*H6 -> 3415.5 | K6: =G6-H6 -> 0 | L6: =I6-J6 -> 0
B7: 20 | C7: OFFICE SUPPLIES | D7: 70180 | E7: PRINTING ADVENTURE PLASTIC ENVELOPE LONG | F7: 18.00 | G7: 53 | H7: 53 | I7: =F7*G7 -> 954 | J7: =F7*H7 -> 954 | K7: =G7-H7 -> 0 | L7: =I7-J7 -> 0
B8: 20 | C8: OFFICE SUPPLIES | D8: 70181 | E8: PRINTING ADVENTURE PLASTIC ENVELOPE W/ HANDLE LONG | F8: 45.00 | G8: 4 | H8: 4 | I8: =F8*G8 -> 180 | J8: =F8*H8 -> 180 | K8: =G8-H8 -> 0 | L8: =I8-J8 -> 0
B9: 20 | C9: OFFICE SUPPLIES | D9: 70003 | E9: PRINTING ARTLINE HIGHLIGHTER ORANGE | F9: 30.00 | G9: 5 | H9: 5 | I9: =F9*G9 -> 150 | J9: =F9*H9 -> 150 | K9: =G9-H9 -> 0 | L9: =I9-J9 -> 0
B10: 20 | C10: OFFICE SUPPLIES | D10: 70006 | E10: PRINTING ASIAN COLOR BONDPAPER BLUE SHORT | F10: 120.00 | G10: 5 | H10: 5 | I10: =F10*G10 -> 600 | J10: =F10*H10 -> 600 | K10: =G10-H10 -> 0 | L10: =I10-J10 -> 0
B11: 20 | C11: OFFICE SUPPLIES | D11: 70007 | E11: PRINTING ASIAN COLOR BONDPAPER PINK SHORT | F11: 120.00 | G11: 3 | H11: 3 | I11: =F11*G11 -> 360 | J11: =F11*H11 -> 360 | K11: =G11-H11 -> 0 | L11: =I11-J11 -> 0
B12: 20 | C12: OFFICE SUPPLIES | D12: 70212 | E12: PRINTING ASKI MPC BOD & GA TARPAULIN 1.5X2FT | F12: 36.00 | G12: 2 | H12: 2 | I12: =F12*G12 -> 72 | J12: =F12*H12 -> 72 | K12: =G12-H12 -> 0 | L12: =I12-J12 -> 0
B13: 20 | C13: OFFICE SUPPLIES | D13: 70008 | E13: PRINTING ASSORTED PLASTIC SLIDING FOLDER LONG | F13: 4.00 | G13: 27 | H13: 27 | I13: =F13*G13 -> 108 | J13: =F13*H13 -> 108 | K13: =G13-H13 -> 0 | L13: =I13-J13 -> 0
B14: 20 | C14: OFFICE SUPPLIES | D14: 70009 | E14: PRINTING ASSORTED PLASTIC SLIDING FOLDER SHORT | F14: 3.75 | G14: 68 | H14: 68 | I14: =F14*G14 -> 255 | J14: =F14*H14 -> 255 | K14: =G14-H14 -> 0 | L14: =I14-J14 -> 0
B15: 20 | C15: OFFICE SUPPLIES | D15: 70278 | E15: PRINTING BALIK TANGKILIK CARD | F15: 105.00 | G15: 157 | H15: 157 | I15: =F15*G15 -> 16485 | J15: =F15*H15 -> 16485 | K15: =G15-H15 -> 0 | L15: =I15-J15 -> 0
B16: 20 | C16: OFFICE SUPPLIES | D16: 70010 | E16: PRINTING BALLPEN HBW GREEN | F16: 3.50 | G16: 55 | H16: 55 | I16: =F16*G16 -> 192.5 | J16: =F16*H16 -> 192.5 | K16: =G16-H16 -> 0 | L16: =I16-J16 -> 0
B17: 20 | C17: OFFICE SUPPLIES | D17: 70011 | E17: PRINTING BALLPEN HBW MATRIX BLUE | F17: 3.50 | G17: 1 | H17: 1 | I17: =F17*G17 -> 3.5 | J17: =F17*H17 -> 3.5 | K17: =G17-H17 -> 0 | L17: =I17-J17 -> 0
... B116: 20 | C116: OFFICE SUPPLIES | D116: 70176 | E116: PRINTING FORMS PERFECT PRINT LONG | F116: 167.80 | G116: 8 | H116: 8 | I116: =F116*G116 -> 1342.4 | J116: =F116*H116 -> 1342.4 | K116: =G116-H116 -> 0 | L116: =I116-J116 -> 0
B117: 20 | C117: OFFICE SUPPLIES | D117: 70175 | E117: PRINTING FORMS PERFECT PRINT LONG B2B | F117: 167.80 | G117: 8 | H117: 8 | I117: =F117*G117 -> 1342.4 | J117: =F117*H117 -> 1342.4 | K117: =G117-H117 -> 0 | L117: =I117-J117 -> 0
B118: 20 | C118: OFFICE SUPPLIES | D118: 70239 | E118: PRINTING FRAME 12X9 | F118: 180.00 | G118: 1 | H118: 1 | I118: =F118*G118 -> 180 | J118: =F118*H118 -> 180 | K118: =G118-H118 -> 0 | L118: =I118-J118 -> 0
B119: 20 | C119: OFFICE SUPPLIES | D119: 70238 | E119: PRINTING FRAME 18X24 | F119: 700.00 | G119: 1 | H119: 1 | I119: =F119*G119 -> 700 | J119: =F119*H119 -> 700 | K119: =G119-H119 -> 0 | L119: =I119-J119 -> 0
B120: 20 | C120: OFFICE SUPPLIES | D120: 70090 | E120: PRINTING FULLMARK INK FILM | F120: 400.00 | G120: 1 | H120: 1 | I120: =F120*G120 -> 400 | J120: =F120*H120 -> 400 | K120: =G120-H120 -> 0 | L120: =I120-J120 -> 0
B121: 20 | C121: OFFICE SUPPLIES | D121: 70306 | E121: PRINTING GATOR CORRECTION TAPE | F121: 24.00 | G121: 147 | H121: 147 | I121: =F121*G121 -> 3528 | J121: =F121*H121 -> 3528 | K121: =G121-H121 -> 0 | L121: =I121-J121 -> 0
B122: 20 | C122: OFFICE SUPPLIES | D122: 70091 | E122: PRINTING GATOR RUBBERBOND | F122: 20.00 | G122: 30 | H122: 30 | I122: =F122*G122 -> 600 | J122: =F122*H122 -> 600 | K122: =G122-H122 -> 0 | L122: =I122-J122 -> 0
B123: 20 | C123: OFFICE SUPPLIES | D123: 70092 | E123: PRINTING GOLDEN LION RUBBERBOND | F123: 4.50 | G123: 1 | H123: 1 | I123: =F123*G123 -> 4.5 | J123: =F123*H123 -> 4.5 | K123: =G123-H123 -> 0 | L123: =I123-J123 -> 0
B124: 20 | C124: OFFICE SUPPLIES | D124: 70283 | E124: PRINTING HBW MATRIX BLACK | F124: 6.00 | G124: 1 | H124: 1 | I124: =F124*G124 -> 6 | J124: =F124*H124 -> 6 | K124: =G124-H124 -> 0 | L124: =I124-J124 -> 0
B125: 20 | C125: OFFICE SUPPLIES | D125: 70320 | E125: PRINTING HBW MATRIX BLACK - 2 | F125: 6.50 | G125: 1440 | H125: 1434 | I125: =F125*G125 -> 9360 | J125: =F125*H125 -> 9321 | K125: =G125-H125 -> 6 | L125: =I125-J125 -> 39
B126: 20 | C126: OFFICE SUPPLIES | D126: 70093 | E126: PRINTING HBW STAMP PAD INK - RED | F126: 17.00 | G126: 9 | H126: 9 | I126: =F126*G126 -> 153 | J126: =F126*H126 -> 153 | K126: =G126-H126 -> 0 | L126: =I126-J126 -> 0
B127: 20 | C127: OFFICE SUPPLIES | D127: 70143 | E127: PRINTING HEAVY DUTY PUNCHER | F127: 150.00 | G127: 14 | H127: 14 | I127: =F127*G127 -> 2100 | J127: =F127*H127 -> 2100 | K127: =G127-H127 -> 0 | L127: =I127-J127 -> 0
B128: 20 | C128: OFFICE SUPPLIES | D128: 70198 | E128: PRINTING INTERMEDIATE PAD | F128: 18.00 | G128: 150 | H128: 150 | I128: =F128*G128 -> 2700 | J128: =F128*H128 -> 2700 | K128: =G128-H128 -> 0 | L128: =I128-J128 -> 0
B129: 20 | C129: OFFICE SUPPLIES | D129: 70260 | E129: PRINTING JACKET BURDA NAME ONLY | F129: 100.00 | G129: 1 | H129: 1 | I129: =F129*G129 -> 100 | J129: =F129*H129 -> 100 | K129: =G129-H129 -> 0 | L129: =I129-J129 -> 0
... B139: 20 | C139: OFFICE SUPPLIES | D139: 70102 | E139: PRINTING LAMINATING FILM SEAL PLUS | F139: 95.00 | G139: 2 | H139: 2 | I139: =F139*G139 -> 190 | J139: =F139*H139 -> 190 | K139: =G139-H139 -> 0 | L139: =I139-J139 -> 0
B140: 20 | C140: OFFICE SUPPLIES | D140: 70292 | E140: PRINTING MAAM ISING RED & VIOLET T-SHIRT W/ DTF PRINT | F140: 146.67 | G140: 12 | H140: 12 | I140: =F140*G140 -> 1760.04 | J140: =F140*H140 -> 1760.04 | K140: =G140-H140 -> 0 | L140: =I140-J140 -> 0 | M140: 10 FOR PUNCH
B141: 20 | C141: OFFICE SUPPLIES | D141: 70103 | E141: PRINTING MAGIC TOUCH NOTEBOOK | F141: 9.00 | G141: 17 | H141: 17 | I141: =F141*G141 -> 153 | J141: =F141*H141 -> 153 | K141: =G141-H141 -> 0 | L141: =I141-J141 -> 0
B142: 20 | C142: OFFICE SUPPLIES | D142: 70104 | E142: PRINTING MAGIC TOUCH NOTEBOOK GRADE 1 | F142: 9.00 | G142: 17 | H142: 17 | I142: =F142*G142 -> 153 | J142: =F142*H142 -> 153 | K142: =G142-H142 -> 0 | L142: =I142-J142 -> 0
B143: 20 | C143: OFFICE SUPPLIES | D143: 70105 | E143: PRINTING MARVY HIGHLIGHTER | F143: 25.00 | G143: 25 | H143: 25 | I143: =F143*G143 -> 625 | J143: =F143*H143 -> 625 | K143: =G143-H143 -> 0 | L143: =I143-J143 -> 0
B144: 20 | C144: OFFICE SUPPLIES | D144: 70106 | E144: PRINTING MASKING TAPE | F144: 21.00 | G144: 171 | H144: 171 | I144: =F144*G144 -> 3591 | J144: =F144*H144 -> 3591 | K144: =G144-H144 -> 0 | L144: =I144-J144 -> 0
B145: 20 | C145: OFFICE SUPPLIES | D145: 70107 | E145: PRINTING MATHEMATICS NOTEBOOK | F145: 17.50 | G145: 1 | H145: 1 | I145: =F145*G145 -> 17.5 | J145: =F145*H145 -> 17.5 | K145: =G145-H145 -> 0 | L145: =I145-J145 -> 0
B146: 20 | C146: OFFICE SUPPLIES | D146: 70233 | E146: PRINTING MBA MUG WITH UV STICKER | F146: 121.95 | G146: 2 | H146: 2 | I146: =F146*G146 -> 243.9 | J146: =F146*H146 -> 243.9 | K146: =G146-H146 -> 0 | L146: =I146-J146 -> 0
B147: 20 | C147: OFFICE SUPPLIES | D147: 70279 | E147: PRINTING MFI PASSBOOK W/ COVER | F147: 23.00 | G147: 2500 | H147: 2500 | I147: =F147*G147 -> 57500 | J147: =F147*H147 -> 57500 | K147: =G147-H147 -> 0 | L147: =I147-J147 -> 0
B148: 20 | C148: OFFICE SUPPLIES | D148: 70108 | E148: PRINTING MIMEO PAPER UNIVERSAL GROUND BONDPAPER | F148: 90.00 | G148: 17 | H148: 17 | I148: =F148*G148 -> 1530 | J148: =F148*H148 -> 1530 | K148: =G148-H148 -> 0 | L148: =I148-J148 -> 0
...

Sheet VB-3
A1: VARIANCE BREAKDOWN (PRINTING)
A2: =PRINTING!B2 -> AS OF JULY 2026
B3: OVER
B4: BARCODE/ CONTROL NUMBER | C4: PRODUCT NAME | D4: UNIT COST | E4: QUANTITY PER RECORD / ACCPOS | F4: ACTUAL INVENTORY | G4: TOTAL COST - RECORD | H4: TOTAL COST - ACTUAL INVENTORY | I4: VARIANCE - QUANTITY | J4: VARIANCE - COST
B5: 70329 | C5: PRINTING BONUS BOND SHORT-2 | D5: 81.00 | E5: 296 | F5: 300 | G5: 23976 | H5: 24300 | I5: -4 | J5: -324
B6: 70016 | C6: PRINTING BONUS LONG | D6: 99.30 | E6: 79 | F6: 90 | G6: 7844.7 | H6: 8937 | I6: -11 | J6: -1092.3
B7: 70017 | C7: PRINTING BONUS SHORT | D7: 84.00 | E7: 110 | F7: 113 | G7: 9240 | H7: 9492 | I7: -3 | J7: -252
B8: 70327 | C8: PRINTING BROWN ENVELOPE - LONG (NEW) | D8: 4.00 | E8: 1990 | F8: 2000 | G8: 7960 | H8: 8000 | I8: -10 | J8: -40
B9: 70018 | C9: PRINTING BROWN ENVELOPE LONG | D9: 4.00 | E9: 748 | F9: 750 | G9: 2992 | H9: 3000 | I9: -2 | J9: -8
B10: 70170 | C10: PRINTING CLIENTS ID | D10: 1.50 | E10: 3650 | F10: 4000 | G10: 5475 | H10: 6000 | I10: -350 | J10: -525
B11: 70066 | C11: PRINTING EXPANDING FOLDER GREEN SHORT | D11: 14.50 | E11: 223 | F11: 226 | G11: 3233.5 | H11: 3277 | I11: -3 | J11: -43.5
B12: 70085 | C12: PRINTING FOLDER LONG WHITE | D12: 2.70 | E12: 2149 | F12: 2630 | G12: 5802.3 | H12: 7101 | I12: -481 | J12: -1298.7
B13: 70088 | C13: PRINTING FOLDER SHORT WHITE | D13: 2.80 | E13: 3176 | F13: 3213 | G13: 8892.8 | H13: 8996.4 | I13: -37 | J13: -103.6
B14: 70110 | C14: PRINTING MY GEL REFILL 0.5 | D14: 15.00 | E14: 84 | F14: 98 | G14: 1260 | H14: 1470 | I14: -14 | J14: -210
B15: 70114 | C15: PRINTING OFFICE PRO A4 | D15: 145.00 | E15: 64 | F15: 76 | G15: 9280 | H15: 11020 | I15: -12 | J15: -1740
B16: 70124 | C16: PRINTING PERFECT PRINT SHORT | D16: 126.00 | E16: 49 | F16: 60 | G16: 6174 | H16: 7560 | I16: -11 | J16: -1386
B17: 70127 | C17: PRINTING PILOT MARKER BLACK | D17: 35.75 | E17: 45 | F17: 46 | G17: 1608.75 | H17: 1644.5 | I17: -1 | J17: -35.75
B18: 70131 | C18: PRINTING PILOT WYTEBOARD MARKER BLACK | D18: 55.25 | E18: 80 | F18: 81 | G18: 4420 | H18: 4475.25 | I18: -1 | J18: -55.25
B19: 70168 | C19: PRINTING WORX BONDPAPER LONG | D19: 32.00 | E19: 18 | F19: 19 | G19: 576 | H19: 608 | I19: -1 | J19: -32
B20: 70169 | C20: PRINTING WORX BONDPAPER SHORT | D20: 34.00 | E20: 92 | F20: 94 | G20: 3128 | H20: 3196 | I20: -2 | J20: -68
E21: =SUM(E5:E20) -> 49 | F21: =SUM(F5:F20) -> 13796 | G21: =SUM(G5:G20) -> 101863.05 | H21: =SUM(H5:H20) -> 109077.15 | I21: =SUM(I5:I20) -> -943 | J21: =SUM(J5:J20) -> -7214.1
B23: RETURN
B24: BARCODE | C24: PRODUCT NAME | D24: UNIT COST | G24: REMARKS / CAUSE OF VARIANCE
G26: =SUM(G25:G25) -> 0
B27: SHORT
B28: BARCODE/ CONTROL NUMBER | C28: PRODUCT NAME | D28: UNIT COST | E28: QUANTITY PER RECORD / ACCPOS | F28: ACTUAL INVENTORY | G28: TOTAL COST - RECORD | H28: TOTAL COST - ACTUAL INVENTORY | I28: VARIANCE - QUANTITY | J28: VARIANCE - COST | K28: SRP | L28: VARIANCE - COST
B29: 70073 | C29: PRINTING EXPANDING FOLDER ROYAL BLUE LONG | D29: 14.50 | E29: 67 | F29: 66 | G29: 971.5 | H29: 957 | I29: 1 | J29: 14.5 | K29: 20 | L29: =I29*K29 -> 20
B30: 70320 | C30: PRINTING HBW MATRIX BLACK - 2 | D30: 6.50 | E30: 1440 | F30: 1434 | G30: 9360 | H30: 9321 | I30: 6 | J30: 39 | K30: 10 | L30: =I30*K30 -> 60
E31: =SUM(E29:E30) -> 0 | F31: =SUM(F29:F30) -> 1500 | G31: =SUM(G29:G30) -> 10331.5 | H31: =SUM(H29:H30) -> 10278 | I31: =SUM(I29:I30) -> 7 | J31: =SUM(J29:J30) -> 53.5 | K31: =SUM(K29:K30) -> 30 | L31: =SUM(L29:L30) -> 80
B34: SHORT
B35: BARCODE | C35: PRODUCT NAME | D35: SRP | E35: QUANTITY PER RECORD / ACCPOS | F35: ACTUAL INVENTORY | G35: VARIANCE - QUANTITY | H35: VARIANCE - COST | I35: REMARKS / CAUSE OF VARIANCE
G39: =SUM(G36:G38) -> 0 | H39: =SUM(H36:H38) -> 0

Sheet CONVIE - final
B1: INVENTORY REPORT
B2: =PRINTING!B2 -> AS OF JULY 2026
B3: COOP STORE
U4: STORE | W4: BODEGA 1 | Y4: BODEGA 2 | AA4: BO - COUNTER | AD4: EXPIRED
B5: SHELF NO. | C5: SHELF DESCRIPTION | D5: BARCODE | E5: PRODUCT NAME | F5: UNIT COST | G5: Actual Count JUNE 2026 | H5: RETAIL | I5: PURCHASES | J5: PULL OUT | K5: SALES | L5: TOTAL | M5: ACTUAL INVENTORY | N5: TOTAL COST - RECORD | O5: TOTAL COST - ACTUAL INVENTORY | P5: VARIANCE - QUANTITY | Q5: VARIANCE - COST | R5: REMARKS / CAUSE OF VARIANCE | U5: QTY | V5: REMARKS | W5: QTY | X5: REMARKS | Y5: QTY | Z5: REMARKS | AA5: QTY | AB5: REMARKS | AD5: QTY | AE5: AMOUNT
B6: 1 | C6: CHIPS & SNACK | D6: 4800631001928 | E6: BOY BAWANG ASSORTED NUTS 85G | F6: 18.53 | G6: 1 | K6: 1 | L6: =G6+I6-J6-K6+H6 -> 0 | N6: =F6*L6 -> 0 | O6: =M6*F6 -> 0 | P6: =L6-M6 -> 0 | Q6: =N6-O6 -> 0 | S6: =U6+Y6+W6+AA6 -> 5 | T6: =M6-S6 -> -5 | U6: 5
B7: 1 | C7: CHIPS & SNACK | D7: 4800631001928 | E7: BOY BAWANG ASSORTED NUTS 85G | F7: 19.1 | I7: 40 | K7: 15 | L7: =G7+I7-J7-K7+H7 -> 25 | M7: 25 | N7: =F7*L7 -> 477.5 | O7: =M7*F7 -> 477.5 | P7: =L7-M7 -> 0 | Q7: =N7-O7 -> 0 | S7: =U7+Y7+W7+AA7 -> 5 | T7: =M7-S7 -> 20 | U7: 5
B8: 1 | C8: CHIPS & SNACK | D8: 4809011 681392 | E8: BOY BAWANG CHILI CHEESE 100G | F8: 16.03 | G8: 15 | K8: 3 | L8: =G8+I8-J8-K8+H8 -> 12 | M8: 12 | N8: =F8*L8 -> 192.36 | O8: =M8*F8 -> 192.36 | P8: =L8-M8 -> 0 | Q8: =N8-O8 -> 0 | S8: =U8+Y8+W8+AA8 -> 26 | T8: =M8-S8 -> -14 | U8: 26
B9: 1 | C9: CHIPS & SNACK | D9: 4809011681095 | E9: BOY BAWANG CORNICK ADOBO 100G | F9: 16.03 | G9: 12 | K9: 5 | L9: =G9+I9-J9-K9+H9 -> 7 | M9: =5+2 -> 7 | N9: =F9*L9 -> 112.21 | O9: =M9*F9 -> 112.21 | P9: =L9-M9 -> 0 | Q9: =N9-O9 -> 0 | S9: =U9+Y9+W9+AA9 -> 23 | T9: =M9-S9 -> -16 | U9: 23
B10: 1 | C10: CHIPS & SNACK | D10: 4809011681507 | E10: BOY BAWANG CORNICK BBQ FLAVOR 100G | F10: 16.84 | G10: 65 | K10: 3 | L10: =G10+I10-J10-K10+H10 -> 62 | M10: =27+35 -> 62 | N10: =F10*L10 -> 1044.08 | O10: =M10*F10 -> 1044.08 | P10: =L10-M10 -> 0 | Q10: =N10-O10 -> 0 | S10: =U10+Y10+W10+AA10 -> 33 | T10: =M10-S10 -> 29 | U10: 33
B11: 1 | C11: CHIPS & SNACK | D11: 4800631681311 | E11: BOY BAWANG CORNICK LECHON MANOK FLAVOR | F11: 16.03 | G11: 24 | K11: 1 | L11: =G11+I11-J11-K11+H11 -> 23 | M11: 23 | N11: =F11*L11 -> 368.69 | O11: =M11*F11 -> 368.69 | P11: =L11-M11 -> 0 | Q11: =N11-O11 -> 0 | S11: =U11+Y11+W11+AA11 -> 27 | T11: =M11-S11 -> -4 | U11: 27
B12: 1 | C12: CHIPS & SNACK | D12: 4800631000419 | E12: BOY BAWANG CRACKER NUTS 85G | F12: 18.88 | I12: 20 | K12: 4 | L12: =G12+I12-J12-K12+H12 -> 16 | M12: 16 | N12: =F12*L12 -> 302.08 | O12: =M12*F12 -> 302.08 | P12: =L12-M12 -> 0 | Q12: =N12-O12 -> 0 | S12: =U12+Y12+W12+AA12 -> 5 | T12: =M12-S12 -> 11 | U12: 5
B13: 1 | C13: CHIPS & SNACK | D13: 4809011681378 | E13: BOY BAWANG GARLIC FLAVOR 100G | F13: 16.03 | G13: 56 | K13: 2 | L13: =G13+I13-J13-K13+H13 -> 54 | M13: 53 | N13: =F13*L13 -> 865.62 | O13: =M13*F13 -> 849.59 | P13: =L13-M13 -> 1 | Q13: =N13-O13 -> 16.03 | S13: =U13+Y13+W13+AA13 -> 19 | T13: =M13-S13 -> 34 | U13: 19
B14: 1 | C14: CHIPS & SNACK | D14: 4809011681194 | E14: BOY BAWANG HOT GARLIC 100G | F14: 16.03 | L14: =G14+I14-J14-K14+H14 -> 0 | N14: =F14*L14 -> 0 | O14: =M14*F14 -> 0 | P14: =L14-M14 -> 0 | Q14: =N14-O14 -> 0 | S14: =U14+Y14+W14+AA14 -> 0 | T14: =M14-S14 -> 0
B15: 1 | C15: CHIPS & SNACK | D15: 4800631000488 | E15: BOY BAWANG MIXED NUTS GARLIC FLAVOR 100G | F15: 32.13 | G15: 30 | L15: =G15+I15-J15-K15+H15 -> 30 | M15: 30 | N15: =F15*L15 -> 963.9 | O15: =M15*F15 -> 963.9 | P15: =L15-M15 -> 0 | Q15: =N15-O15 -> 0 | R15: 1-Expired 4/15/2025 | S15: =U15+Y15+W15+AA15 -> 4 | T15: =M15-S15 -> 26 | U15: 4
B16: 1 | C16: CHIPS & SNACK | D16: 4800631000488 | E16: BOY BAWANG MIXED NUTS GARLIC FLAVOR 100G | F16: 33.75 | I16: 20 | K16: 8 | L16: =G16+I16-J16-K16+H16 -> 12 | M16: 12 | N16: =F16*L16 -> 405 | O16: =M16*F16 -> 405 | P16: =L16-M16 -> 0 | Q16: =N16-O16 -> 0 | R16: 1-Expired 4/15/2025 | S16: =U16+Y16+W16+AA16 -> 4 | T16: =M16-S16 -> 8 | U16: 4
B17: 1 | C17: CHIPS & SNACK | D17: 4800631001867 | E17: BOY BAWANG SNACK MIX W/ REAL GARLIC CHIPS 85G | F17: 18.53 | G17: 12 | K17: 10 | L17: =G17+I17-J17-K17+H17 -> 2 | M17: 2 | N17: =F17*L17 -> 37.06 | O17: =M17*F17 -> 37.06 | P17: =L17-M17 -> 0 | Q17: =N17-O17 -> 0 | S17: =U17+Y17+W17+AA17 -> 27 | T17: =M17-S17 -> -25 | U17: 27
B18: 1 | C18: CHIPS & SNACK | D18: 4800194104128 | E18: CHEEZ ON CHIPS CHEESE FLAVOR 22G | F18: 6.18 | G18: 91 | L18: =G18+I18-J18-K18+H18 -> 91 | M18: 91 | N18: =F18*L18 -> 562.38 | O18: =M18*F18 -> 562.38 | P18: =L18-M18 -> 0 | Q18: =N18-O18 -> 0 | S18: =U18+Y18+W18+AA18 -> 94 | T18: =M18-S18 -> -3 | U18: 6 | W18: =37+50+1 -> 88 | X18: EXPIRED 2024 MAY 2026-50 | AD18: 50 | AE18: =AD18*F18 -> 309
B19: 1 | C19: CHIPS & SNACK | D19: 4800216125919 | E19: CHEEZY CORN CRUNCH CHEESE 150G | F19: 51.54 | G19: 1 | L19: =G19+I19-J19-K19+H19 -> 1 | M19: 1 | N19: =F19*L19 -> 51.54 | O19: =M19*F19 -> 51.54 | P19: =L19-M19 -> 0 | Q19: =N19-O19 -> 0 | S19: =U19+Y19+W19+AA19 -> 1 | T19: =M19-S19 -> 0 | U19: 1
B20: 1 | C20: CHIPS & SNACK | D20: 4800216121041 | E20: CHEEZY CORN CRUNCH CHEESE 24G | F20: 7.4 | G20: 10 | L20: =G20+I20-J20-K20+H20 -> 10 | M20: 10 | N20: =F20*L20 -> 74 | O20: =M20*F20 -> 74 | P20: =L20-M20 -> 0 | Q20: =N20-O20 -> 0 | S20: =U20+Y20+W20+AA20 -> 10 | T20: =M20-S20 -> 0 | U20: 10
B21: 1 | C21: CHIPS & SNACK | D21: 4800216121041 | E21: CHEEZY CORN CRUNCH CHEESE 24G | F21: 7.7485 | I21: 20 | K21: 3 | L21: =G21+I21-J21-K21+H21 -> 17 | M21: 17 | N21: =F21*L21 -> 131.7245 | O21: =M21*F21 -> 131.7245 | P21: =L21-M21 -> 0 | Q21: =N21-O21 -> 0 | S21: =U21+Y21+W21+AA21 -> 10 | T21: =M21-S21 -> 7 | U21: 10
B22: 1 | C22: CHIPS & SNACK | D22: 4800216121058 | E22: CHEEZY CORN CRUNCH CHEESE 70G | F22: 26.09 | G22: 17 | K22: 1 | L22: =G22+I22-J22-K22+H22 -> 16 | M22: 17 | N22: =F22*L22 -> 417.44 | O22: =M22*F22 -> 443.53 | P22: =L22-M22 -> -1 | Q22: =N22-O22 -> -26.09 | S22: =U22+Y22+W22+AA22 -> 23 | T22: =M22-S22 -> -6 | U22: 23
B23: 1 | C23: CHIPS & SNACK | D23: 4800216121058 | E23: CHEEZY CORN CRUNCH CHEESE 70G | F23: 28.196 | I23: 15 | L23: =G23+I23-J23-K23+H23 -> 15 | M23: 14 | N23: =F23*L23 -> 422.94 | O23: =M23*F23 -> 394.744 | P23: =L23-M23 -> 1 | Q23: =N23-O23 -> 28.196 | S23: =U23+Y23+W23+AA23 -> 23 | T23: =M23-S23 -> -9 | U23: 23
B24: 1 | C24: CHIPS & SNACK | D24: 4800216121911 | E24: CHEEZY CORN CRUNCH RED HOT 22G | F24: 7.4 | L24: =G24+I24-J24-K24+H24 -> 0 | N24: =F24*L24 -> 0 | O24: =M24*F24 -> 0 | P24: =L24-M24 -> 0 | Q24: =N24-O24 -> 0 | S24: =U24+Y24+W24+AA24 -> 0 | T24: =M24-S24 -> 0
B25: 1 | C25: CHIPS & SNACK | D25: 4800216122437 | E25: CHEEZY CORN CRUNCH RED HOT 70G | F25: 26.09 | G25: 10 | L25: =G25+I25-J25-K25+H25 -> 10 | M25: 10 | N25: =F25*L25 -> 260.9 | O25: =M25*F25 -> 260.9 | P25: =L25-M25 -> 0 | Q25: =N25-O25 -> 0 | S25: =U25+Y25+W25+AA25 -> 12 | T25: =M25-S25 -> -2 | U25: 12
B26: 1 | C26: CHIPS & SNACK | D26: 4800216122437 | E26: CHEEZY CORN CRUNCH RED HOT 70G | F26: 28.196 | I26: 15 | K26: 2 | L26: =G26+I26-J26-K26+H26 -> 13 | M26: 13 | N26: =F26*L26 -> 366.548 | O26: =M26*F26 -> 366.548 | P26: =L26-M26 -> 0 | Q26: =N26-O26 -> 0 | S26: =U26+Y26+W26+AA26 -> 12 | T26: =M26-S26 -> 1 | U26: 12
B27: 1 | C27: CHIPS & SNACK | D27: 4800016115424 | E27: CHICHARRON NI MANG JUAN KLASIK CHICHARON 90G | F27: 17.1 | L27: =G27+I27-J27-K27+H27 -> 0 | N27: =F27*L27 -> 0 | O27: =M27*F27 -> 0 | P27: =L27-M27 -> 0 | Q27: =N27-O27 -> 0 | S27: =U27+Y27+W27+AA27 -> 0 | T27: =M27-S27 -> 0
B28: 1 | C28: CHIPS & SNACK | D28: 4800016110535 | E28: CHICHARRON NI MANG JUAN PAOMBONG 26G | F28: 6.83 | G28: 28 | L28: =G28+I28-J28-K28+H28 -> 28 | M28: 28 | N28: =F28*L28 -> 191.24 | O28: =M28*F28 -> 191.24 | P28: =L28-M28 -> 0 | Q28: =N28-O28 -> 0 | S28: =U28+Y28+W28+AA28 -> 35 | T28: =M28-S28 -> -7 | U28: 35
B29: 1 | C29: CHIPS & SNACK | D29: 4800016110511 | E29: CHICHARRON NI MANG JUAN PAOMBONG 90G | F29: 19.4 | L29: =G29+I29-J29-K29+H29 -> 0 | N29: =F29*L29 -> 0 | O29: =M29*F29 -> 0 | P29: =L29-M29 -> 0 | Q29: =N29-O29 -> 0 | S29: =U29+Y29+W29+AA29 -> 0 | T29: =M29-S29 -> 0
B30: 1 | C30: CHIPS & SNACK | D30: 4800016110542 | E30: CHICHARRON NI MANG JUAN SUKAT SILI 26G | F30: 6.83 | G30: 29 | L30: =G30+I30-J30-K30+H30 -> 29 | M30: 29 | N30: =F30*L30 -> 198.07 | O30: =M30*F30 -> 198.07 | P30: =L30-M30 -> 0 | Q30: =N30-O30 -> 0 | S30: =U30+Y30+W30+AA30 -> 36 | T30: =M30-S30 -> -7 | U30: 36
B31: 1 | C31: CHIPS & SNACK | D31: 4800016110528 | E31: CHICHARRON NI MANG JUAN SUKAT SILI 90G | F31: 19.4 | L31: =G31+I31-J31-K31+H31 -> 0 | N31: =F31*L31 -> 0 | O31: =M31*F31 -> 0 | P31: =L31-M31 -> 0 | Q31: =N31-O31 -> 0 | S31: =U31+Y31+W31+AA31 -> 0 | T31: =M31-S31 -> 0
B32: 1 | C32: CHIPS & SNACK | D32: 4806505854423 | E32: CHICK BOY CALIFORNIA CRUNCH ONION & GARLIC FLAVOR 100G | F32: 17.65 | G32: 2 | K32: 1 | L32: =G32+I32-J32-K32+H32 -> 1 | M32: 1 | N32: =F32*L32 -> 17.65 | O32: =M32*F32 -> 17.65 | P32: =L32-M32 -> 0 | Q32: =N32-O32 -> 0 | S32: =U32+Y32+W32+AA32 -> 6 | T32: =M32-S32 -> -5 | U32: 6
B33: 1 | C33: CHIPS & SNACK | D33: 4806505854423 | E33: CHICK BOY CALIFORNIA CRUNCH ONION & GARLIC FLAVOR 100G | F33: 18.65 | I33: 10 | K33: 1 | L33: =G33+I33-J33-K33+H33 -> 9 | M33: 9 | N33: =F33*L33 -> 167.85 | O33: =M33*F33 -> 167.85 | P33: =L33-M33 -> 0 | Q33: =N33-O33 -> 0 | S33: =U33+Y33+W33+AA33 -> 6 | T33: =M33-S33 -> 3 | U33: 6
B34: 1 | C34: CHIPS & SNACK | D34: 4806505854225 | E34: CHICK BOY CHEESE FLAVOR 100G | F34: 17.65 | G34: 8 | K34: 4 | L34: =G34+I34-J34-K34+H34 -> 4 | M34: 4 | N34: =F34*L34 -> 70.6 | O34: =M34*F34 -> 70.6 | P34: =L34-M34 -> 0 | Q34: =N34-O34 -> 0 | S34: =U34+Y34+W34+AA34 -> 10 | T34: =M34-S34 -> -6 | U34: 10
B35: 1 | C35: CHIPS & SNACK | D35: 4806505854225 | E35: CHICK BOY CHEESE FLAVOR 100G | F35: 18.65 | I35: 10 | K35: 1 | L35: =G35+I35-J35-K35+H35 -> 9 | M35: 9 | N35: =F35*L35 -> 167.85 | O35: =M35*F35 -> 167.85 | P35: =L35-M35 -> 0 | Q35: =N35-O35 -> 0 | S35: =U35+Y35+W35+AA35 -> 10 | T35: =M35-S35 -> -1 | U35: 10
B36: 1 | C36: CHIPS & SNACK | D36: 4806505854232 | E36: CHICK BOY SWEET CORN FLAVOR 100G | F36: 17.65 | G36: 6 | L36: =G36+I36-J36-K36+H36 -> 6 | M36: 6 | N36: =F36*L36 -> 105.9 | O36: =M36*F36 -> 105.9 | P36: =L36-M36 -> 0 | Q36: =N36-O36 -> 0 | S36: =U36+Y36+W36+AA36 -> 1 | T36: =M36-S36 -> 5 | U36: 1
B37: 1 | C37: CHIPS & SNACK | D37: 4806505854232 | E37: CHICK BOY SWEET CORN FLAVOR 100G | F37: 18.65 | I37: 10 | K37: 6 | L37: =G37+I37-J37-K37+H37 -> 4 | M37: 4 | N37: =F37*L37 -> 74.6 | O37: =M37*F37 -> 74.6 | P37: =L37-M37 -> 0 | Q37: =N37-O37 -> 0 | S37: =U37+Y37+W37+AA37 -> 1 | T37: =M37-S37 -> 3 | U37: 1
B38: 1 | C38: CHIPS & SNACK | D38: 4806505854416 | E38: CHICK BOY TEXAS SMOKED BBQ FLAVOR 100G | F38: 18.65 | I38: 10 | K38: 3 | L38: =G38+I38-J38-K38+H38 -> 7 | M38: 7 | N38: =F38*L38 -> 130.55 | O38: =M38*F38 -> 130.55 | P38: =L38-M38 -> 0 | Q38: =N38-O38 -> 0 | S38: =U38+Y38+W38+AA38 -> 1 | T38: =M38-S38 -> 6 | U38: 1
B39: 1 | C39: CHIPS & SNACK | D39: 4800016115011 | E39: CHICKN SKIN NI MANG JUAN 17G | F39: 7.06 | G39: 95 | K39: 20 | L39: =G39+I39-J39-K39+H39 -> 75 | M39: 75 | N39: =F39*L39 -> 529.5 | O39: =M39*F39 -> 529.5 | P39: =L39-M39 -> 0 | Q39: =N39-O39 -> 0 | S39: =U39+Y39+W39+AA39 -> 0 | T39: =M39-S39 -> 75
B40: 1 | C40: CHIPS & SNACK | D40: 4800016115257 | E40: CHICKN SKIN NI MANG JUAN 70G | F40: 18.03 | L40: =G40+I40-J40-K40+H40 -> 0 | N40: =F40*L40 -> 0 | O40: =M40*F40 -> 0 | P40: =L40-M40 -> 0 | Q40: =N40-O40 -> 0 | S40: =U40+Y40+W40+AA40 -> 28 | T40: =M40-S40 -> -28 | U40: 28
...

Sheet VB-final
A1: VARIANCE BREAKDOWN (CONVIE)
A2: =PRINTING!B2 -> AS OF JULY 2026
A3: OVER
A4: BARCODE | B4: PRODUCT NAME | C4: UNIT COST | D4: Actual Count JUNE 2026 | E4: RETAIL | F4: PURCHASES | G4: PULL OUT | H4: SALES | I4: TOTAL | J4: ACTUAL INVENTORY | K4: VARIANCE - QUANTITY | L4: VARIANCE - COST | M4: REMARKS / CAUSE OF VARIANCE
A5: 4800216121058 | B5: CHEEZY CORN CRUNCH CHEESE 70G | C5: 26.09 | D5: 17 | H5: 1 | I5: 16 | J5: 17 | K5: -1 | L5: -26.09
A6: 4800361028639 | B6: NESTLE KOKO KRUNCH 20G | C6: 11.78 | I6: 0 | J6: 1 | K6: -1 | L6: -11.78
A7: 4800016622533 | B7: POTATO CHIPS VCUT SPICY BBQ 25G | C7: 15.65 | D7: 77 | H7: 10 | I7: 67 | J7: 68 | K7: -1 | L7: -15.65
A8: 4800016661006 | B8: ROLLER COASTER CHEDDAR CHEESE 24G | C8: 7.06 | D8: 98 | H8: 20 | I8: 78 | J8: 84 | K8: -6 | L8: -42.36
A9: 4800016560927 | B9: NISSIN CUP NOODLES SPICY HOT BEEF 45G | C9: 21.88 | D9: 7 | H9: 9 | I9: -2 | J9: 49 | K9: -51 | L9: -1115.88
A10: 4800134101521 | B10: MASTER MACKEREL RED 155G | C10: 26 | H10: 5 | I10: -5 | J10: 0 | K10: -5 | L10: -130
A11: 4806504710126 | B11: MEGA SARDINES RED 155G | C11: 25.03 | H11: 1 | I11: -1 | J11: 0 | K11: -1 | L11: -25.03
A12: 888123456782035 | B12: BAIS SUGAR WASH 1/4 | C12: 13.85 | D12: 42 | H12: 28 | I12: 14 | J12: 42 | K12: -28 | L12: -387.8
A13: 4800024573544 | B13: DM SWEET STYLE SPAGHETTI SAUCE 900G | C13: 94.76 | H13: 2 | I13: -2 | J13: 0 | K13: -2 | L13: -189.52
A14: 4800888605078 | B14: KNORR SINIGANG NA MAY GABI 11G | C14: 6.89 | H14: 23 | I14: -23 | J14: 17 | K14: -40 | L14: -275.6
A15: 4800888603692 | B15: KNORR SINIGANG SA SAMPALOK MIX 11G | C15: 7.14 | D15: 4 | H15: 11 | I15: -7 | J15: 37 | K15: -44 | L15: -314.16
A16: 4800888600790 | B16: KNORR SINIGANG SA SAMPALOK MIX ORIG 22G | C16: 14.38 | D16: 5 | H16: 17 | I16: -12 | J16: 12 | K16: -24 | L16: -345.12
A17: 888123456782032 | B17: LUISITA SUGAR WHITE 1/2 | C17: 27.84 | H17: 25 | I17: -25 | K17: -25 | L17: -696
A18: 4800888147240 | B18: CLOSE UP MENTHOL FRESH 2X11G | C18: 7.75 | D18: 167 | I18: 167 | J18: 169 | K18: -2 | L18: -15.5
A19: 8935102111335 | B19: COLGATE CLASSIC TOOTHBRUSH MEDIUM 2S | C19: 30.2 | H19: 1 | I19: -1 | K19: -1 | L19: -30.2
A20: 4902430522809 | B20: HEAD & SHOULDER ANTI-DANDRUFF SHAMPOO ULTRA MEN COOL MENTHOL 12ML | C20: 6.82 | D20: 5 | H20: 12 | I20: -7 | J20: 5 | K20: -12 | L20: -81.84
A21: 888123456781567 | B21: MAGNUM MINI VANILLA ALMOND 45ML RETAIL | C21: 37.87 | D21: 30 | I21: 30 | J21: 31 | K21: -1 | L21: -37.87
A22: 4800086134325 | B22: SEL CORNETTO CLASSIC CHOCO 110ML | C22: 20.4 | D22: 34 | H22: 8 | I22: 26 | J22: 34 | K22: -8 | L22: -163.2
A23: 4800086043306 | B23: SEL CORNETTO COOKIES & DREAM 110ML | C23: 20.4 | D23: 54 | H23: 5 | I23: 49 | J23: 57 | K23: -8 | L23: -163.2
A24: 888123456782001 | B24: OTC SUPERLAMIG CANDY | C24: 0.74 | H24: 17 | I24: -17 | K24: -17 | L24: -12.58
A25: 888123456782039 | B25: OTC SUPERLAMIG PEPPERMINT | C25: 0.76 | D25: 8 | H25: 9 | I25: -1 | K25: -1 | L25: -0.76
A26: 750515030152 | B26: OTC SKYFLAKES ONION & CHIVES 25G | C26: 6.03 | H26: 2 | I26: -2 | K26: -2 | L26: -12.06
D27: =SUM(D5:D26) -> 548 | E27: =SUM(E5:E26) -> 0 | F27: =SUM(F5:F26) -> 0 | G27: =SUM(G5:G26) -> 0 | H27: =SUM(H5:H26) -> 206 | I27: =SUM(I5:I26) -> 342 | J27: =SUM(J5:J26) -> 623 | K27: =SUM(K5:K26) -> -281 | ... M27: =SUM(M5:M26) -> 0
A28: RETURN
A29: BARCODE | B29: PRODUCT NAME | C29: UNIT COST | F29: VARIANCE - QUANTITY | G29: VARIANCE - COST | H29: REMARKS / CAUSE OF VARIANCE
F31: =SUM(F30:F30) -> 0 | G31: =SUM(G30:G30) -> 0
A33: SHORT
A34: BARCODE | B34: PRODUCT NAME | C34: UNIT COST | D34: Actual Count JUNE 2026 | E34: RETAIL | F34: PURCHASES | G34: PULL OUT | H34: SALES | I34: TOTAL | J34: ACTUAL INVENTORY | K34: VARIANCE - QUANTITY | L34: VARIANCE - COST | M34: REMARKS / CAUSE OF VARIANCE
A35: 4809011681378 | B35: BOY BAWANG GARLIC FLAVOR 100G | C35: 16.03 | D35: 56 | H35: 2 | I35: 54 | J35: 53 | K35: 1 | L35: 16.03
A36: 4800216121058 | B36: CHEEZY CORN CRUNCH CHEESE 70G | C36: 28.196 | F36: 15 | I36: 15 | J36: 14 | K36: 1 | L36: 28.196
A37: 4800016680540 | B37: HONEY BUTTER POTATO CHIPS 22G | C37: 16.58 | D37: 94 | H37: 16 | I37: 78 | J37: 77 | K37: 1 | L37: 16.58
A38: 4800016680267 | B38: HONEY BUTTER POTATO CHIPS 60G | C38: 39.48 | D38: 15 | I38: 15 | J38: 14 | K38: 1 | L38: 39.48
A39: 4800194104913 | B39: OHEYA CHEESE FLAVOR 28G | C39: 6.18 | D39: 87 | I39: 87 | J39: 86 | K39: 1 | L39: 6.18 | M39: 86-Expired 4/23/2026 & 7/2024
A40: 4800194104968 | B40: OISHI PRAWN CRACKERS SPICY FLAVOR 24G | C40: 6.18 | D40: 129 | I40: 129 | J40: 128 | K40: 1 | L40: 6.18
A41: 4800016625534 | B41: POTATO CHIPS VCUT SPICY BBQ FLAVOR 60G | C41: 34.47 | D41: 45 | H41: 3 | I41: 42 | J41: 41 | K41: 1 | L41: 34.47
A42: 4807770100536 | B42: BINGO ORANGE 280G | C42: 59.5 | D42: 10 | H42: 1 | I42: 9 | J42: 8 | K42: 1 | L42: 59.5
...

Sheet FOR PULLOUT
A1: VARIANCE BREAKDOWN (CONVIE)
A2: =PRINTING!B2 -> AS OF JULY 2026
F4: =SUM(F3:F3) -> 0 | G4: =SUM(G3:G3) -> 0
A6: SHORT
A7: BARCODE | B7: PRODUCT NAME | C7: UNIT COST | D7: Actual Count JUNE 2026 | E7: RETAIL | F7: PURCHASES | G7: PULL OUT | H7: SALES | I7: TOTAL | J7: ACTUAL INVENTORY | K7: VARIANCE - QUANTITY | L7: VARIANCE - COST | M7: REMARKS / CAUSE OF VARIANCE
A8: 6902131112925 | B8: MALING CHICKEN LUNCHEON MEAT 397G | C8: 116 | D8: 2 | I8: 2 | K8: 2 | L8: 232 | M8: FOR PULL OUT - ADJUSTMENT (JAZZ EAT SALES)
A9: 4800086045676 | B9: SEL CORNETTO DISC WHITE CHOCO COOKIES & CREAM 115ML | C9: 27.3 | D9: 73 | H9: 2 | I9: 71 | J9: 47 | K9: 24 | L9: 655.2 | M9: FOR PULL OUT - ADJUSTMENT (
A10: 4800086051011 | B10: SEL NAMA CHOCOLATE 1.25L | C10: 250 | D10: 1 | I10: 1 | J10: 0 | K10: 1 | L10: 250 | M10: FOR PULL OUT - ADJUSTMENT (BADORDER MAY TAPOS INILAGAY PA NLA SA ACTUAL COUNT)
A11: 8851932478502 | B11: WALLS BITES STRAW YOGHURT 14G | C11: 22.75 | D11: 11 | I11: 11 | J11: 0 | K11: 11 | L11: 250.25 | M11: FOR PULL OUT - ADJUSTMENT (OVER NA SALES NG MAY 2026)
D12: =SUM(D8:D11) -> 87 | E12: =SUM(E8:E11) -> 0 | F12: =SUM(F8:F11) -> 0 | G12: =SUM(G8:G11) -> 0 | H12: =SUM(H8:H11) -> 2 | I12: =SUM(I8:I11) -> 85 | J12: =SUM(J8:J11) -> 47 | K12: =SUM(K8:K11) -> 38 | L12: =SUM(L8:L11) -> 1387.45

Sheet RECHECKING
A1: OVER
B2: BARCODE | C2: PRODUCT NAME | D2: UNIT COST | E2: Actual Count JUNE 2026 | F2: RETAIL | G2: PURCHASES | H2: PULL OUT | I2: SALES | J2: TOTAL | K2: ACTUAL INVENTORY | L2: VARIANCE - QUANTITY | M2: VARIANCE - COST | N2: REMARKS / CAUSE OF VARIANCE
B3: 4800631001928 | C3: BOY BAWANG ASSORTED NUTS 85G | D3: 19.1 | G3: 40 | I3: 15 | J3: 25 | K3: 31 | L3: -6 | M3: -114.6
B4: 4809011 681392 | C4: BOY BAWANG CHILI CHEESE 100G | D4: 16.03 | E4: 15 | I4: 3 | J4: 12 | K4: 13 | L4: -1 | M4: -16.03
B5: 4800631000488 | C5: BOY BAWANG MIXED NUTS GARLIC FLAVOR 100G | D5: 32.13 | E5: 30 | J5: 30 | K5: 44 | L5: -14 | M5: -449.82 | N5: 1-Expired 4/15/2025
B6: 4800216121058 | C6: CHEEZY CORN CRUNCH CHEESE 70G | D6: 26.09 | E6: 17 | I6: 1 | J6: 16 | K6: 17 | L6: -1 | M6: -26.09
B7: 4800016110511 | C7: CHICHARRON NI MANG JUAN PAOMBONG 90G | D7: 19.4 | J7: 0 | K7: 74 | L7: -74 | M7: -1435.6
B8: 4800054121289 | C8: GROWERS SALTED CASHEW NUTS 80G | D8: 90.42 | E8: 13 | I8: 1 | J8: 12 | K8: 14 | L8: -2 | M8: -180.84
B9: 4800054125287 | C9: GROWERS SALTED PISTACHIO NUTS 80G | D9: 114.79 | E9: 22 | J9: 22 | K9: 27 | L9: -5 | M9: -573.95
B10: 4800361028639 | C10: NESTLE KOKO KRUNCH 20G | D10: 11.78 | J10: 0 | K10: 1 | L10: -1 | M10: -11.78
B11: 4800016663505 | C11: NOVA COUNTRY CHEDDAR 78G | D11: 33.1 | E11: 39 | I11: 8 | J11: 31 | K11: 32 | L11: -1 | M11: -33.1
B12: 4800194116084 | C12: OISHI CRACKLINGS SALT & VINEGAR 24G | D12: 6.18 | E12: 132 | J12: 132 | K12: 133 | L12: -1 | M12: -6.18 | N12: 56-EXPIRED 11/26/2024
B13: 4800194104869 | C13: OISHI CRISPY PATATA 24G | D13: 6.18 | E13: 49 | J13: 49 | K13: 50 | L13: -1 | M13: -6.18
B14: 4800194177962 | C14: OISHI PRAWN CRACKERS SPICY FLAVOR 90G | D14: 21.97 | E14: 16 | J14: 16 | K14: 17 | L14: -1 | M14: -21.97 | N14: 15-expired 5/2026
B15: 4800016644801 | C15: PIATTOS CHEESE 40G | D15: 15.512 | G15: 24 | I15: 4 | J15: 20 | K15: 23 | L15: -3 | M15: -46.536
B16: 4800016622533 | C16: POTATO CHIPS VCUT SPICY BBQ 25G | D16: 15.65 | E16: 77 | I16: 10 | J16: 67 | K16: 68 | L16: -1 | M16: -15.65
B17: 4800194101783 | C17: POTATO CRISPS CHEESE FLAVOR 18G | D17: 6.18 | E17: 97 | J17: 97 | K17: 100 | L17: -3 | M17: -18.54
B18: 4800016661006 | C18: ROLLER COASTER CHEDDAR CHEESE 24G | D18: 7.06 | E18: 98 | I18: 20 | J18: 78 | K18: 84 | L18: -6 | M18: -42.36
B19: 4800142110089 | C19: EMPERADOR LIGHT 750ML | D19: 117.5 | E19: 72 | J19: 72 | K19: 73 | L19: -1 | M19: -117.5
B20: 4800130728128 | C20: G.S.M BLUE MOJITO 700ML | D20: 121.5 | E20: 27 | J20: 27 | K20: 28 | L20: -1 | M20: -121.5
B21: 4800116136022 | C21: BUTTER CREAM CRACKERS CHEESE SPREAD 10X17G | D21: 44.8 | E21: 16 | G21: 15 | H21: 1 | I21: 8 | J21: 22 | K21: 23 | L21: -1 | M21: -44.8
B22: 4800016077531 | C22: CREAM-O COOKIES N CREAM 27GX10 | D22: 68.54 | J22: 0 | K22: 1 | L22: -1 | M22: -68.54
B23: 4800016112577 | C23: JNJ CREAM-O CHOCOLATE CAKE SANDWICH W/ THICK VANILLA | D23: 78.29 | J23: 0 | K23: 2 | L23: -2 | M23: -156.58
B24: 4800016082979 | C24: MAGIC CHIPS BBQ FLAVOR 28G | D24: 6.8 | J24: 0 | K24: 1 | L24: -1 | M24: -6.8 | N24: over 21 sales
B25: 4800016083778 | C25: MAGIC CHIPS SOUR CREAM AND ONION 28G | D25: 6.8 | J25: 0 | K25: 3 | L25: -3 | M25: -20.4 | N25: over 13 sales
B26: 4800016628283 | C26: MINI CHOCO PRETZELS 28G | D26: 7.41 | E26: 16 | I26: 14 | J26: 2 | K26: 7 | L26: -5 | M26: -37.05
B27: 4807770121364 | C27: MONDE SPECIAL MAMON MOCHA 6X43G | D27: 96 | J27: 0 | K27: 1 | L27: -1 | M27: -96
B28: 4807770100963 | C28: NISSIN EGGNOG COOKIES 18G PACK | D28: 58.8 | E28: 9 | J28: 9 | K28: 10 | L28: -1 | M28: -58.8
B29: 8992760223046 | C29: OREO CHOCOLATE CREME 12X28.5G | D29: 67.28 | E29: 1 | H29: 1 | J29: 0 | K29: 1 | L29: -1 | M29: -67.28
B30: 8992760221066 | C30: OREO VANILLA ORIGINAL 12X27.6G | D30: 70.91 | E30: 3 | H30: 1 | J30: 2 | K30: 4 | L30: -2 | M30: -141.82 | N30: 3-Expired 6/20/2025
B31: 4800010075922 | C31: PRESTO CREAMS PEANUT BUTTER 300G | D31: 59.51 | E31: 7 | I31: 5 | J31: 2 | K31: 3 | L31: -1 | M31: -59.51
B32: 7622202046780 | C32: TIGER BITES VANILLA 10PACKS | D32: 56.37 | J32: 0 | K32: 1 | L32: -1 | M32: -56.37
B33: 49814521 | C33: CHUPA CHUPS LOLLIPOPS FRUIT FLAVORED 12G | D33: 8.38 | E33: 101 | I33: 6 | J33: 95 | K33: 104 | L33: -9 | M33: -75.42
B34: 8935001721673 | C34: CHUPAS CHUPS MILKY CARAMEL LOLLIPO 9.5G | D34: 36 | E34: 4 | G34: 2 | H34: 2 | J34: 4 | K34: 7 | L34: -3 | M34: -108
B35: 8935001721680 | C35: CHUPA CHUPS MILKY STRAWBERRY&CREAM LOLLIPOP 9.5G | D35: 36 | E35: 1 | G35: 2 | H35: 2 | J35: 1 | K35: 8 | L35: -7 | M35: -252
B36: 4806517042085 | C36: GOYA BAR DARK CHOCOLATE 30G | D36: 23.63 | E36: 19 | I36: 11 | J36: 8 | K36: 11 | L36: -3 | M36: -70.89
B37: 4806517042214 | C37: GOYA CREAM WHITE 35G BUY 2 TAKE 1 | D37: 44.37 | J37: 0 | K37: 2 | L37: -2 | M37: -88.74
B38: 4806533325254 | C38: GOYA TAKE IT 2F 2+1 | D38: 33.76 | E38: 9 | J38: 9 | K38: 10 | L38: -1 | M38: -33.76
B39: 8851096020012 | C39: PUSH POP LOLLIPOP 14G | D39: 29.9 | E39: 12 | I39: 4 | J39: 8 | K39: 11 | L39: -3 | M39: -89.7
B40: 4800575144590 | C40: ALASKA POWDERED MILK DRINK 300ML | D40: 99.12 | E40: 9 | J40: 9 | K40: 14 | L40: -5 | M40: -495.6
...

Sheet Sheet1

Sheet JUNE SALES-
A1: SALES
A2: =PRINTING!B2 -> AS OF JULY 2026
A3: DATE | B3: PARTICULAR | C3: TRANSACTION NO: | D3: DESCRIPTION | E3: QTY. | F3: COST PRICE | G3: UNIT PRICE | H3: CASH SALE | I3: ACCOUNT RECEIVABLE | J3: SALES DISCOUNT | K3: NET SALES | L3: COGS
A4: 07/01/2026 | B4: 4800016560927 | C4: 0-145208 | D4: NISSIN CUP NOODLES SPICY HOT BEEF 45G | E4: 1 | F4: 21.88 | G4: 25.25 | H4: 25.25 | K4: 25.25 | L4: 21.88
A5: 07/01/2026 | B5: 69025310 | C5: 0-145208 | D5: SNICKERS 20G | E5: 1 | F5: 14.31 | G5: 16.5 | H5: 16.5 | K5: 16.5 | L5: 14.31
A6: 07/01/2026 | B6: 4800631000488 | C6: 0-145208 | D6: BOY BAWANG MIXED NUTS GARLIC FLAVOR 100G | E6: 1 | F6: 33.75 | G6: 39 | H6: 39 | K6: 39 | L6: 33.75
A7: 07/01/2026 | B7: 4800086050120 | C7: 0-145208 | D7: SEL CUPS DOUBLE CHOCO SUNDAE 100ML | E7: 1 | F7: 23.15 | G7: 26.75 | H7: 26.75 | K7: 26.75 | L7: 23.15
A8: 07/01/2026 | B8: 748485802060 | C8: 0-145208 | D8: WOW ULAM ADOBO 155G | E8: 1 | F8: 22.59 | G8: 26 | H8: 26 | K8: 26 | L8: 22.59
A9: 07/01/2026 | B9: 8935001721550 | C9: 0-145208 | D9: OTC CHUPA CHUPS MILKY CARAMEL LOLLIPOP 9G | E9: 1 | F9: 3.6 | G9: 4.25 | H9: 4.25 | K9: 4.25 | L9: 3.6
A10: 07/01/2026 | B10: 748485150079 | C10: 0-145208 | D10: COCO MAMA FRESH GATA 200ML | E10: 1 | F10: 32.86 | G10: 38 | H10: 38 | K10: 38 | L10: 32.86
A11: 07/01/2026 | B11: 4806517040395 | C11: 0-145208 | D11: DELFI KNICK KNACKS MILK FLAVOR 28G | E11: 1 | F11: 8.2 | G11: 10 | H11: 10 | K11: 10 | L11: 8.2
A12: 07/01/2026 | B12: 4806506318832 | C12: 0-145208 | D12: SISTERS 8PADS DAY MAXI REGULAR FLOW W/ WINGS | E12: 1 | F12: 23.75 | G12: 27.5 | H12: 27.5 | K12: 27.5 | L12: 23.75
A13: 07/01/2026 | B13: 8998666001726 | C13: 0-145208 | D13: KOPIKO BLANCA TWINPACK 52G | E13: 2 | F13: 12.66 | G13: 14.25 | H13: 28.5 | K13: 28.5 | L13: 25.32
A14: 07/01/2026 | B14: 4800361413480 | C14: 0-145208 | D14: NESTLE MILO 24G | E14: 1 | F14: 8.58 | G14: 10 | H14: 10 | K14: 10 | L14: 8.58
A15: 07/01/2026 | B15: 8998666001702 | C15: 0-145208 | D15: KOPIKO BLACK 3IN1 TWINPACK 60G | E15: 1 | F15: 12.56 | G15: 14.25 | H15: 14.25 | K15: 14.25 | L15: 12.56
... A24: 07/01/2026 | B24: 4808680221250 | C24: 0-145209 | D24: KNORR CREAM OF MUSHROOM SOUP MIX 70G | E24: 2 | F24: 51.97 | G24: 60 | H24: 120 | K24: 120 | L24: 103.94
A25: 07/01/2026 | B25: 888123456781304 | C25: 0-145210 | D25: PANI-PEANUT | E25: 1 | F25: 90 | G25: 120 | H25: 120 | J25: 20 | K25: 100 | L25: 90
A26: 07/01/2026 | B26: 8850007371403 | C26: 0-145211 | D26: MODESS REGULAR W/ WINGS 8S | E26: 1 | F26: 37.5 | G26: 43.25 | H26: 43.25 | K26: 43.25 | L26: 37.5
A27: 07/01/2026 | B27: 4800016551857 | C27: 0-145211 | D27: NISSIN CUP NOODLES SPICY SEAFOOD 40G | E27: 1 | F27: 21.88 | G27: 24.5 | H27: 24.5 | K27: 24.5 | L27: 21.88
A28: 07/01/2026 | B28: 4800016552113 | C28: 0-145211 | D28: NISSIN CUP NOODLES SEAFOOD 40G | E28: 1 | F28: 21.88 | G28: 25.25 | H28: 25.25 | K28: 25.25 | L28: 21.88
A29: 07/01/2026 | B29: 75051030176 | C29: 0-145211 | D29: OTC SKYFLAKES ONION & CHIVES | E29: 1 | F29: 6.03 | G29: 7 | H29: 7 | K29: 7 | L29: 6.03
A30: 07/01/2026 | B30: 750515030176 | C30: 0-145211 | D30: OTC SKYFLAKES ONION & CHIVES 25G | E30: 1 | F30: 6.03 | G30: 7 | H30: 7 | K30: 7 | L30: 6.03
A31: 07/01/2026 | B31: 4800086005610 | C31: 0-145211 | D31: MAGNUM VANILLA ALMOND 80ML | E31: 2 | F31: 69.51 | G31: 80 | H31: 160 | K31: 160 | L31: 139.02
A32: 07/01/2026 | B32: 4800016560927 | C32: 0-145211 | D32: NISSIN CUP NOODLES SPICY HOT BEEF 45G | E32: 1 | F32: 21.88 | G32: 25.25 | H32: 25.25 | K32: 25.25 | L32: 21.88
A33: 07/01/2026 | B33: 4800016661006 | C33: 0-145211 | D33: ROLLER COASTER CHEDDAR CHEESE 24G | E33: 2 | F33: 7.06 | G33: 8.25 | H33: 16.5 | K33: 16.5 | L33: 14.12
A34: 07/01/2026 | B34: 4902430453028 | C34: 0-145213 | D34: DOWNY SUNRISE FRESH 800ML | E34: 1 | F34: 160.51 | G34: 184.75 | H34: 184.75 | K34: 184.75 | L34: 160.51
A35: 07/01/2026 | B35: 4902430945554 | C35: 0-145213 | D35: SAFEGUARD SOAP BAR PURE WHITE 60G | E35: 2 | F35: 19.61 | G35: 22.75 | H35: 45.5 | K35: 45.5 | L35: 39.22
A36: 07/01/2026 | B36: 4809011681392 | C36: 0-145216 | D36: BOY BAWANG CHILI CHEESE 100G | E36: 1 | F36: 16.03 | G36: 18.5 | H36: 18.5 | K36: 18.5 | L36: 16.03
A37: 07/01/2026 | B37: 4800016666445 | C37: 0-145218 | D37: MR. CHIPS MANAMIS MAIS 45G | E37: 1 | F37: 7.62 | G37: 8.75 | H37: 8.75 | K37: 8.75 | L37: 7.62
... A602: 07/15/2026 | B602: 999087 | C602: 0-145734 | D602: RBV TT-RIC COFFEE | E602: 1 | F602: 280 | G602: 350 | H602: 350 | K602: 350 | L602: 280
A603: 07/15/2026 | B603: 888123456781304 | C603: 0-145734 | D603: PANI-PEANUT | E603: 10 | F603: 90 | G603: 120 | H603: 1200 | J603: 162.5 | K603: 1037.5 | L603: 900
A604: 07/15/2026 | B604: 888123456782008 | C604: 0-145734 | D604: PANI CORNICK | E604: 4 | F604: 60 | G604: 75 | H604: 300 | K604: 300 | L604: 240
A605: 07/15/2026 | B605: 888123456782041 | C605: 0-145734 | D605: PANI-COATED PEANUTS | E605: 4 | F605: 30 | G605: 40 | H605: 160 | K605: 160 | L605: 120
A606: 07/15/2026 | B606: 4806505854232 | C606: 0-145737 | D606: CHICK BOY SWEET CORN FLAVOR 100G | E606: 1 | F606: 18.65 | G606: 21.5 | H606: 21.5 | K606: 21.5 | L606: 18.65
A607: 07/16/2026 | B607: 4800552888059 | C607: 0-145739 | D607: CHIPS DELIGHT CHOCOLATE CHIP COOKIES 80G | E607: 1 | F607: 30.04 | G607: 34.75 | H607: 34.75 | J607: 0 | K607: 34.75 | L607: 30.04
A608: 07/16/2026 | B608: 4800116024008 | C608: 0-145740 | D608: OTC SUNFLOWER CRACKERS BLUEBERRY | E608: 1 | F608: 6.18 | G608: 7.25 | H608: 7.25 | J608: 0 | K608: 7.25 | L608: 6.18
A609: 07/16/2026 | B609: 4800116099006 | C609: 0-145740 | D609: OTC BUTTER CREAM ENSAYMADA 25G | E609: 1 | F609: 6.15 | G609: 7.25 | H609: 7.25 | J609: 0 | K609: 7.25 | L609: 6.15
A610: 07/16/2026 | B610: 4800888603692 | C610: 0-145741 | D610: KNORR SINIGANG SA SAMPALOK MIX 11G | E610: 2 | F610: 7.14 | G610: 8.25 | H610: 16.5 | J610: 0 | K610: 16.5 | L610: 14.28
A611: 07/16/2026 | B611: 4800016663505 | C611: 0-145742 | D611: NOVA COUNTRY CHEDDAR 78G | E611: 1 | F611: 33.1 | G611: 38.25 | H611: 38.25 | J611: 0 | K611: 38.25 | L611: 33.1
A612: 07/16/2026 | B612: 4800016625534 | C612: 0-145742 | D612: POTATO CHIPS VCUT SPICY BBQ FLAVOR 60G | E612: 1 | F612: 34.47 | G612: 39.75 | H612: 39.75 | J612: 0 | K612: 39.75 | L612: 34.47
...

Sheet PURCHASES+
A1: PURCHASES
A2: =PRINTING!B2 -> AS OF JULY 2026
A3: DATE | B3: PARTICULARS | C3: BARCODE | D3: CV No. | E3: DESCRIPTION | F3: QTY | G3: UNIT | H3: UNIT PRICE | I3: PURCHASES
A4: 46209 | B4: PADSA ENTERPRISES CORPORATION | C4: 4806500806410 | E4: MAGIC DRI PINK XL 4S | F4: 30 | G4: PACK/S | H4: 30.21 | I4: 906.3
A5: 46209 | B5: PADSA ENTERPRISES CORPORATION | C5: 4806500806212 | E5: MAGIC DRI GREEN MEDIUM 4S | F5: 30 | G5: PACK/S | H5: 25.37 | I5: 761.1
A6: 46209 | B6: PADSA ENTERPRISES CORPORATION | C6: 4806500806311 | E6: MAGIC DRI BLUE LARGE 4S | F6: 30 | G6: PACK/S | H6: 27.8 | I6: 834
A7: 46209 | B7: PADSA ENTERPRISES CORPORATION | C7: 4806500807110 | E7: MAGIC DRI YELLOW SMALL 4S | F7: 30 | G7: PACK/S | H7: 22.96 | I7: 688.8
A8: 46209 | B8: PADSA ENTERPRISES CORPORATION | C8: 8997035600010 | E8: POCARI SWEAT 350ML | F8: 24 | G8: PC/S | H8: 32 | I8: 768
A9: 46209 | B9: IBEST CORPORATION | C9: 4800024575500 | E9: DM FILIPINO STYLE SPAGHETTI SAUCE 900G | F9: 12 | G9: PC/S | H9: 98.1 | I9: 1177.2
A10: 46209 | B10: IBEST CORPORATION | C10: 4800024587985 | E10: DM FRUITY ZING CALAMANSI-LEMON 330ML | F10: 24 | G10: PC/S | H10: 22.73 | I10: 545.52
A11: 46209 | B11: IBEST CORPORATION | C11: 4800024583161 | E11: DEL POTATO CRISP BISCUITS ORIGINAL 50G | F11: 48 | G11: PC/S | H11: 20.68 | I11: 992.64
A12: 46209 | B12: IBEST CORPORATION | C12: 748485150093 | E12: COCO MAMA FRESH GATA 400ML | F12: 24 | G12: PC/S | H12: 68.57125 | I12: 1645.71
A13: 46211 | B13: OPTIPRIME DISTRIBUTION CORPORATION | C13: 4801668607879 | E13: UFC HAPI FIESTA VEGETABLE OIL 17KG | F13: 2 | G13: PC/S | H13: 1670 | I13: 3340
A14: 46211 | B14: OPTIPRIME DISTRIBUTION CORPORATION | C14: 014285001102 | E14: UFC BANANA CATSUP 4KG | F14: 4 | G14: PC/S | H14: 250.75 | I14: 1003
A15: 46211 | B15: OPTIPRIME DISTRIBUTION CORPORATION | C15: 4801668601235 | E15: UFC CANOLA OIL 1L | F15: 12 | G15: PC/S | H15: 149 | I15: 1788
... A194: 46234 | B194: PERSONAL COLLECTION DIRECT SELLING, INC. | C194: 888123456782061 | E194: PERSONAL COLLECTION KIT BAG(TUFF, DOVE BABY COL. & CHECK DEO) | F194: 1 | G194: PC/S | H194: 220 | I194: 220
F195: =SUM(F4:F194) -> 5589 | H195: =SUM(H4:H194) -> 40720.005 | I195: =SUM(I4:I194) -> 144198.3

Sheet RETAIL+
A1: RETAIL
A2: =PRINTING!B2 -> AS OF JULY 2026
A3: DATE | B3: SUPPLIER | C3: BARCODE | D3: PARTICULAR | E3: QTY | F3: UNIT | G3: Unit Price | H3: Amount
A4: 46210 | B4: EDELIAS | C4: 4800116136008 | D4: OTC BUTTER CREAM CHEESE SPREAD 17G | E4: 10 | F4: PCS | G4: 4.48 | H4: =G4*E4 -> 44.8
B5: PROS | C5: 750515018402 | D5: OTC SKYFLAKES CRACKERS 25G | E5: 10 | F5: PCS | G5: 5.8 | H5: =G5*E5 -> 58
B6: R&J | C6: 888123456782042 | D6: OTC O PUFF CHOCO | E6: 24 | F6: PCS | G6: 1 | H6: =G6*E6 -> 24
A7: 46241 | B7: EDELIAS | C7: 4806526074299 | D7: OTC SUNFLOWER SEEDS 13G | E7: 20 | F7: PCS | G7: 3.7 | H7: =G7*E7 -> 74
C8: 4800116099006 | D8: OTC BUTTER CREAM ENSAYMADA 25G | E8: 10 | F8: PCS | G8: 6.15 | H8: =G8*E8 -> 61.5
C9: 4800116131003 | D9: OTC BUTTER CREAM CRACKERS LECHE FLAN | E9: 10 | F9: PCS | G9: 5.85 | H9: =G9*E9 -> 58.5
C10: 4800116024008 | D10: OTC SUNFLOWER CRACKERS BLUEBERRY | E10: 10 | F10: PCS | G10: 6.18 | H10: =G10*E10 -> 61.8
B11: PROS | C11: 750515018402 | D11: OTC SKYFLAKES CRACKERS 25G | E11: 10 | F11: PCS | G11: 5.8 | H11: =G11*E11 -> 58
A12: 42186 | B12: KIMBERLIN | C12: 888123456781549 | D12: OTC DYNAMITE CHOCO MINT RETAIL | E12: 50 | F12: PCS | G12: 0.76 | H12: =G12*E12 -> 38
C13: 888123456781858 | D13: OTC DYNAMITE MELON MINT RETAIL | E13: 50 | F13: PCS | G13: 0.76 | H13: =G13*E13 -> 38
A14: 44013 | B14: AS-LS | C14: 4806502720219 | D14: GAR TOASTIES 25G | E14: 10 | F14: PCS | G14: 6.82 | H14: =G14*E14 -> 68.2
B15: DELIGHT | C15: 8935001721550 | D15: OTC CHUPA CHUPS MILKY CARAMEL LOLLIPOP 9G | E15: 20 | F15: PCS | G15: 3.6 | H15: =G15*E15 -> 72
C16: 8935001721567 | D16: OTC CHUPA CHUPS STRAWBERRY & CREAM FLAVOR 9G | E16: 20 | F16: PCS | G16: 3.6 | H16: =G16*E16 -> 72
B17: MIDLANDS | C17: 8992760223039 | D17: OTC OREO CHOCOCREME 26.25G | E17: 12 | F17: PCS | G17: 5.61 | H17: =G17*E17 -> 67.32
C18: 8992760121021 | D18: OTC OREO VANILLA 26.25G | E18: 12 | F18: PCS | G18: 5.61 | H18: =G18*E18 -> 67.32
A19: 45108 | B19: EDELIAS | C19: 4806518844015 | D19: OTC HONEY HOUSE CLASSIC | E19: 10 | F19: PCS | G19: 5.74 | H19: =G19*E19 -> 57.4
C20: 4806518844022 | D20: OTC HONEY HOUSE SOUR CREAM & ONION 22G | E20: 10 | F20: PCS | G20: 5.74 | H20: =G20*E20 -> 57.4
E21: =SUM(E4:E20) -> 298
H51: =G51*E51 -> 0

Sheet PULL OUT-
A1: PULL OUT
A2: =PRINTING!B2 -> AS OF JULY 2026
A3: BAD ORDER
A4: DATE | B4: SUPPLIER | C4: BARCODE | D4: PARTICULAR | E4: QTY | F4: UNIT | G4: COST | H4: SRP
A5: 46180 | B5: PADSA | C5: 4806500806410 | D5: MAGIC DRI PINK XL 4S | E5: 9 | F5: PACK/S | G5: 30.9 | H5: =E5*G5 -> 278.1
C6: 4800488960348 | D6: EQ PANTS XL 24S | E6: 1 | F6: PACK/S | G6: 186.43 | H6: =E6*G6 -> 186.43
C7: 4806525621098 | D7: BEYBIKO DIAPERS MEDIUM 12S | E7: 1 | F7: PACK/S | G7: 68.64 | H7: =E7*G7 -> 68.64
C8: 4806525621036 | D8: BEYBIKO DIAPERS XL 30S | E8: 1 | F8: PACK/S | G8: 206.23 | H8: =E8*G8 -> 206.23
A9: RETAIL | C9: 4806500806410 | D9: MAGIC DRI PINK XL 4S | E9: 27 | F9: PACK/S | G9: 30.21 | H9: =E9*G9 -> 815.67
A10: 46210 | B10: EDELIAS | C10: 4800116136022 | D10: BUTTER CREAM CRACKERS CHEESE SPREAD 10X17G | E10: 1 | F10: PACK/S | G10: 44.8 | H10: =E10*G10 -> 44.8
B11: PROS | C11: 750515018501 | D11: SKYFLAKES CRACKERS 25GX10S | E11: 1 | F11: PACK/S | G11: 57.95 | H11: =E11*G11 -> 57.95
B12: R&J | C12: 4800194107822 | D12: O PUFF CHOCOLATE FILLED MARSHMALLOWS 24PCS | E12: 1 | F12: PACK/S | G12: 23.97 | H12: =E12*G12 -> 23.97 | I12: ADJ NA LAST MONTH
A13: 46241 | B13: EDELIAS | C13: 4806526074305 | D13: SUNFLOWER SEEDS 13GX20PCS | E13: 1 | F13: PACK/S | G13: 74 | H13: =E13*G13 -> 74
A14: 46302 | B14: AS-LS BAD ORDER | C14: 4806502726129 | D14: GAR CHEESE BUNS 250G | E14: 1 | F14: PACK/S | G14: 65 | H14: =E14*G14 -> 65
A15: 41456 | B15: EDELIAS | C15: 4800116099020 | D15: BUTTER CREAM ENSAYMADA CRACKERS 10X25G | E15: 1 | F15: PACK/S | G15: 61.5 | H15: =E15*G15 -> 61.5
C16: 4800116131027 | D16: BUTTER CREAM CRACKERS LECHE FLAN FLAVOR 10X25G | E16: 1 | F16: PACK/S | G16: 58.45 | H16: =E16*G16 -> 58.45
C17: 4800116024022 | D17: SUNFLOWER CREAM SANDWICH BLUEBERRY 10X27G | E17: 1 | F17: PACK/S | G17: 61.75 | H17: =E17*G17 -> 61.75
B18: PROS | C18: 750515018501 | D18: SKYFLAKES CRACKERS 25GX10S | E18: 2 | F18: PACK/S | G18: 57.95 | H18: =E18*G18 -> 115.9
A19: 42186 | B19: IBEST - BAD ORDER | C19: 4800024011862 | D19: DM TIDBITS 822G | E19: 14 | F19: PCS | G19: 96.19 | H19: =E19*G19 -> 1346.66
A20: 42552 | B20: KIMBERLIN - RETAIL | C20: 4800016307041 | D20: DYNAMITE CHOCO MINT CANDY 200G | E20: 1 | F20: PACK/S | G20: 38 | H20: =E20*G20 -> 38
C21: 4800016307102 | D21: DYNAMITE MELON MINT FLAVORED CANDY 200G | E21: 1 | F21: PACK/S | G21: 38 | H21: =E21*G21 -> 38
A22: 43282 | B22: PROS-BAD ORDER | C22: 4800216120013 | D22: CLOVER CHEESE 24G | E22: 64 | F22: PCS | G22: 7.51 | H22: =E22*G22 -> 480.64
A23: 44013 | B23: AS-LS BAD ORDER | C23: 4806502721452 | D23: GAR HIGH FIBER WHEAT BREAD 400G | E23: 1 | F23: PACK/S | G23: 72.95 | H23: =E23*G23 -> 72.95
C24: 4806502726822 | D24: GAR NEUBAKE WHITE BREAD 450G | E24: 1 | F24: PACK/S | G24: 53.9 | H24: =E24*G24 -> 53.9
C25: 4806502726822 | D25: GAR NEUBAKE WHITE BREAD 450G | E25: 1 | F25: PACK/S | G25: 53.9 | H25: =E25*G25 -> 53.9
A26: 44013 | B26: AS-LS RETAIL | C26: 4806502720011 | D26: GAR TOASTIES BUTTER 10X25G | E26: 1 | F26: PACK/S | G26: 68.2 | H26: =E26*G26 -> 68.2
B27: DELIGHT RETAIL | C27: 8935001721680 | D27: CHUPA CHUPS MILKY STRAWBERRY&CREAM LOLLIPOP 9.5G | E27: 2 | F27: PACK/S | G27: 36 | H27: =E27*G27 -> 72
C28: 8935001721673 | D28: CHUPAS CHUPS MILKY CARAMEL LOLLIPO 9.5G | E28: 2 | F28: PACK/S | G28: 36 | H28: =E28*G28 -> 72
B29: MIDLANDS-RETAIL | C29: 8992760221066 | D29: OREO VANILLA ORIGINAL 12X27.6G | E29: 1 | F29: PACK/S | G29: 67.28 | H29: =G29 -> 67.28
C30: 8992760223046 | D30: OREO CHOCOLATE CREME 12X28.5G | E30: 1 | F30: PACK/S | G30: 67.28 | H30: =G30 -> 67.28
A31: 45108 | B31: WING AN -BAD ORDER | C31: 4800034606980 | D31: HAPEE EXPLOSIVE MENTHOL RED SULIT DOBLE PACK 2X140ML | E31: 2 | F31: PCS | G31: 125 | H31: =E31*G31 -> 250
B32: EDELIAS | C32: 4806518846026 | D32: HONEY HOUSE SOUR CREAM & ONION 220G | E32: 1 | F32: PACK/S | G32: 57.4 | H32: =E32*G32 -> 57.4
C33: 4806518846019 | D33: HONEY HOUSE CLASSIC 220G | E33: 1 | F33: PACK/S | G33: 57.4 | H33: =E33*G33 -> 57.4
E34: =SUM(E5:E33) -> 143
