Workbook

Sheet Chips & Snack
B1: ACTUAL INVENTORY COUNT SHEET
B2: AS OF APRIL 2026
B3: COOP STORE
B5: CONTROL NO.: 1
B6: SHELF NO. | C6: SHELF DESCRIPTION | D6: BARCODE | E6: PRODUCT NAME | F6: UNIT COST | G6: QUANTITY | H6: TOTAL COST | I6: REMARKS
B7: 1 | C7: CHIPS & SNACK | D7: 4800631001928 | E7: BOY BAWANG ASSORTED NUTS 85G | F7: 18.15 | H7: =F7*G7 -> 0
B8: 1 | C8: CHIPS & SNACK | D8: 4809011681392 | E8: BOY BAWANG CHILI CHEESE 100G | F8: 16.15
B9: 1 | C9: CHIPS & SNACK | D9: 4809011681392 | E9: BOY BAWANG CHILI CHEESE 100G | F9: 17.65
B10: 1 | C10: CHIPS & SNACK | D10: 4809011681095 | E10: BOY BAWANG CORNICK ADOBO 100G | F10: 30.73 | H10: =F10*G10 -> 0
B11: 1 | C11: CHIPS & SNACK | D11: 4809011681507 | E11: BOY BAWANG CORNICK BBQ FLAVOR 100G | F11: 5.66 | H11: =F11*G11 -> 0
B12: 1 | C12: CHIPS & SNACK | D12: 4809011681507 | E12: BOY BAWANG CORNICK BBQ FLAVOR 100G | F12: 5.66 | H12: =F12*G12 -> 0
B13: 1 | C13: CHIPS & SNACK | D13: 4800631681311 | E13: BOY BAWANG CORNICK LECHON MANOK FLAVOR
B14: 1 | C14: CHIPS & SNACK | D14: 4800631000419 | E14: BOY BAWANG CRACKER NUTS 85G
B15: 1 | C15: CHIPS & SNACK | D15: 4800631000419 | E15: BOY BAWANG CRACKER NUTS 85G
B16: 1 | C16: CHIPS & SNACK | D16: 4809011681378 | E16: BOY BAWANG GARLIC FLAVOR 100G
B17: 1 | C17: CHIPS & SNACK | D17: 4809011681194 | E17: BOY BAWANG HOT GARLIC 100G | F17: 41.15 | H17: =F17*G17 -> 0
B18: 1 | C18: CHIPS & SNACK | D18: 4800631000488 | E18: BOY BAWANG MIXED NUTS GARLIC FLAVOR 100G | F18: 114.79 | H18: =F18*G18 -> 0
B19: 1 | C19: CHIPS & SNACK | D19: 4800631001867 | E19: BOY BAWANG SNACK MIX W/ REAL GARLIC CHIPS 85G | F19: 38.44 | H19: =F19*G19 -> 0
B20: 1 | C20: CHIPS & SNACK | D20: 4800194104128 | E20: CHEEZ ON CHIPS CHEESE FLAVOR 22G | F20: 6.43 | H20: =F20*G20 -> 0
B21: 1 | C21: CHIPS & SNACK | D21: 4800216125919 | E21: CHEEZY CORN CRUNCH CHEESE 150G | F21: 19.75 | H21: =F21*G21 -> 0
B22: 1 | C22: CHIPS & SNACK | D22: 4800216121041 | E22: CHEEZY CORN CRUNCH CHEESE 24G | F22: 5.47 | H22: =F22*G22 -> 0
B23: 1 | C23: CHIPS & SNACK | D23: 4800216121058 | E23: CHEEZY CORN CRUNCH CHEESE 70G | F23: 6.43
B24: 1 | C24: CHIPS & SNACK | D24: 4800216121058 | E24: CHEEZY CORN CRUNCH CHEESE 70G | F24: 15.14
B25: 1 | C25: CHIPS & SNACK | D25: 4800216121911 | E25: CHEEZY CORN CRUNCH RED HOT 22G | F25: 37.50
B26: 1 | C26: CHIPS & SNACK | D26: 4800216122437 | E26: CHEEZY CORN CRUNCH RED HOT 70G | F26: 6.31
B27: 1 | C27: CHIPS & SNACK | D27: 4800016115424 | E27: CHICHARRON NI MANG JUAN KLASIK CHICHARON 90G | F27: 22.86
B28: 1 | C28: CHIPS & SNACK | D28: 4800016110535 | E28: CHICHARRON NI MANG JUAN PAOMBONG 26G | F28: 8.61
B29: 1 | C29: CHIPS & SNACK | D29: 4800016110535 | E29: CHICHARRON NI MANG JUAN PAOMBONG 26G | F29: 39.49
B30: 1 | C30: CHIPS & SNACK | D30: 4800016110511 | E30: CHICHARRON NI MANG JUAN PAOMBONG 90G | F30: 6.43
B31: 1 | C31: CHIPS & SNACK | D31: 4800016110542 | E31: CHICHARRON NI MANG JUAN SUKAT SILI 26G | F31: 30.75
B32: 1 | C32: CHIPS & SNACK | D32: 4800016110542 | E32: CHICHARRON NI MANG JUAN SUKAT SILI 26G | F32: 22.86
B33: 1 | C33: CHIPS & SNACK | D33: 4800016110528 | E33: CHICHARRON NI MANG JUAN SUKAT SILI 90G | F33: 8.61
B34: 1 | C34: CHIPS & SNACK | D34: 4806505854423 | E34: CHICK BOY CALIFORNIA CRUNCH ONION & GARLIC FLAVOR 100G | F34: 31.60
B35: 1 | C35: CHIPS & SNACK | D35: 4806505854225 | E35: CHICK BOY CHEESE FLAVOR 100G
B36: 1 | C36: CHIPS & SNACK | D36: 4806505854232 | E36: CHICK BOY SWEET CORN FLAVOR 100G
B37: 1 | C37: CHIPS & SNACK | D37: 4806505854416 | E37: CHICK BOY TEXAS SMOKED BBQ FLAVOR 100G
B38: 1 | C38: CHIPS & SNACK | D38: 4800016115011 | E38: CHICKN SKIN NI MANG JUAN 17G
B39: 1 | C39: CHIPS & SNACK | D39: 4800016115257 | E39: CHICKN SKIN NI MANG JUAN 70G
B40: 1 | C40: CHIPS & SNACK | D40: 4800016115257 | E40: CHICKN SKIN NI MANG JUAN 70G
B41: 1 | C41: CHIPS & SNACK | D41: 4800016643095 | E41: CHIPPY BBQ FLAVOR 110G
...

Sheet Beverages
B1: ACTUAL INVENTORY COUNT SHEET
B2: ='Chips & Snack'!B2 -> AS OF APRIL 2026
B3: COOP STORE
B5: CONTROL NO.: 2
B6: SHELF NO. | C6: SHELF DESCRIPTION | D6: BARCODE | E6: PRODUCT NAME | F6: UNIT COST | G6: QUANTITY | H6: TOTAL COST | I6: REMARKS
B7: 2 | C7: WINE & ALCOHOLIC BEVERAGES | D7: 8410028900091 | E7: ALFONSO I LIGHT 1L 25%VOL | F7: 273.00
B8: 2 | C8: WINE & ALCOHOLIC BEVERAGES | D8: 8410028902477 | E8: ALFONSO I LIGHT 500ML 25%VOL | F8: 85.00
B9: 2 | C9: WINE & ALCOHOLIC BEVERAGES | D9: 8410028901210 | E9: ALFONSO I PLATINUM 1L | F9: 147.75
B10: 2 | C10: WINE & ALCOHOLIC BEVERAGES | D10: 8410028905041 | E10: ALFONSO LIGHT 1L TRIPACK W/ POCARI
B11: 2 | C11: WINE & ALCOHOLIC BEVERAGES | D11: 8809640030338 | E11: CHINGU SOJU GRAPE 360ML
B12: 2 | C12: WINE & ALCOHOLIC BEVERAGES | D12: 8809640030659 | E12: CHINGU SOJU MANDARIN 360ML
B13: 2 | C13: WINE & ALCOHOLIC BEVERAGES | D13: 4800220608750 | E13: EMBASSY PREMIUM BLENDED WHISKY 750ML
B14: 2 | C14: WINE & ALCOHOLIC BEVERAGES | D14: 4800142118290 | E14: EMPERADOR DOUBLE LIGHT 1L
B15: 2 | C15: WINE & ALCOHOLIC BEVERAGES | D15: 4800142118283 | E15: EMPERADOR DOUBLE LIGHT 750ML
B16: 2 | C16: WINE & ALCOHOLIC BEVERAGES | D16: 4800142110102 | E16: EMPERADOR LIGHT 1L
B17: 2 | C17: WINE & ALCOHOLIC BEVERAGES | D17: 4800142110089 | E17: EMPERADOR LIGHT 750ML
B18: 2 | C18: WINE & ALCOHOLIC BEVERAGES | D18: 8410162100234 | E18: FUNDADOR LIGHT 1L
B19: 2 | C19: WINE & ALCOHOLIC BEVERAGES | D19: 4800130315168 | E19: G.S.M BLUE MOJITO 1L
B20: 2 | C20: WINE & ALCOHOLIC BEVERAGES | D20: 4800130728128 | E20: G.S.M BLUE MOJITO 700ML | F20: 153.50
B21: 2 | C21: WINE & ALCOHOLIC BEVERAGES | D21: 4800130100023 | E21: GINEBRA SAN MIGUEL (BILOG) 350ML | F21: 355.00
B22: 2 | C22: WINE & ALCOHOLIC BEVERAGES | D22: 4806518687179 | E22: GINEBRA SAN MIGUEL 1L | F22: 160.00
B23: 2 | C23: WINE & ALCOHOLIC BEVERAGES | D23: 4800130100030 | E23: GINEBRA SAN MIGUEL 2X2 350ML | F23: 121.50
B24: 2 | C24: WINE & ALCOHOLIC BEVERAGES | D24: 4800130100016 | E24: GINEBRA SAN MIGUEL 4X4 700ML | F24: 186.50
B25: 2 | C25: WINE & ALCOHOLIC BEVERAGES | D25: 4800130121097 | E25: PRIMERA LIGHT PREMIUM SMOOTH BLEND 750ML | F25: 61.00 | H25: =F25*G25 -> 0
B26: 2 | C26: WINE & ALCOHOLIC BEVERAGES | D26: 4800220646851 | E26: TANDUAY FLAVORED MIXES DAIQUIRI 700ML | F26: 164.00
B27: 2 | C27: WINE & ALCOHOLIC BEVERAGES | D27: 4800220645854 | E27: TANDUAY FLAVORED MIXES DARK & STORMY 700ML
B28: 2 | C28: WINE & ALCOHOLIC BEVERAGES | D28: 4800220604752 | E28: TANDUAY SELECT BLENDED RUM 700ML | F28: 120.75
B29: 2 | C29: WINE & ALCOHOLIC BEVERAGES | D29: 8410028125906 | E29: VINO FONTANA RED WINE 750ML | F29: 120.75
B30: 2 | C30: WINE & ALCOHOLIC BEVERAGES | D30: 8410028901289 | E30: VINO FONTANA SWEET RED 750ML | F30: 120.75
B31: 2 | C31: WINE & ALCOHOLIC BEVERAGES | F31: 249.83
B32: 2 | C32: WINE & ALCOHOLIC BEVERAGES | F32: 239.94
B33: 2 | C33: WINE & ALCOHOLIC BEVERAGES
B34: 2 | C34: WINE & ALCOHOLIC BEVERAGES
B35: TOTAL | H35: =SUM(H7:H26) -> 0
B37: PREPARED BY: | E37: WITNESSED BY:
E39: NERISSA C. DULDULAO
B40: OPERATION - STAFF | E40: ACCOUNTING STAFF
B42: CHECKED BY: | E42: APPROVED BY:
B44: JENNY-LYN R. GANIGAN | E44: MICHAEL S. GUTIERREZ
B45: OPERATION - UNIT HEAD | E45: OPERATIONS MANAGER

Sheet Bread
B1: ACTUAL INVENTORY COUNT SHEET
B2: ='Clients Product'!B2 -> AS OF APRIL 2026
B3: COOP STORE
B5: CONTROL NO.: 12
B6: SHELF NO. | C6: SHELF DESCRIPTION | D6: BARCODE | E6: PRODUCT NAME | F6: UNIT COST | G6: QUANTITY | H6: TOTAL COST | I6: REMARKS
B7: 3 | C7: BREAD & BISCUIT | D7: 4800016627279 | E7: BERRY KNOTS STRAW 28G | F7: 57.25
B8: 3 | C8: BREAD & BISCUIT | D8: 4807770100611 | E8: BINGO DOUBLE CHOCO 280G
B9: 3 | C9: BREAD & BISCUIT | D9: 4807770100611 | E9: BINGO DOUBLE CHOCO 280G
B10: 3 | C10: BREAD & BISCUIT | D10: 4807770100536 | E10: BINGO ORANGE 280G
B11: 3 | C11: BREAD & BISCUIT | D11: 4807770100536 | E11: BINGO ORANGE 280G
B12: 3 | C12: BREAD & BISCUIT | D12: 4807770100697 | E12: BINGO VANILLA 280G
B13: 3 | C13: BREAD & BISCUIT | D13: 4807770100697 | E13: BINGO VANILLA 280G
B14: 3 | C14: BREAD & BISCUIT | D14: 4800194153683 | E14: BREAD PAN BUTTER 24G
B15: 3 | C15: BREAD & BISCUIT | D15: 4800194173681 | E15: BREAD PAN BUTTER 42G
B16: 3 | C16: BREAD & BISCUIT | D16: 4800194173223 | E16: BREAD PAN CHEESE&ONION 42G
B17: 3 | C17: BREAD & BISCUIT | D17: 4807770101717 | E17: BREAD STIX 130G
B18: 3 | C18: BREAD & BISCUIT | D18: 4807770100529 | E18: BUTTER COCONUT 168G
B19: 3 | C19: BREAD & BISCUIT | D19: 4807770122170 | E19: BUTTER COCONUT 280G
... B172: 3 | C172: BREAD & BISCUIT | D172: 4800016084201 | E172: WAFRETS CHOCO VANILLA BRIX 24GX10
B173: 3 | C173: BREAD & BISCUIT
B174: 3 | C174: BREAD & BISCUIT
B175: 3 | C175: BREAD & BISCUIT
B176: 3 | C176: BREAD & BISCUIT
B177: 3 | C177: BREAD & BISCUIT
B178: 3 | C178: BREAD & BISCUIT
B179: 3 | C179: BREAD & BISCUIT
B180: 3 | C180: BREAD & BISCUIT
B181: 3 | C181: BREAD & BISCUIT
B182: 3 | C182: BREAD & BISCUIT
B183: 3 | C183: BREAD & BISCUIT
B184: 3 | C184: BREAD & BISCUIT
... B192: 3 | C192: BREAD & BISCUIT
B193: 3 | C193: BREAD & BISCUIT | F193: 57.25
B194: 3 | C194: BREAD & BISCUIT | F194: 31.75
B195: 3 | C195: BREAD & BISCUIT | F195: 36.00
B196: 3 | C196: BREAD & BISCUIT | F196: 58.45
B197: 3 | C197: BREAD & BISCUIT | F197: 65.84
B198: 3 | C198: BREAD & BISCUIT | F198: 51.98
B199: 3 | C199: BREAD & BISCUIT | F199: 65.20
B200: TOTAL
...

Sheet Candies
B1: ACTUAL INVENTORY COUNT SHEET
B2: ='Chips & Snack'!B2 -> AS OF APRIL 2026
B3: COOP STORE
B5: CONTROL NO.: 9
B6: SHELF NO. | C6: SHELF DESCRIPTION | D6: BARCODE | E6: PRODUCT NAME | F6: UNIT COST | G6: QUANTITY | H6: TOTAL COST | I6: REMARKS
B7: 4 | C7: CHOCOLATE & CANDIES | D7: 8886001038011 | E7: BENGBENG 26.5G | F7: 7.50 | H7: =F7*G7 -> 0
B8: 4 | C8: CHOCOLATE & CANDIES | D8: 8886001038011 | E8: BENGBENG 26.5G
B9: 4 | C9: CHOCOLATE & CANDIES | D9: 4800818809712 | E9: CHAMPI CHOCOFILLED CHEWY CHOCOLATE CANDY 165G
B10: 4 | C10: CHOCOLATE & CANDIES | D10: 4800092660788 | E10: CHOCO MUCHO WHITE CHOCOLATE 33G
B11: 4 | C11: CHOCOLATE & CANDIES | D11: 49814521 | E11: CHUPA CHUPS LOLLIPOPS FRUIT FLAVORED 12G
B12: 4 | C12: CHOCOLATE & CANDIES | D12: 8935001721680 | E12: CHUPA CHUPS MILKY STRAWBERRY&CREAM LOLLIPOP 9.5G
B13: 4 | C13: CHOCOLATE & CANDIES | D13: 8935001722106 | E13: CHUPA CHUPS MINI MEGA LOLLIPOPS 10S
B14: 4 | C14: CHOCOLATE & CANDIES | D14: 8935001721673 | E14: CHUPAS CHUPS MILKY CARAMEL LOLLIPO 9.5G
B15: 4 | C15: CHOCOLATE & CANDIES | D15: 4800016964367 | E15: CLOUD 9 CHOCO FUDGE 28G
B16: 4 | C16: CHOCOLATE & CANDIES | D16: 4800010961447 | E16: CLOUD 9 CLASSIC 28G
B17: 4 | C17: CHOCOLATE & CANDIES | D17: 4800016963827 | E17: CLOUD 9 OVERLOAD 50G
B18: 4 | C18: CHOCOLATE & CANDIES | D18: 4800818801389 | E18: COLUM CIOCO LUV-LOV CHOCO WAFER BAR 20G
B19: 4 | C19: CHOCOLATE & CANDIES | D19: 8991001661746 | E19: DELFI TREASURES COOKIES N CREAM 4PCS
... B80: 4 | C80: CHOCOLATE & CANDIES | D80: 4800016475016 | E80: X.O. COFFEE CANDY 175G
B81: 4 | C81: CHOCOLATE & CANDIES
B82: 4 | C82: CHOCOLATE & CANDIES
B83: 4 | C83: CHOCOLATE & CANDIES
B84: 4 | C84: CHOCOLATE & CANDIES
B85: 4 | C85: CHOCOLATE & CANDIES
B86: 4 | C86: CHOCOLATE & CANDIES
B87: 4 | C87: CHOCOLATE & CANDIES
B88: 4 | C88: CHOCOLATE & CANDIES
B89: 4 | C89: CHOCOLATE & CANDIES
B90: 4 | C90: CHOCOLATE & CANDIES
B91: 4 | C91: CHOCOLATE & CANDIES
B92: 4 | C92: CHOCOLATE & CANDIES
... B130: 4 | C130: CHOCOLATE & CANDIES
B131: TOTAL | G131: =SUM(G7:G130) -> 0 | H131: =SUM(H7:H130) -> 0
B133: PREPARED BY: | E133: WITNESSED BY:
E135: NERISSA C. DULDULAO
B136: OPERATION - STAFF | E136: ACCOUNTING STAFF
B138: CHECKED BY: | E138: APPROVED BY:
B140: JENNY-LYN R. GANIGAN | E140: MICHAEL S. GUTIERREZ
B141: OPERATION - UNIT HEAD | E141: OPERATIONS MANAGER

Sheet Milk, Juice, Coffee
B1: ACTUAL INVENTORY COUNT SHEET
B2: =Candies!B2 -> AS OF APRIL 2026
B3: COOP STORE
B5: CONTROL NO.: 5
B6: SHELF NO. | C6: SHELF DESCRIPTION | D6: BARCODE | E6: PRODUCT NAME | F6: UNIT COST | G6: QUANTITY | H6: TOTAL COST | I6: REMARKS
B7: 5 | C7: POWDER MILK, JUICES & COFFEE | D7: 4800575144583 | E7: ALASKA POWDERED MILK DRINK 150G | F7: 35.88 | H7: =F7*G7 -> 0
B8: 5 | C8: POWDER MILK, JUICES & COFFEE | D8: 4800575144590 | E8: ALASKA POWDERED MILK DRINK 300ML | F8: 99.12 | H8: =F8*G8 -> 0
B9: 5 | C9: POWDER MILK, JUICES & COFFEE | D9: 4800575142633 | E9: ALASKA POWDERED MILK DRINK 33G | F9: 8.20 | H9: =F9*G9 -> 0
B10: 5 | C10: POWDER MILK, JUICES & COFFEE | D10: 4800575230453 | E10: ALASKA POWDERED MILK DRINK 450G | F10: 139.44
B11: 5 | C11: POWDER MILK, JUICES & COFFEE | D11: 4800575144613 | E11: ALASKA POWDERED MILK DRINK 840G
B12: 5 | C12: POWDER MILK, JUICES & COFFEE | D12: 4800361388337 | E12: BEARBRAND 1210G
B13: 5 | C13: POWDER MILK, JUICES & COFFEE | D13: 748485401492 | E13: BIRCH TREE 33G
B14: 5 | C14: POWDER MILK, JUICES & COFFEE | D14: 4800010008302 | E14: BLEND 45 SOLUBLE COFFEE 25G
B15: 5 | C15: POWDER MILK, JUICES & COFFEE | D15: 4800818880803 | E15: CHOCQUIK CHOCOMALT POWDERED MILK DRINK 24G
B16: 5 | C16: POWDER MILK, JUICES & COFFEE | D16: 4800361420730 | E16: COFFEE-MATE 80G
B17: 5 | C17: POWDER MILK, JUICES & COFFEE | D17: 888123456781921 | E17: CONVIE EIGHT OCLOCK ORANGE
B18: 5 | C18: POWDER MILK, JUICES & COFFEE | D18: 4800575144958 | E18: COWBELL EVAPSARAP 360NL
B19: 5 | C19: POWDER MILK, JUICES & COFFEE | D19: 4800016014499 | E19: CREAM ALL COFFFEE CREAMER 80G
B20: 5 | C20: POWDER MILK, JUICES & COFFEE | D20: 710535411928 | E20: DON FRANK AGAR-AGAR 1KG
B21: 5 | C21: POWDER MILK, JUICES & COFFEE | D21: 8996001440049 | E21: ENERGEN CEREAL DRINK CHOCOLATE 40G
B22: 5 | C22: POWDER MILK, JUICES & COFFEE | D22: 8996001440049 | E22: ENERGEN CEREAL DRINK CHOCOLATE 40G
... B62: 5 | C62: POWDER MILK, JUICES & COFFEE | D62: 4809013526318 | E62: MR. GULAMAN RED 25G
B63: 5 | C63: POWDER MILK, JUICES & COFFEE | D63: 4809013526356 | E63: MR. GULAMAN WHITE 25G | F63: 409.53
B64: 5 | C64: POWDER MILK, JUICES & COFFEE | D64: 4809013526349 | E64: MR. GULAMAN YELLOW 25G | F64: 8.63
B65: 5 | C65: POWDER MILK, JUICES & COFFEE | D65: 888123456782011 | E65: MT. KALINGA DRIP COFEE 12PCSX10GRAMS | F65: 74.07
B66: 5 | C66: POWDER MILK, JUICES & COFFEE | D66: 888123456781315 | E66: MT. KALINGA GROUND COFFEE 200G | F66: 20.38
B67: 5 | C67: POWDER MILK, JUICES & COFFEE | D67: 888123456781526 | E67: MT. KALINGA GROUND COFFEE 400G | F67: 115.70
B68: 5 | C68: POWDER MILK, JUICES & COFFEE | D68: 4800361388252 | E68: NESCAFE CLASSIC 1.9GX48 | F68: 7.64
B69: 5 | C69: POWDER MILK, JUICES & COFFEE | D69: 4800361393669 | E69: NESCAFE CLASSIC 200G | F69: 11.20
B70: 5 | C70: POWDER MILK, JUICES & COFFEE | D70: 4800361425889 | E70: NESCAFE CLASSIC 23G | F70: 103.32
B71: 5 | C71: POWDER MILK, JUICES & COFFEE | D71: 4800361339186 | E71: NESCAFE CLASSIC 25G | F71: 19.64
B72: 5 | C72: POWDER MILK, JUICES & COFFEE | D72: 4800361339186 | E72: NESCAFE CLASSIC 25G
B73: 5 | C73: POWDER MILK, JUICES & COFFEE | D73: 4800361393621 | E73: NESCAFE CLASSIC DECAF 160G
B74: 5 | C74: POWDER MILK, JUICES & COFFEE | D74: 4800361393683 | E74: NESCAFE CLASSIC RESEALABLE 100G
B75: 5 | C75: POWDER MILK, JUICES & COFFEE | D75: 4800361393645 | E75: NESCAFE CLASSIC RESEALABLE 50G
B76: 5 | C76: POWDER MILK, JUICES & COFFEE | D76: 4800361383493 | E76: NESCAFE CREAMY LATTE 25.5G
B77: 5 | C77: POWDER MILK, JUICES & COFFEE | D77: 4800361413992 | E77: NESCAFE CREAMY LATTE TWINPACK 55G
B78: 5 | C78: POWDER MILK, JUICES & COFFEE | D78: 4800361423588 | E78: NESCAFE CREAMY WHITE SUGAR FREE TWIN PACK 11.2 GRAMS
B79: 5 | C79: POWDER MILK, JUICES & COFFEE | D79: 4800361416726 | E79: NESCAFE CREAMY WHITE TWINPACK 58G
B80: 5 | C80: POWDER MILK, JUICES & COFFEE | D80: 8801055709267 | E80: NESCAFE GOLD INTENSE 100G
...

Sheet Noodles
B1: ACTUAL INVENTORY COUNT SHEET
B2: ='ICE CREAM'!B2 -> AS OF APRIL 2026
B3: COOP STORE
B5: CONTROL NO.: 16
B6: SHELF NO. | C6: SHELF DESCRIPTION | D6: BARCODE | E6: PRODUCT NAME | F6: UNIT COST | G6: QUANTITY | H6: TOTAL COST | I6: REMARKS
B7: 6 | C7: NOODLES | D7: 4806500470352 | E7: DELICIOUS SPAGHETTI 400G | F7: 49.80 | H7: =F7*G7 -> 0
B8: 6 | C8: NOODLES | D8: 4806500470857 | E8: DELICIOUS SULIT PLUS SPAGHETTI 800G | F8: 26.20 | H8: =F8*G8 -> 0
B9: 6 | C9: NOODLES | D9: 4800024575722 | E9: DM PARTY COMBO PCK SWEET STYLE | F9: 48.60 | H9: =F9*G9 -> 0
B10: 6 | C10: NOODLES | D10: 4800024575722 | E10: DM PARTY COMBO PCK SWEET STYLE | F10: 129.10
B11: 6 | C11: NOODLES | D11: 4806500473681 | E11: FAVORITO MACARONI 5KL | F11: 100.30
B12: 6 | C12: NOODLES | D12: 4806500472622 | E12: FAVORITO PANCIT CANTON 200G | F12: 73.86
B13: 6 | C13: NOODLES | D13: 4806500472639 | E13: FAVORITO PANCIT CANTON 400G | F13: 29.17 | H13: =F13*G13 -> 0
B14: 6 | C14: NOODLES | D14: 888123456781868 | E14: FAVORITO RIDGE&SHELL MACARONI 1/2 | F14: 32.00
B15: 6 | C15: NOODLES | D15: 4800110069319 | E15: FIESTA FILIPINO STYLE SPAGHETTI 2IN1 SPAGHETTI & SAUCE | F15: 7.88
B16: 6 | C16: NOODLES | D16: 4800110033402 | E16: FIESTA SPAGHETTI 800G | F16: 14.30
B17: 6 | C17: NOODLES | D17: 4800110060729 | E17: FIESTA SPAGHETTI NOODLES 400G | F17: 8.75 | H17: =F17*G17 -> 0
B18: 6 | C18: NOODLES | D18: 4800110069227 | E18: FIESTA SPAGHETTIPID SWEET STYLE SPAGHETTI AND SAUCE 1.6KG | F18: 8.75 | H18: =F18*G18 -> 0
B19: 6 | C19: NOODLES | D19: 888123456781958 | E19: HAPPY ME INSTANT FRIED NOODLES ASSORTED 70G | F19: 25.50
B20: 6 | C20: NOODLES | D20: 4800528456282 | E20: HOBE BIHON 454G | F20: 25.50
B21: 6 | C21: NOODLES | D21: 4800528456374 | E21: HOBE SPECIAL PALABOK 454G | F21: 9.75
B22: 6 | C22: NOODLES | D22: 4800110026497 | E22: HOMI NOODLES BEEF 55G | F22: 14.00
B23: 6 | C23: NOODLES | D23: 089686171679 | E23: INDOMIE MI GORENG HOT&SPICY 80G | F23: 18.50
B24: 6 | C24: NOODLES | D24: 089686170726 | E24: INDOMIE MI GORENG STIR FRIED ORIGINAL 85G | F24: 18.50
B25: 6 | C25: NOODLES | D25: 4806500670073 | E25: KOMEYA 3Q BIHON
B26: 6 | C26: NOODLES | D26: 4807770270017 | E26: LM BEEF NA BEEF 55G
B27: 6 | C27: NOODLES | D27: 4807770270024 | E27: LM CHICKEN 55G
B28: 6 | C28: NOODLES | D28: 4807770272943 | E28: LM CUP SEAFOOD 40G
B29: 6 | C29: NOODLES | D29: 4807770271168 | E29: LM GO CUP BATCHOY 40G | F29: 18.35
B30: 6 | C30: NOODLES | D30: 4807770311871 | E30: LM GO CUP BATCHOY 40G W/ FREE SKYFLAKES | F30: 22.80
B31: 6 | C31: NOODLES | D31: 4807770271175 | E31: LM GO CUP BULALO 40G | F31: 18.35
B32: 6 | C32: NOODLES | D32: 4807770311864 | E32: LM GO CUP BULALO 40G W/ FREE SKYFLAKES | F32: 20.55
B33: 6 | C33: NOODLES | D33: 4807770311895 | E33: LM GO CUP CHICKEN SOTANGHON 28G W/ SKYFLAKES
B34: 6 | C34: NOODLES | D34: 4807770272653 | E34: LM GO CUP JJAMPPONG 40G W/ SKYFLAKES
B35: 6 | C35: NOODLES | D35: 4807770273810 | E35: LM GO CUP SPICY BATCHOY 40G
B36: 6 | C36: NOODLES | D36: 4807770273612 | E36: LM GO CUP SPICY BULALO 40G
B37: 6 | C37: NOODLES | D37: 4807770270116 | E37: LM ITNOK CHICKEN 50G
B38: 6 | C38: NOODLES | D38: 4807770273100 | E38: LM JJAMPONG FLAVOR 55G
B39: 6 | C39: NOODLES | D39: 4807770272813 | E39: LM LA PAZ BATCHOY 55G
B40: 6 | C40: NOODLES | D40: 4807770273698 | E40: LM PANCIT CANTON CHILIMANSI 80G
B41: 6 | C41: NOODLES | D41: 4807770274480 | E41: LM PANCIT CANTON CHILIMANSI KASALO PACK 120G
...

Sheet S&C Goods
B1: ACTUAL INVENTORY COUNT SHEET
B2: =Noodles!B2 -> AS OF APRIL 2026
B3: COOP STORE
B5: CONTROL NO.: 4
B6: SHELF NO. | C6: SHELF DESCRIPTION | D6: BARCODE | E6: PRODUCT NAME | F6: UNIT COST | G6: QUANTITY | H6: TOTAL COST | I6: REMARKS
B7: 7 | C7: SPREAD & CANNED GOODS | D7: 748485700014 | E7: 555 TUNA ADOBO 155G | F7: 28.95
B8: 7 | C8: SPREAD & CANNED GOODS | D8: 748485700021 | E8: 555 TUNA AFRITADA 155G
B9: 7 | C9: SPREAD & CANNED GOODS | D9: 748485700038 | E9: 555 TUNA CALDERETA 155G
B10: 7 | C10: SPREAD & CANNED GOODS | D10: 748485700045 | E10: 555 TUNA MECHADO 155G
B11: 7 | C11: SPREAD & CANNED GOODS | D11: 4800575110373 | E11: ALASKA CLASSIC EVAPORATED FILLED MILK 370ML
B12: 7 | C12: SPREAD & CANNED GOODS | D12: 4800575110373 | E12: ALASKA CLASSIC EVAPORATED FILLED MILK 370ML
B13: 7 | C13: SPREAD & CANNED GOODS | D13: 4800575130302 | E13: ALASKA CONDENSADA 300ML
B14: 7 | C14: SPREAD & CANNED GOODS | D14: 4800575140158 | E14: ALASKA EVAPORADA CREAMER 140ML
B15: 7 | C15: SPREAD & CANNED GOODS | D15: 4800575140370 | E15: ALASKA EVAPORADA CREAMER 360ML
B16: 7 | C16: SPREAD & CANNED GOODS | D16: 4800575140370 | E16: ALASKA EVAPORADA CREAMER 360ML
B17: 7 | C17: SPREAD & CANNED GOODS | D17: 4800575241664 | E17: ALASKA SWEETENED CONDENSED 377G BUY1TAKE1
B18: 7 | C18: SPREAD & CANNED GOODS | D18: 4800575120303 | E18: ALASKA SWEETENED CONDENSED MILK 300ML
B19: 7 | C19: SPREAD & CANNED GOODS | D19: 748485400808 | E19: ANGEL CONDENSADA 380G
B20: 7 | C20: SPREAD & CANNED GOODS | D20: 748485400716 | E20: ANGEL EVAPORADA 410ML | F20: 27.25
B21: 7 | C21: SPREAD & CANNED GOODS | D21: 748485401225 | E21: ANGEL KREMDENSADA 410ML | F21: 29.47
B22: 7 | C22: SPREAD & CANNED GOODS | D22: 748485801803 | E22: ARGENTINA CB 100G | F22: 17.86
B23: 7 | C23: SPREAD & CANNED GOODS | D23: 748485800431 | E23: ARGENTINA CORN BEEF 150G | F23: 33.17
B24: 7 | C24: SPREAD & CANNED GOODS | D24: 748485800011 | E24: ARGENTINA CORN BEEF 175G | F24: 50.48
B25: 7 | C25: SPREAD & CANNED GOODS | D25: 748485800011 | E25: ARGENTINA CORN BEEF 175G | F25: 59.55
B26: 7 | C26: SPREAD & CANNED GOODS | D26: 748485800035 | E26: ARGENTINA CORNED BEEF 260G | F26: 25.50
B27: 7 | C27: SPREAD & CANNED GOODS | D27: 748485804057 | E27: ARGENTINA GINILING 100G | F27: 34.58
B28: 7 | C28: SPREAD & CANNED GOODS | D28: 748485804064 | E28: ARGENTINA GINILING 250G | F28: 39.08
B29: 7 | C29: SPREAD & CANNED GOODS | D29: 748485801490 | E29: ARGENTINA MEAT LOAF 150G | F29: 54.89
B30: 7 | C30: SPREAD & CANNED GOODS | D30: 748485800233 | E30: ARGENTINA MEAT LOAF 170G | F30: 21.90
B31: 7 | C31: SPREAD & CANNED GOODS | D31: 748485800448 | E31: ARGENTINA MEAT LOAF 250G | F31: 32.80
... B60: 7 | C60: SPREAD & CANNED GOODS | D60: 4800024570611 | E60: DM PINEAPPLE TIDBITS 115G | F60: 232.05
B61: 7 | C61: SPREAD & CANNED GOODS | D61: 4800024011862 | E61: DM TIDBITS 822G | F61: 32.84 | H61: =F61*G61 -> 0
B62: 7 | C62: SPREAD & CANNED GOODS | D62: 9557727929202 | E62: DOREEN SWEETENED CONDENSED CREAMER 390G | F62: 93.84 | H62: =F62*G62 -> 0
B63: 7 | C63: SPREAD & CANNED GOODS | D63: 4808647020094 | E63: EDEN CHEESE ORIGINAL 160G | F63: 76.14 | H63: =F63*G63 -> 0
B64: 7 | C64: SPREAD & CANNED GOODS | D64: 4808647020094 | E64: EDEN CHEESE ORIGINAL 160G | F64: 32.18 | H64: =F64*G64 -> 0
B65: 7 | C65: SPREAD & CANNED GOODS | D65: 4808647020100 | E65: EDEN CHEESE ORIGINAL 440G | F65: 23.40 | H65: =F65*G65 -> 0
B66: 7 | C66: SPREAD & CANNED GOODS | D66: 7622210278371 | E66: EDEN MAYO 220ML | F66: 116.00 | H66: =F66*G66 -> 0
B67: 7 | C67: SPREAD & CANNED GOODS | D67: 7622210892126 | E67: EDEN SULIT PACK ORIGINAL 45G | F67: 38.00 | H67: =F67*G67 -> 0
B68: 7 | C68: SPREAD & CANNED GOODS | D68: 4806502727607 | E68: GAR DELICIA MILKY CHOCOLATE SPREAD 200G | F68: 24.24 | H68: =F68*G68 -> 0
B69: 7 | C69: SPREAD & CANNED GOODS | D69: 4806517042597 | E69: GOYA SPREAD 350G BUY 2 SAVE | F69: 26.00 | H69: =F69*G69 -> 0
...

Sheet Condiments
B1: ACTUAL INVENTORY COUNT SHEET
B2: ='S&C Goods'!B2 -> AS OF APRIL 2026
B3: COOP STORE
B5: CONTROL NO.: 3
B6: SHELF NO. | C6: SHELF DESCRIPTION | D6: BARCODE | E6: PRODUCT NAME | F6: UNIT COST | G6: QUANTITY | H6: TOTAL COST | I6: REMARKS
B7: 8 | C7: CONDIMENTS | D7: 4801958393109 | E7: AJI CRISPY FRY BREADING MIX GARLIC 62G | F7: 15.39
B8: 8 | C8: CONDIMENTS | D8: 4801958390108 | E8: AJI CRISPY FRY BREADING MIX ORIGINAL 62G | F8: 41.36
B9: 8 | C9: CONDIMENTS | D9: 4801958240007 | E9: AJI-NO-MOTO UMAMI SEASONING 100G | F9: 11.66
B10: 8 | C10: CONDIMENTS | D10: 4801958300107 | E10: AJI-NO-MOTO UMAMI SEASONING 10GX18
B11: 8 | C11: CONDIMENTS | D11: 4801958341100 | E11: AJI-NO-MOTO UMAMI SEASONING 11GX12S
B12: 8 | C12: CONDIMENTS | D12: 4801958310007 | E12: AJI-NO-MOTO UMAMI SEASONING 1KG
B13: 8 | C13: CONDIMENTS | D13: 4801958342008 | E13: AJI-NO-MOTO UMAMI SEASONING 24G
B14: 8 | C14: CONDIMENTS | D14: 4801958250006 | E14: AJI-NO-MOTO UMAMI SEASONING 250G
B15: 8 | C15: CONDIMENTS | D15: 4801958260005 | E15: AJI-NO-MOTO UMAMI SEASONING 500G
B16: 8 | C16: CONDIMENTS | D16: 4801958146002 | E16: AJI-NO-MOTO UMAMI SEASONING 50G
B17: 8 | C17: CONDIMENTS | D17: 888123456782040 | E17: ALLYSSA PALM OIL 17L
B18: 8 | C18: CONDIMENTS | D18: 4809014863702 | E18: ALLYSSA PALM OIL 1L
B19: 8 | C19: CONDIMENTS | D19: 0745125096018 | E19: ALLYSSA SAVERS PATIS 1L
B20: 8 | C20: CONDIMENTS | D20: 0745125096032 | E20: ALLYSSA SAVERS SOY SAUCE 1L
B21: 8 | C21: CONDIMENTS | D21: 888123456782034 | E21: BAIS SUGAR WASH 1/2
... B87: 8 | C87: CONDIMENTS | D87: 888123456782032 | E87: LUISITA SUGAR WHITE 1/2
B88: 8 | C88: CONDIMENTS | D88: 888123456782033 | E88: LUISITA SUGAR WHITE 1/4 | F88: 30.00
B89: 8 | C89: CONDIMENTS | D89: 888123456781210 | E89: LUISITA SUGAR WHITE SACK | F89: 60.00
B90: 8 | C90: CONDIMENTS | D90: 48025522 | E90: MAGGI MAGIC SARAP 8G | F90: 13.56
B91: 8 | C91: CONDIMENTS | D91: 888123456781834 | E91: MAGGI MAGIC SARAP BUY 32 GET FREE 1 TOM YAM | F91: 71.75
B92: 8 | C92: CONDIMENTS | D92: 4804888804189 | E92: MAMA SITAS ACHUETE POWDER 10G | F92: 26.43
B93: 8 | C93: CONDIMENTS | D93: 025407803603 | E93: MAMA SITAS CALDERETA SPICY SAUCE MIX 50G | F93: 23.05
B94: 8 | C94: CONDIMENTS | D94: 4806512022099 | E94: MAMA SITAS ILOCANO PINAPAITAN BITTER STEW MIX 40G | F94: 16.88
B95: 8 | C95: CONDIMENTS | D95: 025407803313 | E95: MAMA SITAS KARE KARE PEANUT SAUCE MIX 57G | F95: 99.09 | H95: =F95*G95 -> 0
B96: 8 | C96: CONDIMENTS | D96: 025407805201 | E96: MAMA SITAS MENUDO/AFRITADA MIX 30G | F96: 56.54 | H96: =F96*G96 -> 0
B97: 8 | C97: CONDIMENTS | D97: 4806512026387 | E97: MAMA SITAS ORIGINAL OYSTER SAUCE 60G | F97: 14.59 | H97: =F97*G97 -> 0
B98: 8 | C98: CONDIMENTS | D98: 4804888809788 | E98: MAMA SITAS OYSTER SAUCE 2KG | F98: 31.04 | H98: =F98*G98 -> 0
B99: 8 | C99: CONDIMENTS | D99: 4804888809474 | E99: MAMA SITAS OYSTER SAUCE 30G | F99: 5.61 | H99: =F99*G99 -> 0
B100: 8 | C100: CONDIMENTS | D100: 4804888804868 | E100: MAMA SITAS OYSTER SAUCE 4.2KG | F100: 21.67 | H100: =F100*G100 -> 0
B101: 8 | C101: CONDIMENTS | D101: 4806512023522 | E101: MAMA SITAS OYSTER SAUCE 90G | F101: 35.79 | H101: =F101*G101 -> 0
B102: 8 | C102: CONDIMENTS | D102: 025407806680 | E102: MAMA SITAS PALABOK ORIENTAL GRAVY MIX 57G | F102: 36.00 | H102: =F102*G102 -> 0
B103: 8 | C103: CONDIMENTS | D103: 4801668600641 | E103: MANG TOMAS ALL AROUND SARSA 100G | F103: 12.60 | H103: =F103*G103 -> 0
B104: 8 | C104: CONDIMENTS | D104: 4801668100264 | E104: MANG TOMAS ALL AROUND SARSA 325G | F104: 10.25 | H104: =F104*G104 -> 0
B105: 8 | C105: CONDIMENTS | D105: 4801668100288 | E105: MANG TOMAS SIGA HOT AND SPICY 325G | F105: 61.00
B106: 8 | C106: CONDIMENTS | D106: 4809013526448 | E106: MR. GULAMAN BLACK 25G | F106: 20.88
...

Sheet Toiletries
B1: ACTUAL INVENTORY COUNT SHEET
B2: ='Milk, Juice, Coffee'!B2 -> AS OF APRIL 2026
B3: COOP STORE
B5: CONTROL NO.: 6
B6: SHELF NO. | C6: SHELF DESCRIPTION | D6: BARCODE | E6: PRODUCT NAME | F6: UNIT COST | G6: QUANTITY | H6: TOTAL COST | I6: REMARKS
B7: 9 | C7: TOILETRIES & PERSONAL HYGIENE | D7: 888123456781807 | E7: ALCOLUXX ISOPROPYL ALCOHOL ALCORADE 70% SOLUTION 500ML | F7: 75.00 | H7: =F7*G7 -> 0
B8: 9 | C8: TOILETRIES & PERSONAL HYGIENE | D8: 4809016162056 | E8: BACTIRAND HAND SANITIZER PUMP 500ML | F8: 110.00
B9: 9 | C9: TOILETRIES & PERSONAL HYGIENE | D9: 4800417005225 | E9: BENCH ATLANTIS 75ML | F9: 88.00
B10: 9 | C10: TOILETRIES & PERSONAL HYGIENE | D10: 4800417060415 | E10: BENCH CLAY DOH 4G | F10: 4.96 | H10: =F10*G10 -> 0
B11: 9 | C11: TOILETRIES & PERSONAL HYGIENE | D11: 4800417059549 | E11: BENCH DAILY SCENT COLOGNE HAPPY HOUR 125ML | F11: 54.00
B12: 9 | C12: TOILETRIES & PERSONAL HYGIENE | D12: 4800417059556 | E12: BENCH DAILY SCENT COLOGNE INDIAN SUMMER 125ML | F12: 54.00
B13: 9 | C13: TOILETRIES & PERSONAL HYGIENE | D13: 4800417059563 | E13: BENCH DAILY SCENT COLOGNE LAZY AFTERNOON 125ML | F13: 27.00
B14: 9 | C14: TOILETRIES & PERSONAL HYGIENE | D14: 4800417059433 | E14: BENCH DAILY SCENT COLOGNE LAZY AFTERNOON 50ML | F14: 54.00
B15: 9 | C15: TOILETRIES & PERSONAL HYGIENE | D15: 4800417059594 | E15: BENCH DAILY SCENT COLOGNE SUNDAY MORNING 125ML | F15: 115.00
B16: 9 | C16: TOILETRIES & PERSONAL HYGIENE | D16: 4800417005249 | E16: BENCH EIGHT BODY SPRAY 100ML | F16: 38.00
B17: 9 | C17: TOILETRIES & PERSONAL HYGIENE | D17: 4806525621340 | E17: BEYBIKO BABY WIPES FLORAL BLOSSOM 80+20WIPES | F17: 38.00
B18: 9 | C18: TOILETRIES & PERSONAL HYGIENE | D18: 4806525621333 | E18: BEYBIKO BABY WIPES UNSCENTED 80WIPES+20FREE | F18: 76.29
B19: 9 | C19: TOILETRIES & PERSONAL HYGIENE | D19: 4806525621098 | E19: BEYBIKO DIAPERS MEDIUM 12S | F19: 187.20
B20: 9 | C20: TOILETRIES & PERSONAL HYGIENE | D20: 4806525621012 | E20: BEYBIKO DIAPERS MEDIUM 30S | F20: 68.64
B21: 9 | C21: TOILETRIES & PERSONAL HYGIENE | D21: 4806525621081 | E21: BEYBIKO DIAPERS SMALL 12S | F21: 169.42
B22: 9 | C22: TOILETRIES & PERSONAL HYGIENE | D22: 4806525621005 | E22: BEYBIKO DIAPERS SMALL 30S | F22: 58.03
... B212: 9 | C212: TOILETRIES & PERSONAL HYGIENE | D212: 4902430634014 | E212: PANTENE HAIR FALL CONTROL SUPPLEMENT CONDITIONER 13ML | F212: 25.00
B213: 9 | C213: TOILETRIES & PERSONAL HYGIENE | D213: 4902430634014 | E213: PANTENE HAIR FALL CONTROL SUPPLEMENT CONDITIONER 13ML
B214: 9 | C214: TOILETRIES & PERSONAL HYGIENE | D214: 4902430698146 | E214: PANTENE SHAMPOO TOTAL DAMAGE CARE 15ML
B215: 9 | C215: TOILETRIES & PERSONAL HYGIENE | D215: 4902430759960 | E215: PANTENE SILKY SMOOTH CARE SHAMPOO 12ML
B216: 9 | C216: TOILETRIES & PERSONAL HYGIENE | D216: 4800060084806 | E216: PURITY COTTON BALLS 140S
B217: 9 | C217: TOILETRIES & PERSONAL HYGIENE | D217: 4800060084905 | E217: PURITY COTTON BALLS 300S
B218: 9 | C218: TOILETRIES & PERSONAL HYGIENE | D218: 4800060084707 | E218: PURITY COTTON BALLS 30S
B219: 9 | C219: TOILETRIES & PERSONAL HYGIENE | D219: 4800060008475 | E219: PURITY COTTON BALLS 50S
B220: 9 | C220: TOILETRIES & PERSONAL HYGIENE | D220: 4800060080709 | E220: PURITY COTTON BUDS 190+10 TIPS
B221: 9 | C221: TOILETRIES & PERSONAL HYGIENE | D221: 4800060080808 | E221: PURITY COTTON BUDS 400 TIPS
B222: 9 | C222: TOILETRIES & PERSONAL HYGIENE | D222: 4800060075200 | E222: PURITY COTTON ROLL 10G
B223: 9 | C223: TOILETRIES & PERSONAL HYGIENE | D223: 4800060075408 | E223: PURITY COTTON ROLL 45G
B224: 9 | C224: TOILETRIES & PERSONAL HYGIENE | D224: 4800060906313 | E224: PURITY COTTON ROLL NEGOSYO PACK
... B310: 9 | C310: TOILETRIES & PERSONAL HYGIENE | D310: 4800045410316 | E310: WHITE ROSE KOJIC WHITENING SOAP 60G
B311: 9 | C311: TOILETRIES & PERSONAL HYGIENE
B312: 9 | C312: TOILETRIES & PERSONAL HYGIENE
B313: 9 | C313: TOILETRIES & PERSONAL HYGIENE
B314: 9 | C314: TOILETRIES & PERSONAL HYGIENE
B315: 9 | C315: TOILETRIES & PERSONAL HYGIENE
...

Sheet Household
B1: ACTUAL INVENTORY COUNT SHEET
B2: =Toiletries!B2 -> AS OF APRIL 2026
B3: COOP STORE
B5: CONTROL NO.: 2
B6: SHELF NO. | C6: SHELF DESCRIPTION | D6: BARCODE | E6: PRODUCT NAME | F6: UNIT COST | G6: QUANTITY | H6: TOTAL COST | I6: REMARKS
B7: 10 | C7: HOUSEHOLD ITEM | D7: 4809014971230 | E7: ACTIVE LYSOL 250ML | F7: 55.00 | H7: =F7*G7 -> 0
B8: 10 | C8: HOUSEHOLD ITEM | D8: 4800603124044 | E8: ACTIVE LYSOL 500ML
B9: 10 | C9: HOUSEHOLD ITEM | D9: 888123456781619 | E9: ADVANCE POLISHING CAKE ALL PURPOSE CLEANER
B10: 10 | C10: HOUSEHOLD ITEM | D10: 4800067600658 | E10: ALBATROSS APPLE 100G
B11: 10 | C11: HOUSEHOLD ITEM | D11: 4800067600139 | E11: ALBATROSS APPLE REFILL 50G
B12: 10 | C12: HOUSEHOLD ITEM | D12: 4800067600351 | E12: ALBATROSS KIWI REFILL 100G
B13: 10 | C13: HOUSEHOLD ITEM | D13: 4800067600191 | E13: ALBATROSS KIWI REFILL 50G
B14: 10 | C14: HOUSEHOLD ITEM | D14: 4800067600108 | E14: ALBATROSS LEMON REFILL 50G
B15: 10 | C15: HOUSEHOLD ITEM | D15: 4800067608159 | E15: ALBATROSS MELON 100G
B16: 10 | C16: HOUSEHOLD ITEM | D16: 4800067608074 | E16: ALBATROSS MELON 50G
B17: 10 | C17: HOUSEHOLD ITEM | D17: 4800067600184 | E17: ALBATROSS SAMBA 50G
B18: 10 | C18: HOUSEHOLD ITEM | D18: 4800067600405 | E18: ALBATROSS SAMPAGUITA REFILL 100G
B19: 10 | C19: HOUSEHOLD ITEM | D19: 4800067600283 | E19: ALBATROSS SAMPAGUITA REFILL 50G
... B134: 10 | C134: HOUSEHOLD ITEM | D134: 4800888190970 | E134: SURF BAR CHERRY BLOSSOM 120G
B135: 10 | C135: HOUSEHOLD ITEM | D135: 4800888190987 | E135: SURF BAR CHERRY BLOSSOM 380G | F135: 32.00 | H135: =F135*G135 -> 0
B136: 10 | C136: HOUSEHOLD ITEM | D136: 4800888136749 | E136: SURF BAR OXYBUBBLES KALAMANSI 380G | F136: 55.00 | H136: =F136*G136 -> 0
B137: 10 | C137: HOUSEHOLD ITEM | D137: 4800888136770 | E137: SURF BAR SUN FRESH 120G | F137: 32.00 | H137: =F137*G137 -> 0
B138: 10 | C138: HOUSEHOLD ITEM | D138: 4800888157614 | E138: SURF FABCON BLOSSOM FRESH 25ML | F138: 62.75 | H138: =F138*G138 -> 0
B139: 10 | C139: HOUSEHOLD ITEM | D139: 4800888157614 | E139: SURF FABCON BLOSSOM FRESH 25ML | F139: 41.50 | H139: =F139*G139 -> 0
B140: 10 | C140: HOUSEHOLD ITEM | D140: 8934868139362 | E140: SURF FABCON CHARCOAL FRESH 25ML | F140: 62.75 | H140: =F140*G140 -> 0
B141: 10 | C141: HOUSEHOLD ITEM | D141: 8934868094982 | E141: SURF FABCON FRENCH PERFUME 25ML | F141: 27.25 | H141: =F141*G141 -> 0
B142: 10 | C142: HOUSEHOLD ITEM | D142: 8934868110170 | E142: SURF FABCON LUXE PERFUME 25ML | F142: 41.50 | H142: =F142*G142 -> 0
B143: 10 | C143: HOUSEHOLD ITEM | D143: 8934868110170 | E143: SURF FABCON LUXE PERFUME 25ML | F143: 13.95 | H143: =F143*G143 -> 0
B144: 10 | C144: HOUSEHOLD ITEM | D144: 4800888287984 | E144: SURF FABCON LUXE PERFUME 28ML BUY 5 GET 1 FREE | F144: 19.47 | H144: =F144*G144 -> 0
B145: 10 | C145: HOUSEHOLD ITEM | D145: 8934868125211 | E145: SURF FABCON MAGICAL BLOOM 28ML | F145: 279.34 | H145: =F145*G145 -> 0
B146: 10 | C146: HOUSEHOLD ITEM | D146: 4800888151834 | E146: SURF FABCON TAWAS 61G | F146: 20.20 | H146: =F146*G146 -> 0
... B192: 10 | C192: HOUSEHOLD ITEM | D192: 4800047840012 | E192: ZONROX BLEACH ORIGINAL 1L | F192: 27.45 | H192: =F192*G192 -> 0
B193: 10 | C193: HOUSEHOLD ITEM | D193: 4800047840036 | E193: ZONROX BLEACH ORIGINAL 250ML | F193: 27.45
B194: 10 | C194: HOUSEHOLD ITEM | D194: 4800047840029 | E194: ZONROX BLEACH ORIGINAL 500ML | F194: 10.35
B195: 10 | C195: HOUSEHOLD ITEM | D195: 4800047840029 | E195: ZONROX BLEACH ORIGINAL 500ML | F195: 25.45
B196: 10 | C196: HOUSEHOLD ITEM | D196: 4800047840296 | E196: ZONROX BLEACH SCENTED LEMON 100ML | F196: 11.17
B197: 10 | C197: HOUSEHOLD ITEM | D197: 4800047840272 | E197: ZONROX BLEACH SCENTED LEMON 500ML | F197: 25.45
B198: 10 | C198: HOUSEHOLD ITEM | D198: 4800047841729 | E198: ZONROX COLORSAFE BLEACH BLOSSOM FRESH 225ML | F198: 21.88
B199: 10 | C199: HOUSEHOLD ITEM | D199: 4800047841712 | E199: ZONROX COLORSAFE BLEACH BLOSSOM FRESH 450ML | F199: 11.17
B200: 10 | C200: HOUSEHOLD ITEM | D200: 4800047841712 | E200: ZONROX COLORSAFE BLEACH BLOSSOM FRESH 450ML | F200: 5.41
...

Sheet Clients Product
B1: ACTUAL INVENTORY COUNT SHEET
B2: ='Other Products'!B2 -> AS OF APRIL 2026
B3: COOP STORE
B5: CONTROL NO.: 11
B6: SHELF NO. | C6: SHELF DESCRIPTION | D6: BARCODE | E6: PRODUCT NAME | F6: UNIT COST | G6: QUANTITY | H6: TOTAL COST | I6: REMARKS
B7: 11 | C7: CLIENTS PRODUCT | D7: 888123456781983 | E7: AEVA 001 | F7: 180.00 | H7: =F7*G7 -> 0
B8: 11 | C8: CLIENTS PRODUCT | D8: 888123456781985 | E8: AEVA 003 | F8: 250.00 | H8: =F8*G8 -> 0
B9: 11 | C9: CLIENTS PRODUCT | D9: 888123456781986 | E9: AEVA 004 | F9: 300.00 | H9: =F9*G9 -> 0
B10: 11 | C10: CLIENTS PRODUCT | D10: 888123456781991 | E10: AEVA 005 - MINI | F10: 150.00
B11: 11 | C11: CLIENTS PRODUCT | D11: 888123456781992 | E11: AEVA 006 - W/ DESIGN SMALL | F11: 300.00 | H11: =F11*G11 -> 0
B12: 11 | C12: CLIENTS PRODUCT | D12: 888123456781943 | E12: AURORAS KIT TEA COFFEE PEANUT | F12: 450.00 | H12: =F12*G12 -> 0
B13: 11 | C13: CLIENTS PRODUCT | D13: 888123456781941 | E13: AURORAS KIT TEA HONEY PURO
B14: 11 | C14: CLIENTS PRODUCT | D14: 888123456781942 | E14: AURORAS KIT TEA PEANUT BUTTER CHIA SEED 340G
B15: 11 | C15: CLIENTS PRODUCT | D15: 888123456781939 | E15: AURORAS KIT TEA SUKANG ATSARA
B16: 11 | C16: CLIENTS PRODUCT | D16: 888123456781940 | E16: AURORAS KIT TEA SUKANG SINAMAK
B17: 11 | C17: CLIENTS PRODUCT | D17: 0764460243888 | E17: BIGAS MAIS CORN GRITS 1KL
B18: 11 | C18: CLIENTS PRODUCT | D18: 888123456782026 | E18: BUTCHERON MUSHROOM CHIPS
B19: 11 | C19: CLIENTS PRODUCT | D19: 888123456781960 | E19: CAPINTALAN FOOD PRODUCTS TURMERIC W/ LEMON GRASS 150G
B20: 11 | C20: CLIENTS PRODUCT | D20: CLMA62611-2X-BLKCATN | E20: COMPRESSION SHORTS BLACK CATION 2X
B21: 11 | C21: CLIENTS PRODUCT | D21: CLMA62511-S-GRYHBL | E21: COMPRESSION SHORTS GRAYISH BLUE S
B22: 11 | C22: CLIENTS PRODUCT | D22: 888123456781946 | E22: DINA CHEESY TART
B23: 11 | C23: CLIENTS PRODUCT | D23: 888123456781949 | E23: DINA CHEWY BROWNIES
B24: 11 | C24: CLIENTS PRODUCT | D24: 888123456781948 | E24: DINA REVEL BAR
... B36: 11 | C36: CLIENTS PRODUCT | D36: OLFM10313-AVAH-S | E36: FEM PANTY OG BIKINI HIPSTER COTTON PLAIN-AVAH S
B37: 11 | C37: CLIENTS PRODUCT | D37: OLFM10313-AVAH-XL | E37: FEM PANTY OG BIKINI HIPSTER COTTON PLAIN-AVAH XL | F37: 75.00 | H37: =F37*G37 -> 0
B38: 11 | C38: CLIENTS PRODUCT | D38: OLFM10013-PAIGE-M | E38: FEM PANTY OG COTTON PLAIN-PAIGE M | F38: 140.00 | H38: =F38*G38 -> 0
B39: 11 | C39: CLIENTS PRODUCT | D39: OLFM10013-PAIGE-S | E39: FEM PANTY OG COTTON PLAIN-PAIGE S | F39: 160.00 | H39: =F39*G39 -> 0
B40: 11 | C40: CLIENTS PRODUCT | D40: OLFM10013-PAIGE-XL | E40: FEM PANTY OG COTTON PLAIN-PAIGE XL | F40: 160.00 | H40: =F40*G40 -> 0
B41: 11 | C41: CLIENTS PRODUCT | D41: OLFM50011-WILLOW-M | E41: FEM SHORTS IG WOVEN 100% COTTON-ASSORTED PATTERN M | F41: 160.00 | H41: =F41*G41 -> 0
B42: 11 | C42: CLIENTS PRODUCT | D42: OLFM50011-WILLOW-S | E42: FEM SHORTS IG WOVEN 100% COTTON-ASSORTED PATTERN S | F42: 75.00 | H42: =F42*G42 -> 0
B43: 11 | C43: CLIENTS PRODUCT | D43: 888123456781997 | E43: GARLIC MAYO 300G | F43: 105.00 | H43: =F43*G43 -> 0
B44: 11 | C44: CLIENTS PRODUCT | D44: 888123456781998 | E44: GARLIC MAYO 500G | F44: 293.83 | H44: =F44*G44 -> 0
B45: 11 | C45: CLIENTS PRODUCT | D45: CLMP11516-2X-ASSTD-F | E45: HANDFORD MENS BRIEFS IG BUY5+1FREE 2X | F45: 227.33
B46: 11 | C46: CLIENTS PRODUCT | D46: CLMP80111-M-MDNTBLU | E46: HANDFORD MENS R-NECK SHIRT MODERN FIT SHORT SLEEVE MIDNIGHT BLUE M | F46: 120.00
B47: 11 | C47: CLIENTS PRODUCT | D47: CLMA60211-M-BLACK | E47: HANFORD ATHLETIC MENS SPANDEX SUPPORTER BRIEFS M | F47: 120.00
B48: 11 | C48: CLIENTS PRODUCT | D48: CLMA60211-S-BLACK | E48: HANFORD ATHLETIC MENS SPANDEX SUPPORTER BRIEFS S | F48: 120.00
B49: 11 | C49: CLIENTS PRODUCT | D49: CLMA60211-XL-BLACK | E49: HANFORD ATHLETIC MENS SPANDEX SUPPORTER BRIEFS XL | F49: 120.00
B50: 11 | C50: CLIENTS PRODUCT | D50: CLMA63101-XL-NATURAL | E50: HANFORD ATHLETIC MENS SUPPORTER 3S | F50: 60.00
B51: 11 | C51: CLIENTS PRODUCT | D51: CLMA63101-L-NATURAL | E51: HANFORD ATHLETIC MENS SUPPORTER 3S L | F51: 60.00
B52: 11 | C52: CLIENTS PRODUCT | D52: CLMA63111-L-BLACK | E52: HANFORD ATHLETIC MENS SUPPORTER 3S L | F52: 50.00
...

Sheet ICE CREAM
B1: ACTUAL INVENTORY COUNT SHEET
B2: =OTC!B2 -> AS OF APRIL 2026
B3: COOP STORE
B5: CONTROL NO.: 15
B6: SHELF NO. | C6: SHELF DESCRIPTION | D6: BARCODE | E6: PRODUCT NAME | F6: UNIT COST | G6: QUANTITY | H6: TOTAL COST | I6: REMARKS
B7: 12 | C7: ICE CREAM | D7: 4800086050519 | E7: CORNETTO UBE CARAMEL 110ML | F7: 18.20 | H7: =F7*G7 -> 0
B8: 12 | C8: ICE CREAM | D8: 8999999035631 | E8: MAGNUM MINI VANILLA ALMOND 45ML
B9: 12 | C9: ICE CREAM | D9: 888123456781567 | E9: MAGNUM MINI VANILLA ALMOND 45ML RETAIL
B10: 12 | C10: ICE CREAM | D10: 4800086005610 | E10: MAGNUM VANILLA ALMOND 80ML
B11: 12 | C11: ICE CREAM | D11: 4800086049681 | E11: SEL 3IN1 CHOCO MANGO UBE 750ML
B12: 12 | C12: ICE CREAM | D12: 4800086044372 | E12: SEL BDAY BASO CHOCO 400ML
B13: 12 | C13: ICE CREAM | D13: 4800086044365 | E13: SEL BDAY BASO UBE 400ML
B14: 12 | C14: ICE CREAM | D14: 4800086045751 | E14: SEL BOOM BOOM CHOCOLATE 60ML
B15: 12 | C15: ICE CREAM | D15: 4800086047472 | E15: SEL BOOM BOOM COOKIES & CREAM 60ML
B16: 12 | C16: ICE CREAM | D16: 4800086050359 | E16: SEL CHOCKY STICK 45ML
B17: 12 | C17: ICE CREAM | D17: 4800086047380 | E17: SEL CHOCO ALMOND FUDGE 750ML
B18: 12 | C18: ICE CREAM | D18: 4800086040909 | E18: SEL COFFEE CRUMBLE 750ML
B19: 12 | C19: ICE CREAM | D19: 4800086050649 | E19: SEL CORNETTO APPLE CRUMBLE 110ML
B20: 12 | C20: ICE CREAM | D20: 4800086134325 | E20: SEL CORNETTO CLASSIC CHOCO 110ML
B21: 12 | C21: ICE CREAM | D21: 4800086043306 | E21: SEL CORNETTO COOKIES & DREAM 110ML | F21: 27.30 | H21: =F21*G21 -> 0
B22: 12 | C22: ICE CREAM | D22: 4800086046482 | E22: SEL CORNETTO DISC BLACK CHOCO COOKIE 115ML | F22: 68.15 | H22: =F22*G22 -> 0
B23: 12 | C23: ICE CREAM | D23: 4800086049551 | E23: SEL CORNETTO DISC MATCHA CRUMBLE 115ML | F23: 37.87
B24: 12 | C24: ICE CREAM | D24: 4800086045676 | E24: SEL CORNETTO DISC WHITE CHOCO COOKIES & CREAM 115ML | F24: 135.45
B25: 12 | C25: ICE CREAM | D25: 4800086034670 | E25: SEL CORNETTO VANILLA 110ML | F25: 90.00
B26: 12 | C26: ICE CREAM | D26: 4800086047717 | E26: SEL CREAMDAE 3+1 CHOCO KESO UBE MANGO 1.5L | F26: 14.55
B27: 12 | C27: ICE CREAM | D27: 4800086047717 | E27: SEL CREAMDAE 3+1 CHOCO KESO UBE MANGO 1.5L | F27: 18.20
B28: 12 | C28: ICE CREAM | D28: 4800086046987 | E28: SEL CREAMDAE CUPS CHOCO 100ML
B29: 12 | C29: ICE CREAM | D29: 4800086049162 | E29: SEL CREAMDAE STICK CHOCO MALLOW 60ML
B30: 12 | C30: ICE CREAM | D30: 4800086050168 | E30: SEL CRUNCHY MAX 65ML
B31: 12 | C31: ICE CREAM | D31: 8999999005610 | E31: SEL MAGNUM ALMOND 80ML
B32: 12 | C32: ICE CREAM | D32: 4800086043627 | E32: SEL SOLO PACK COOKIES & CREAM 450ML
B33: 12 | C33: ICE CREAM | D33: 4800086043603 | E33: SEL SOLO PACK DOUBLE DUTCH 450ML
B34: 12 | C34: ICE CREAM | D34: 4800086043641 | E34: SEL SOLO PACK PISTACHIO & CASHEW 475ML | F34: 18.20
B35: 12 | C35: ICE CREAM | D35: 4800086043610 | E35: SEL SOLO PACK ROCKY ROAD 475ML | F35: 27.30
B36: 12 | C36: ICE CREAM | D36: 4800086050847 | E36: SEL STRAW CHEESECAKE 450ML | F36: 27.30
B37: 12 | C37: ICE CREAM | D37: 4800086050212 | E37: SEL SUP AVOCADO DREAM 1.3L | F37: 18.20 | H37: =F37*G37 -> 0
B38: 12 | C38: ICE CREAM | D38: 4800086050212 | E38: SEL SUP AVOCADO DREAM 1.3L | F38: 18.20 | H38: =F38*G38 -> 0
B39: 12 | C39: ICE CREAM | D39: 4800086035943 | E39: SEL SUP COFFEE CRUMBLE 1.5L | F39: 9.10 | H39: =F39*G39 -> 0
B40: 12 | C40: ICE CREAM | D40: 4800086035929 | E40: SEL SUP COOKIES & CREAM 1.5L | F40: 18.20 | H40: =F40*G40 -> 0
B41: 12 | C41: ICE CREAM | D41: 4800086040893 | E41: SEL SUP COOKIES & CREAM 750ML | F41: 63.60 | H41: =F41*G41 -> 0
...

Sheet RTD & REFRI
B1: ACTUAL INVENTORY COUNT SHEET
B2: =Bread!B2 -> AS OF APRIL 2026
B3: COOP STORE
B5: CONTROL NO.: 13
B6: SHELF NO. | C6: SHELF DESCRIPTION | D6: BARCODE | E6: PRODUCT NAME | F6: UNIT COST | G6: QUANTITY | H6: TOTAL COST | I6: REMARKS
B7: 13 | C7: RTD & REFRI | D7: 4800016052774 | E7: C2 APPLE 1L | F7: 279.00
B8: 13 | C8: RTD & REFRI | D8: 4800016052040 | E8: C2 APPLE 355ML | F8: 49.75 | H8: =F8*G8 -> 0
B9: 13 | C9: RTD & REFRI | D9: 4800016068010 | E9: C2 SOLO APPLE FLAVOR 230ML | F9: 12.25 | H9: =F9*G9 -> 0
B10: 13 | C10: RTD & REFRI | D10: 0721688115007 | E10: CALM-C CALAMANSI JUICE 250ML
B11: 13 | C11: RTD & REFRI | D11: 4800249004748 | E11: CDO FUNTASTYK YOUNG PORK TOCINO 225G
B12: 13 | C12: RTD & REFRI | D12: 888123456781877 | E12: COBRA ORIG FLAVOR ASTIG 300ML
B13: 13 | C13: RTD & REFRI | D13: 4800014134083 | E13: COLT 45 500ML
B14: 13 | C14: RTD & REFRI | D14: 00008 | E14: CONVIE COKE 1.5
B15: 13 | C15: RTD & REFRI | D15: 00004 | E15: CONVIE COKE 237ML
B16: 13 | C16: RTD & REFRI | D16: 00007 | E16: CONVIE COKE 75OML
B17: 13 | C17: RTD & REFRI | D17: 00005 | E17: CONVIE COKE IN CAN ZERO SUGAR 320ML
B18: 13 | C18: RTD & REFRI | D18: 00048 | E18: CONVIE COKE LIGHT 1.5
B19: 13 | C19: RTD & REFRI | D19: 00003 | E19: CONVIE COKE MISMO 295ML
B20: 13 | C20: RTD & REFRI | D20: 00001 | E20: CONVIE COKE SWAKTO 200ML
B21: 13 | C21: RTD & REFRI | D21: 00002 | E21: CONVIE COKE SWAKTO ZERO SUGAR 200ML
... B32: 13 | C32: RTD & REFRI | D32: 00015 | E32: CONVIE ROYAL MISMO 250ML
B33: 13 | C33: RTD & REFRI | D33: 00047 | E33: CONVIE ROYAL STRAWBERRY MISMO | F33: 62.00 | H33: =F33*G33 -> 0
B34: 13 | C34: RTD & REFRI | D34: 000014 | E34: CONVIE ROYAL SWAKTO 200ML | F34: 15.83 | H34: =F34*G34 -> 0
B35: 13 | C35: RTD & REFRI | D35: 00013 | E35: CONVIE SPRITE 1.5 | F35: 37.00 | H35: =F35*G35 -> 0
B36: 13 | C36: RTD & REFRI | D36: 00011 | E36: CONVIE SPRITE 237ML | F36: 58.58 | H36: =F36*G36 -> 0
B37: 13 | C37: RTD & REFRI | D37: 000012 | E37: CONVIE SPRITE 750ML | F37: 7.08 | H37: =F37*G37 -> 0
B38: 13 | C38: RTD & REFRI | D38: 00010 | E38: CONVIE SPRITE MISMO 295ML | F38: 31.71 | H38: =F38*G38 -> 0
B39: 13 | C39: RTD & REFRI | D39: 00009 | E39: CONVIE SPRITE SWAKTO 200ML | F39: 15.67 | H39: =F39*G39 -> 0
B40: 13 | C40: RTD & REFRI | D40: 00029 | E40: CONVIE WILKINS 1L | F40: 10.83 | H40: =F40*G40 -> 0
B41: 13 | C41: RTD & REFRI | D41: 00027 | E41: CONVIE WILKINS 330ML | F41: 8.80
B42: 13 | C42: RTD & REFRI | D42: 00028 | E42: CONVIE WILKINS 500ML | F42: 8.80
B43: 13 | C43: RTD & REFRI | D43: 00028 | E43: CONVIE WILKINS 500ML | F43: 11.50
B44: 13 | C44: RTD & REFRI | D44: 00030 | E44: CONVIE WILKINS 7L | F44: 15.50
B45: 13 | C45: RTD & REFRI | D45: 888123456781247 | E45: DM JUICE DRINK PINEAPPLE 100% W/ ACE | F45: 15.67
B46: 13 | C46: RTD & REFRI | D46: 4800024581105 | E46: DM JUICE DRINK PINEAPPLE ACE 6S | F46: 58.58
B47: 13 | C47: RTD & REFRI | D47: 4800024562692 | E47: DM PINEAPPLE JUICE ACE 100% 220ML-2 | F47: 7.08
B48: 13 | C48: RTD & REFRI | D48: 888123456782018 | E48: DM PINEAPPLE JUICE ACE 220ML | F48: 15.67
B49: 13 | C49: RTD & REFRI | D49: 4800024572981 | E49: DM PINEAPPLE JUICE HEART SMART 240ML | F49: 9.17
B50: 13 | C50: RTD & REFRI | D50: 8851717040245 | E50: DUTCH MILL BLUEBERRY 180ML | F50: 22.73
B51: 13 | C51: RTD & REFRI | D51: 8851717200014 | E51: DUTCH MILL BLUEBERRY 90ML | F51: 165.95
...

Sheet OTC
B1: ACTUAL INVENTORY COUNT SHEET
B2: ='RTD & REFRI'!B2 -> AS OF APRIL 2026
B3: COOP STORE
B5: CONTROL NO.: 14
B6: SHELF NO. | C6: SHELF DESCRIPTION | D6: BARCODE | E6: PRODUCT NAME | F6: UNIT COST | G6: QUANTITY | H6: TOTAL COST | I6: REMARKS
B7: 14 | C7: OVER THE COUNTER (OTC) | D7: 888123456781081 | E7: GOLDEN DEER PLASTIC BAG MEDIUM | F7: 20.50 | H7: =F7*G7 -> 0
B8: 14 | C8: OVER THE COUNTER (OTC) | D8: 4809012413046 | E8: KATINKO OINTMENT 10G | F8: 154.30
B9: 14 | C9: OVER THE COUNTER (OTC) | D9: 48044295 | E9: MARLBORO RED PACK | F9: 1.32
B10: 14 | C10: OVER THE COUNTER (OTC) | D10: 48041812 | E10: MIGHTY GREEN PACK | F10: 123.00
B11: 14 | C11: OVER THE COUNTER (OTC) | D11: 8881234567826 | E11: OTC ALAXAN FR | F11: 7.00
B12: 14 | C12: OVER THE COUNTER (OTC) | D12: 4800204002048 | E12: OTC BETADINE WOUND SOLUTION 15ML | F12: 5.58
B13: 14 | C13: OVER THE COUNTER (OTC) | D13: 888123456781205 | E13: OTC BIOFLU | F13: 5.85
B14: 14 | C14: OVER THE COUNTER (OTC) | D14: 4800116136008 | E14: OTC BUTTER CREAM CHEESE SPREAD 17G | F14: 5.85
B15: 14 | C15: OVER THE COUNTER (OTC) | D15: 4800116135001 | E15: OTC BUTTER CREAM CHOCOLATE SPREAD 17G | F15: 14.33
B16: 14 | C16: OVER THE COUNTER (OTC) | D16: 8935001721550 | E16: OTC CHUPA CHUPS MILKY CARAMEL LOLLIPOP 9G | F16: 3.60
B17: 14 | C17: OVER THE COUNTER (OTC) | D17: 8935001721567 | E17: OTC CHUPA CHUPS STRAWBERRY & CREAM FLAVOR 9G | F17: 7.04
B18: 14 | C18: OVER THE COUNTER (OTC) | D18: 4800016113048 | E18: OTC DEWBERRY STRAWBERRIES N CREAM 33G | F18: 7.00
B19: 14 | C19: OVER THE COUNTER (OTC) | D19: 888123456781387 | E19: OTC DIATABS | F19: 20.00
... B38: 14 | C38: OVER THE COUNTER (OTC) | D38: 750515018402 | E38: OTC SKYFLAKES CRACKERS 25G | F38: 3.31
B39: 14 | C39: OVER THE COUNTER (OTC) | D39: 750515030190 | E39: OTC SKYFLAKES OAT FIBER CRACKERS 25G | F39: 10.70 | H39: =F39*G39 -> 0
B40: 14 | C40: OVER THE COUNTER (OTC) | D40: 750515031029 | E40: OTC SKYFLAKES TSOKOLATE | F40: 8.84 | H40: =F40*G40 -> 0
B41: 14 | C41: OVER THE COUNTER (OTC) | D41: 888123456781866 | E41: OTC SOLMUX 500MG | F41: 9.17 | H41: =F41*G41 -> 0
B42: 14 | C42: OVER THE COUNTER (OTC) | D42: 4800116024008 | E42: OTC SUNFLOWER CRACKERS BLUEBERRY
B43: 14 | C43: OVER THE COUNTER (OTC) | D43: 4800116016003 | E43: OTC SUNFLOWER CRACKERS STRAWBERRY 27G
B44: 14 | C44: OVER THE COUNTER (OTC) | D44: 888123456782001 | E44: OTC SUPERLAMIG CANDY
B45: 14 | C45: OVER THE COUNTER (OTC) | D45: 7622202046797 | E45: OTC TIGER BITES VANILLA 18G
B46: 14 | C46: OVER THE COUNTER (OTC) | D46: 888123456799 | E46: OTC VFRESH WINTER COOL GUM 3G
B47: 14 | C47: OVER THE COUNTER (OTC) | D47: 888123456781801 | E47: OTC WHISPER W/ WINGS
B48: 14 | C48: OVER THE COUNTER (OTC) | D48: 4806515650305 | E48: TAWAS PASTE BLUE 50G
B49: 14 | C49: OVER THE COUNTER (OTC) | D49: 4806515650299 | E49: TAWAS POWDER RED 50G
B50: 14 | C50: OVER THE COUNTER (OTC) | D50: 4806515650312 | E50: TAWAS W/ SCENT POWDER YELLOW 50G
B51: 14 | C51: OVER THE COUNTER (OTC) | D51: 8998898101409 | E51: TOLAK ANGIN HERBAL MINT HONEY 15ML
B52: 14 | C52: OVER THE COUNTER (OTC) | D52: 888123456781608 | E52: WASHABLE FACE MASK
B53: 14 | C53: OVER THE COUNTER (OTC) | D53: 48040594 | E53: WINSTON RED PACK
B54: 14 | C54: OVER THE COUNTER (OTC)
B55: 14 | C55: OVER THE COUNTER (OTC)
B56: 14 | C56: OVER THE COUNTER (OTC)
B57: 14 | C57: OVER THE COUNTER (OTC)
B58: 14 | C58: OVER THE COUNTER (OTC)
B59: 14 | C59: OVER THE COUNTER (OTC)
...

Sheet Other Products
B1: ACTUAL INVENTORY COUNT SHEET
B2: =Candies!B2 -> AS OF APRIL 2026
B3: COOP STORE
B5: CONTROL NO.: 10
B6: SHELF NO. | C6: SHELF DESCRIPTION | D6: BARCODE | E6: PRODUCT NAME | F6: UNIT COST | G6: QUANTITY | H6: TOTAL COST | I6: REMARKS
B7: 15 | C7: OTHER PRODUCTS | D7: 888123456781870 | E7: BABY FEEDING BOTTLE 5OZ | F7: 44.54
B8: 15 | C8: OTHER PRODUCTS | D8: 888123456781871 | E8: BABY FEEDING BOTTLE 8OZ | F8: 45.71 | H8: =F8*G8 -> 0
B9: 15 | C9: OTHER PRODUCTS | D9: 4800067051443 | E9: BABYFLO BOTTLE NURSERY RHYME 8OZ | F9: 89.75 | H9: =F9*G9 -> 0
B10: 15 | C10: OTHER PRODUCTS | D10: 4800067048962 | E10: BABYFLO BOTTLE PLAYTIME NURSERY 12 OZ | F10: 130.75 | H10: =F10*G10 -> 0
B11: 15 | C11: OTHER PRODUCTS | D11: 0710535987874 | E11: BELLE MICROWAVE SAFE CONTAINERS 500ML 10S | F11: 38.33
B12: 15 | C12: OTHER PRODUCTS | D12: 888123456781634 | E12: BEST SILICONE NIPPLE LARGE 6 MOS & ABOVE | F12: 16.95 | H12: =F12*G12 -> 0
B13: 15 | C13: OTHER PRODUCTS | D13: 888123456781863 | E13: BEST SILICONE NIPPLE MEDIUM 3 TO 7 MONTHS | F13: 16.95 | H13: =F13*G13 -> 0
B14: 15 | C14: OTHER PRODUCTS | D14: 888123456781862 | E14: BEST SILICONE NIPPLE SMALL 0 TO 3 MONTHS | F14: 16.95 | H14: =F14*G14 -> 0
B15: 15 | C15: OTHER PRODUCTS | D15: 4806502161364 | E15: CHEERS TRASH BAG LARGE 10 BAGS | F15: 53.64 | H15: =F15*G15 -> 0
B16: 15 | C16: OTHER PRODUCTS | D16: 4806502161371 | E16: CHEERS TRASH BAG X-LARGE 10 BAGS | F16: 80.90 | H16: =F16*G16 -> 0
B17: 15 | C17: OTHER PRODUCTS | D17: 888123456781291 | E17: CHICHARON | F17: 100.00 | H17: =F17*G17 -> 0
B18: 15 | C18: OTHER PRODUCTS | D18: 4800065113112 | E18: COMMANDO SAFETY MATCHES 10S | F18: 19.35 | H18: =F18*G18 -> 0
B19: 15 | C19: OTHER PRODUCTS | D19: 4806523175838 | E19: DIARY OF A PULUBI BOOK | F19: 85.00 | H19: =F19*G19 -> 0
B20: 15 | C20: OTHER PRODUCTS | D20: 888123456781289 | E20: ECO BAG | F20: 5.00 | H20: =F20*G20 -> 0
B21: 15 | C21: OTHER PRODUCTS | D21: 888123456781288 | E21: ECO BAG BLUE LARGE | F21: 7.00 | H21: =F21*G21 -> 0
B22: 15 | C22: OTHER PRODUCTS | D22: 888123456781954 | E22: ECO BAG LARGE | F22: 6.00 | H22: =F22*G22 -> 0
B23: 15 | C23: OTHER PRODUCTS | D23: 888123456781953 | E23: ECO BAG MEDIUM | F23: 6.00
B24: 15 | C24: OTHER PRODUCTS | D24: 888123456781528 | E24: ECO BAG XL | F24: 8.00
B25: 15 | C25: OTHER PRODUCTS | D25: 888123456781577 | E25: GAS LITE BBQ GRILL SET | F25: 1,900.00
B26: 15 | C26: OTHER PRODUCTS | D26: 4800888606709 | E26: GERM KILL KIT 3000L
B27: 15 | C27: OTHER PRODUCTS | D27: 888123456781793 | E27: GOLDEN DEER PLASTIC BAG LARGE
B28: 15 | C28: OTHER PRODUCTS | D28: 888123456781224 | E28: GOLDEN DEER PLASTIC BAG MINI
B29: 15 | C29: OTHER PRODUCTS | D29: 888123456781779 | E29: GOLDEN DEER PLASTIC BAG TINY
B30: 15 | C30: OTHER PRODUCTS | D30: 888123456781764 | E30: HOUSEHOLD GLOVES LARGE
B31: 15 | C31: OTHER PRODUCTS | D31: 888123456781913 | E31: JILLY TURMERIC GINGER TEA 150G
B32: 15 | C32: OTHER PRODUCTS | D32: 888123456781472 | E32: MIKKO CLING WRAP
B33: 15 | C33: OTHER PRODUCTS | D33: 888123456781285 | E33: MSC MALUNGAY TEA 15 TEA BAGS
B34: 15 | C34: OTHER PRODUCTS | D34: 888123456781912 | E34: MSC PROMO PACK
B35: 15 | C35: OTHER PRODUCTS | D35: 888123456781235 | E35: MSC RICE COFFEE 100G
B36: 15 | C36: OTHER PRODUCTS | D36: 4806523176392 | E36: MY IPON DIARY BOOK
B37: 15 | C37: OTHER PRODUCTS | D37: 4806535990016 | E37: ONE OPTI JUICE 30G
... B46: 15 | C46: OTHER PRODUCTS | D46: 888123456781792 | E46: SUPER STAR WHITE BUNDLE 20X30
B47: 15 | C47: OTHER PRODUCTS | D47: 4806525912271 | E47: TRIGEM MICROWAVABLE PLASTIC CONTAINER 750 | F47: 1,098.00
B48: 15 | C48: OTHER PRODUCTS | D48: 4806525912288 | E48: TRIGEM MICROWAVABLE PLASTIC CONTAINER RE1000 10S | F48: 43.00
B49: 15 | C49: OTHER PRODUCTS | D49: 888123456781377 | E49: VERSA ALUMINUM FOIL JUMBO ROLL | F49: 35.00
...

Sheet S. Moringa
B1: ACTUAL INVENTORY COUNT SHEET
B2: =Noodles!B2 -> AS OF APRIL 2026
B3: COOP STORE
B5: CONTROL NO.: 17
B6: SHELF NO. | C6: SHELF DESCRIPTION | D6: BARCODE | E6: PRODUCT NAME | F6: UNIT COST | G6: QUANTITY | H6: TOTAL COST | I6: REMARKS
B7: 18 | C7: SUPER MORINGA PRODUCTS | D7: 4809015665916 | E7: SUPER MORINGA 7IN1 BOTANICAL LUYANG DILAW 60ML
B8: 18 | C8: SUPER MORINGA PRODUCTS | D8: 4809015665206 | E8: SUPER MORINGA CALMING OIL 10ML
B9: 18 | C9: SUPER MORINGA PRODUCTS | D9: 4809015665206 | E9: SUPER MORINGA CALMING OIL 10ML
B10: 18 | C10: SUPER MORINGA PRODUCTS | D10: 4809015665954 | E10: SUPER MORINGA GLUTA KOJIC 135G
B11: 18 | C11: SUPER MORINGA PRODUCTS | D11: 4809015665039 | E11: SUPER MORINGA GREEN COFFEE 10X21G
B12: 18 | C12: SUPER MORINGA PRODUCTS | D12: 4809015665961 | E12: SUPER MORINGA GUAVA & TEA TREE SOAP 135G
B13: 18 | C13: SUPER MORINGA PRODUCTS | D13: 4809015665022 | E13: SUPER MORINGA HERBAL COFFEE 10X21G
B14: 18 | C14: SUPER MORINGA PRODUCTS | D14: 888123456781560 | E14: SUPER MORINGA HERBAL CREAM 25G
B15: 18 | C15: SUPER MORINGA PRODUCTS | D15: 4809015665152 | E15: SUPER MORINGA ISOPROPYL ALCOHOL 70% SOL 100ML
B16: 18 | C16: SUPER MORINGA PRODUCTS | D16: 4809015665305 | E16: SUPER MORINGA MOISTURIZING MASSAGE GEL
B17: 18 | C17: SUPER MORINGA PRODUCTS | D17: 4809015665312 | E17: SUPER MORINGA MOISTURIZING MASSAGE OIL 60ML | F17: 168.00 | H17: =F17*G17 -> 0
B18: TOTAL | G18: =SUM(G7:G17) -> 0 | H18: =SUM(H7:H17) -> 0
B20: PREPARED BY: | E20: WITNESSED BY:
E22: NERISSA C. DULDULAO
B23: OPERATION - STAFF | E23: ACCOUNTING STAFF
B25: CHECKED BY: | E25: APPROVED BY:
B27: JENNY-LYN R. GANIGAN | E27: MICHAEL S. GUTIERREZ
B28: OPERATION - UNIT HEAD | E28: OPERATIONS MANAGER

Sheet School Supplies
B1: ACTUAL INVENTORY COUNT SHEET
B2: ='S. Moringa'!B2 -> AS OF APRIL 2026
B3: COOP STORE
B5: CONTROL NO.: 1
B6: SHELF NO. | C6: SHELF DESCRIPTION | D6: BARCODE | E6: PRODUCT NAME | F6: UNIT COST | G6: QUANTITY | H6: TOTAL COST | I6: REMARKS
B7: 23 | C7: SCHOOL SUPPLIES | D7: 4806021302040 | E7: 2 HOLE JOY PUNCHER | F7: 178.00 | H7: =F7*G7 -> 0
B8: 23 | C8: SCHOOL SUPPLIES | D8: 4806021300053 | E8: BINDER CLIP BIG | F8: 7.00 | H8: =F8*G8 -> 0
B9: 23 | C9: SCHOOL SUPPLIES | D9: 4806021316931 | E9: BINDER CLIP SMALL | F9: 3.00 | H9: =F9*G9 -> 0
B10: 23 | C10: SCHOOL SUPPLIES | D10: 200035 | E10: BRITE FASTENER #8 1/2 | F10: 118.00 | H10: =F10*G10 -> 0
B11: 23 | C11: SCHOOL SUPPLIES | D11: 200036 | E11: BROWN ENVELOPE - LONG | F11: 4.00
B12: 23 | C12: SCHOOL SUPPLIES | D12: 200037 | E12: BROWN ENVELOPE - SHORT | F12: 2.00
B13: 23 | C13: SCHOOL SUPPLIES | D13: 200006 | E13: COLORED FOLDER LONG - VIOLET | F13: 8.00
B14: 23 | C14: SCHOOL SUPPLIES | D14: 200003 | E14: COLORED FOLDER LONG - YELLOW | F14: 8.00
B15: 23 | C15: SCHOOL SUPPLIES | D15: 200009 | E15: COLORED FOLDER SHORT - RED | F15: 7.00
B16: 23 | C16: SCHOOL SUPPLIES | D16: 200010 | E16: COLORED FOLDER SHORT - YELLOW | F16: 7.00 | H16: =F16*G16 -> 0
B17: 23 | C17: SCHOOL SUPPLIES | D17: 4806021388082 | E17: CORRECTION TAPE JOY | F17: 22.00 | H17: =F17*G17 -> 0
B18: 23 | C18: SCHOOL SUPPLIES | D18: 8802203648315 | E18: DONG-A REFILL .7 | F18: 18.00 | H18: =F18*G18 -> 0
B19: 23 | C19: SCHOOL SUPPLIES | D19: 200016 | E19: EXPANDING FOLDER SHORT - PINK | F19: 13.00 | H19: =F19*G19 -> 0
B20: 23 | C20: SCHOOL SUPPLIES | D20: 200018 | E20: EXPANDING FOLDER SHORT - ROYAL BLUE | F20: 13.00 | H20: =F20*G20 -> 0
B21: 23 | C21: SCHOOL SUPPLIES | D21: 200038 | E21: FOLDER WHITE - LONG 14PTS | F21: 7.00 | H21: =F21*G21 -> 0
B22: 23 | C22: SCHOOL SUPPLIES | D22: 200049 | E22: HBW MATRIX BALLPEN RED | F22: 5.00 | H22: =F22*G22 -> 0
B23: 23 | C23: SCHOOL SUPPLIES | D23: 6926341889729 | E23: HBW STAMP PAD #3 | F23: 57.00 | H23: =F23*G23 -> 0
B24: 23 | C24: SCHOOL SUPPLIES | D24: 4802870729288 | E24: MAX STAPLER W/ REMOVER | F24: 387.00 | H24: =F24*G24 -> 0
B25: 23 | C25: SCHOOL SUPPLIES | D25: 4806502211137 | E25: OFFICE PRO - A4 SUBS 20 | F25: 166.00 | H25: =F25*G25 -> 0
B26: 23 | C26: SCHOOL SUPPLIES | D26: 200040 | E26: PAID STAMP W/ DATE | F26: 30.00 | H26: =F26*G26 -> 0
B27: 23 | C27: SCHOOL SUPPLIES | D27: 200041 | E27: PAPER CLIP GATOR 50MM | F27: 20.00 | H27: =F27*G27 -> 0
... B35: 23 | C35: SCHOOL SUPPLIES | D35: 6925722100514 | E35: STAPLE WIRE #10 | F35: 30.00 | H35: =F35*G35 -> 0
B36: 23 | C36: SCHOOL SUPPLIES | F36: 3.00 | H36: =F36*G36 -> 0
B37: TOTAL | G37: =SUM(G7:G36) -> 0 | H37: =SUM(H7:H36) -> 0
B39: PREPARED BY: | E39: WITNESSED BY:
E41: NERISSA C. DULDULAO
B42: OPERATION - STAFF | E42: ACCOUNTING STAFF
B44: CHECKED BY: | E44: APPROVED BY:
B46: JENNY-LYN R. GANIGAN | E46: MICHAEL S. GUTIERREZ
B47: OPERATION - UNIT HEAD | E47: OPERATIONS MANAGER

Sheet PRINTING
B1: ACTUAL INVENTORY COUNT SHEET
B2: ='S. Moringa'!B2 -> AS OF APRIL 2026
B3: PRINTING
B5: CONTROL NO.: 2
B6: SHELF NO. | C6: SHELF DESCRIPTION | D6: BARCODE | E6: PRODUCT NAME | F6: UNIT COST | G6: QUANTITY | H6: TOTAL COST | I6: REMARKS
B7: 20 | C7: OFFICE SUPPLIES | D7: 70002 | E7: PRINTING ADRITE RIBBON INK MEDIUM/BLACK | F7: 13.50
B8: 20 | C8: OFFICE SUPPLIES | D8: 70180 | E8: PRINTING ADVENTURE PLASTIC ENVELOPE LONG | F8: 18.00
B9: 20 | C9: OFFICE SUPPLIES | D9: 70181 | E9: PRINTING ADVENTURE PLASTIC ENVELOPE W/ HANDLE LONG | F9: 45.00
B10: 20 | C10: OFFICE SUPPLIES | D10: 70003 | E10: PRINTING ARTLINE HIGHLIGHTER ORANGE | F10: 220.00
B11: 20 | C11: OFFICE SUPPLIES | D11: 70006 | E11: PRINTING ASIAN COLOR BONDPAPER BLUE SHORT | F11: 240.00
B12: 20 | C12: OFFICE SUPPLIES | D12: 70007 | E12: PRINTING ASIAN COLOR BONDPAPER PINK SHORT | F12: 30.00
B13: 20 | C13: OFFICE SUPPLIES | D13: 70008 | E13: PRINTING ASSORTED PLASTIC SLIDING FOLDER LONG | F13: 156.33 | H13: =F13*G13 -> 0
B14: 20 | C14: OFFICE SUPPLIES | D14: 70009 | E14: PRINTING ASSORTED PLASTIC SLIDING FOLDER SHORT | F14: 257.00 | H14: =F14*G14 -> 0
B15: 20 | C15: OFFICE SUPPLIES | D15: 70278 | E15: PRINTING BALIK TANGKILIK CARD | F15: 4.00 | H15: =F15*G15 -> 0
B16: 20 | C16: OFFICE SUPPLIES | D16: 70010 | E16: PRINTING BALLPEN HBW GREEN | F16: 3.75 | H16: =F16*G16 -> 0
B17: 20 | C17: OFFICE SUPPLIES | D17: 70011 | E17: PRINTING BALLPEN HBW MATRIX BLUE | F17: 3.75
B18: 20 | C18: OFFICE SUPPLIES | D18: 70012 | E18: PRINTING BALLPEN HBW MATRIX RED | F18: 105.00
B19: 20 | C19: OFFICE SUPPLIES | D19: 70314 | E19: PRINTING BALLPEN HBW MATRIX RED - 2 | F19: 3.50
B20: 20 | C20: OFFICE SUPPLIES | D20: 70013 | E20: PRINTING BALLPEN PIANO BLACK | F20: 3.50
B21: 20 | C21: OFFICE SUPPLIES | D21: 70179 | E21: PRINTING BEIFA PXSTICK BALLPEN BLACK | F21: 3.50
B22: 20 | C22: OFFICE SUPPLIES | D22: 70014 | E22: PRINTING BINDER CLIPS 1 INCH | F22: 4.25
