Workbook

Sheet PRINTING
B1: INVENTORY REPORT
B2: AS OF JUNE 2026
B3: PRINTING
B5: SHELF NO. | C5: SHELF DESCRIPTION | D5: BARCODE/ CONTROL NUMBER | E5: PRODUCT NAME | F5: UNIT COST | G5: QUANTITY PER RECORD / ACCPOS | H5: ACTUAL INVENTORY | I5: TOTAL COST - RECORD | J5: TOTAL COST - ACTUAL INVENTORY | K5: VARIANCE - QUANTITY | L5: VARIANCE - COST | M5: REMARKS / CAUSE OF VARIANCE
B6: 20 | C6: OFFICE SUPPLIES | D6: 70002 | E6: PRINTING ADRITE RIBBON INK MEDIUM/BLACK | F6: 13.50 | G6: 253 | H6: 253 | I6: =F6*G6 -> 3415.5 | J6: =F6*H6 -> 3415.5 | K6: =G6-H6 -> 0 | L6: =I6-J6 -> 0
B7: 20 | C7: OFFICE SUPPLIES | D7: 70180 | E7: PRINTING ADVENTURE PLASTIC ENVELOPE LONG | F7: 18.00 | G7: 53 | H7: 53 | I7: =F7*G7 -> 954 | J7: =F7*H7 -> 954 | K7: =G7-H7 -> 0 | L7: =I7-J7 -> 0
B8: 20 | C8: OFFICE SUPPLIES | D8: 70181 | E8: PRINTING ADVENTURE PLASTIC ENVELOPE W/ HANDLE LONG | F8: 45.00 | G8: 4 | H8: 4 | I8: =F8*G8 -> 180 | J8: =F8*H8 -> 180 | K8: =G8-H8 -> 0 | L8: =I8-J8 -> 0
B9: 20 | C9: OFFICE SUPPLIES | D9: 70003 | E9: PRINTING ARTLINE HIGHLIGHTER ORANGE | F9: 30.00 | G9: 5 | H9: 5 | I9: =F9*G9 -> 150 | J9: =F9*H9 -> 150 | K9: =G9-H9 -> 0 | L9: =I9-J9 -> 0
B10: 20 | C10: OFFICE SUPPLIES | D10: 70006 | E10: PRINTING ASIAN COLOR BONDPAPER BLUE SHORT | F10: 120.00 | G10: 5 | H10: 5 | I10: =F10*G10 -> 600 | J10: =F10*H10 -> 600 | K10: =G10-H10 -> 0 | L10: =I10-J10 -> 0
B11: 20 | C11: OFFICE SUPPLIES | D11: 70007 | E11: PRINTING ASIAN COLOR BONDPAPER PINK SHORT | F11: 120.00 | G11: 3 | H11: 3 | I11: =F11*G11 -> 360 | J11: =F11*H11 -> 360 | K11: =G11-H11 -> 0 | L11: =I11-J11 -> 0
B12: 20 | C12: OFFICE SUPPLIES | D12: 70212 | E12: PRINTING ASKI MPC BOD & GA TARPAULIN 1.5X2FT | F12: 36.00 | G12: 2 | H12: 2 | I12: =F12*G12 -> 72 | J12: =F12*H12 -> 72 | K12: =G12-H12 -> 0 | L12: =I12-J12 -> 0
B13: 20 | C13: OFFICE SUPPLIES | D13: 70008 | E13: PRINTING ASSORTED PLASTIC SLIDING FOLDER LONG | F13: 4.00 | G13: 27 | H13: 27 | I13: =F13*G13 -> 108 | J13: =F13*H13 -> 108 | K13: =G13-H13 -> 0 | L13: =I13-J13 -> 0
B14: 20 | C14: OFFICE SUPPLIES | D14: 70009 | E14: PRINTING ASSORTED PLASTIC SLIDING FOLDER SHORT | F14: 3.75 | G14: 68 | H14: 68 | I14: =F14*G14 -> 255 | J14: =F14*H14 -> 255 | K14: =G14-H14 -> 0 | L14: =I14-J14 -> 0
B15: 20 | C15: OFFICE SUPPLIES | D15: 70278 | E15: PRINTING BALIK TANGKILIK CARD | F15: 105.00 | G15: 157 | H15: 157 | I15: =F15*G15 -> 16485 | J15: =F15*H15 -> 16485 | K15: =G15-H15 -> 0 | L15: =I15-J15 -> 0
B16: 20 | C16: OFFICE SUPPLIES | D16: 70010 | E16: PRINTING BALLPEN HBW GREEN | F16: 3.50 | G16: 55 | H16: 55 | I16: =F16*G16 -> 192.5 | J16: =F16*H16 -> 192.5 | K16: =G16-H16 -> 0 | L16: =I16-J16 -> 0
B17: 20 | C17: OFFICE SUPPLIES | D17: 70011 | E17: PRINTING BALLPEN HBW MATRIX BLUE | F17: 3.50 | G17: 1 | H17: 1 | I17: =F17*G17 -> 3.5 | J17: =F17*H17 -> 3.5 | K17: =G17-H17 -> 0 | L17: =I17-J17 -> 0
... B78: 20 | C78: OFFICE SUPPLIES | D78: 70323 | E78: PRINTING EXPANDING FOLDER LONG-2 | F78: 16.00 | G78: 200 | H78: 200 | I78: =F78*G78 -> 3200 | J78: =F78*H78 -> 3200 | K78: =G78-H78 -> 0 | L78: =I78-J78 -> 0
B79: 20 | C79: OFFICE SUPPLIES | D79: 70311 | E79: PRINTING EXPANDING FOLDER GREEN LONG - 2 | F79: 16.00 | G79: 147 | H79: 147 | I79: =F79*G79 -> 2352 | J79: =F79*H79 -> 2352 | K79: =G79-H79 -> 0 | L79: =I79-J79 -> 0
B80: 20 | C80: OFFICE SUPPLIES | D80: 70066 | E80: PRINTING EXPANDING FOLDER GREEN SHORT | F80: 14.50 | G80: 233 | H80: 233 | I80: =F80*G80 -> 3378.5 | J80: =F80*H80 -> 3378.5 | K80: =G80-H80 -> 0 | L80: =I80-J80 -> 0
B81: 20 | C81: OFFICE SUPPLIES | D81: 70067 | E81: PRINTING EXPANDING FOLDER LIGHT BLUE LONG | F81: 12.00 | G81: 222 | H81: 222 | I81: =F81*G81 -> 2664 | J81: =F81*H81 -> 2664 | K81: =G81-H81 -> 0 | L81: =I81-J81 -> 0
B82: 20 | C82: OFFICE SUPPLIES | D82: 70068 | E82: PRINTING EXPANDING FOLDER ORANGE LONG | F82: 13.50 | G82: 55 | H82: 55 | I82: =F82*G82 -> 742.5 | J82: =F82*H82 -> 742.5 | K82: =G82-H82 -> 0 | L82: =I82-J82 -> 0
B83: 20 | C83: OFFICE SUPPLIES | D83: 70069 | E83: PRINTING EXPANDING FOLDER PINK LONG | F83: 14.50 | G83: 10 | H83: 10 | I83: =F83*G83 -> 145 | J83: =F83*H83 -> 145 | K83: =G83-H83 -> 0 | L83: =I83-J83 -> 0
B84: 20 | C84: OFFICE SUPPLIES | D84: 70322 | E84: PRINTING EXPANDING FOLDER PINK LONG -2 | F84: 16.00 | G84: 200 | H84: 200 | I84: =F84*G84 -> 3200 | J84: =F84*H84 -> 3200 | K84: =G84-H84 -> 0 | L84: =I84-J84 -> 0
B85: 20 | C85: OFFICE SUPPLIES | D85: 70070 | E85: PRINTING EXPANDING FOLDER PINK SHORT | F85: 13.25 | G85: 1 | H85: 1 | I85: =F85*G85 -> 13.25 | J85: =F85*H85 -> 13.25 | K85: =G85-H85 -> 0 | L85: =I85-J85 -> 0
B86: 20 | C86: OFFICE SUPPLIES | D86: 70297 | E86: PRINTING EXPANDING FOLDER PINK SHORT - 2 | F86: 14.00 | G86: 100 | H86: 100 | I86: =F86*G86 -> 1400 | J86: =F86*H86 -> 1400 | K86: =G86-H86 -> 0 | L86: =I86-J86 -> 0
B87: 20 | C87: OFFICE SUPPLIES | D87: 70071 | E87: PRINTING EXPANDING FOLDER RED LONG | F87: 14.50 | G87: 23 | H87: 23 | I87: =F87*G87 -> 333.5 | J87: =F87*H87 -> 333.5 | K87: =G87-H87 -> 0 | L87: =I87-J87 -> 0
B88: 20 | C88: OFFICE SUPPLIES | D88: 70072 | E88: PRINTING EXPANDING FOLDER RED SHORT | F88: 13.25 | G88: 115 | H88: 115 | I88: =F88*G88 -> 1523.75 | J88: =F88*H88 -> 1523.75 | K88: =G88-H88 -> 0 | L88: =I88-J88 -> 0
B89: 20 | C89: OFFICE SUPPLIES | D89: 70073 | E89: PRINTING EXPANDING FOLDER ROYAL BLUE LONG | F89: 14.50 | G89: 67 | H89: 67 | I89: =F89*G89 -> 971.5 | J89: =F89*H89 -> 971.5 | K89: =G89-H89 -> 0 | L89: =I89-J89 -> 0
B90: 20 | C90: OFFICE SUPPLIES | D90: 70312 | E90: PRINTING EXPANDING FOLDER ROYAL BLUE LONG - 2 | F90: 16.00 | G90: 280 | H90: 280 | I90: =F90*G90 -> 4480 | J90: =F90*H90 -> 4480 | K90: =G90-H90 -> 0 | L90: =I90-J90 -> 0
B91: 20 | C91: OFFICE SUPPLIES | D91: 70313 | E91: PRINTING EXPANDING FOLDER ROYAL BLUE SHORT - 2 | F91: 15.00 | G91: 46 | H91: 46 | I91: =F91*G91 -> 690 | J91: =F91*H91 -> 690 | K91: =G91-H91 -> 0 | L91: =I91-J91 -> 0
... B93: 20 | C93: OFFICE SUPPLIES | D93: 70077 | E93: PRINTING FASTENER GATOR 8 1/2 SIZE | F93: 130.00 | G93: 48 | H93: 48 | I93: =F93*G93 -> 6240 | J93: =F93*H93 -> 6240 | K93: =G93-H93 -> 0 | L93: =I93-J93 -> 0
B94: 20 | C94: OFFICE SUPPLIES | D94: 70075 | E94: PRINTING FASTENER HOT ARTS 70MM | F94: 40.00 | G94: 219 | H94: 219 | I94: =F94*G94 -> 8760 | J94: =F94*H94 -> 8760 | K94: =G94-H94 -> 0 | L94: =I94-J94 -> 0
B95: 20 | C95: OFFICE SUPPLIES | D95: 70234 | E95: PRINTING FFNE POLO SHIRT M-2XL | F95: 281.11 | G95: 1 | H95: 1 | I95: =F95*G95 -> 281.11 | J95: =F95*H95 -> 281.11 | K95: =G95-H95 -> 0 | L95: =I95-J95 -> 0
B96: 20 | C96: OFFICE SUPPLIES | D96: 70249 | E96: PRINTING FILE BOX | F96: 98.00 | G96: 15 | H96: 15 | I96: =F96*G96 -> 1470 | J96: =F96*H96 -> 1470 | K96: =G96-H96 -> 0 | L96: =I96-J96 -> 0
B97: 20 | C97: OFFICE SUPPLIES | D97: 70078 | E97: PRINTING FILE RACK | F97: 98.00 | G97: 7 | H97: 7 | I97: =F97*G97 -> 686 | J97: =F97*H97 -> 686 | K97: =G97-H97 -> 0 | L97: =I97-J97 -> 0
B98: 20 | C98: OFFICE SUPPLIES | D98: 70079 | E98: PRINTING FOLDER BROWN SHORT | F98: 4.50 | G98: 495 | H98: 495 | I98: =F98*G98 -> 2227.5 | J98: =F98*H98 -> 2227.5 | K98: =G98-H98 -> 0 | L98: =I98-J98 -> 0
B99: 20 | C99: OFFICE SUPPLIES | D99: 70080 | E99: PRINTING FOLDER LONG BLUE | F99: 8.25 | G99: 649 | H99: 649 | I99: =F99*G99 -> 5354.25 | J99: =F99*H99 -> 5354.25 | K99: =G99-H99 -> 0 | L99: =I99-J99 -> 0
B100: 20 | C100: OFFICE SUPPLIES | D100: 70081 | E100: PRINTING FOLDER LONG GREEN | F100: 8.25 | G100: 1001 | H100: 1001 | I100: =F100*G100 -> 8258.25 | J100: =F100*H100 -> 8258.25 | K100: =G100-H100 -> 0 | L100: =I100-J100 -> 0
B101: 20 | C101: OFFICE SUPPLIES | D101: 70266 | E101: PRINTING FOLDER LONG ORANGE | F101: 7.00 | G101: 100 | H101: 100 | I101: =F101*G101 -> 700 | J101: =F101*H101 -> 700 | K101: =G101-H101 -> 0 | L101: =I101-J101 -> 0
B102: 20 | C102: OFFICE SUPPLIES | D102: 70082 | E102: PRINTING FOLDER LONG PINK | F102: 4.75 | G102: 806 | H102: 806 | I102: =F102*G102 -> 3828.5 | J102: =F102*H102 -> 3828.5 | K102: =G102-H102 -> 0 | L102: =I102-J102 -> 0
...

Sheet VB-3
A1: VARIANCE BREAKDOWN (PRINTING)
A2: =PRINTING!B2 -> AS OF JUNE 2026
B3: OVER
B4: BARCODE | C4: PRODUCT NAME | D4: UNIT COST | E4: QUANTITY PER RECORD / ACCPOS | F4: ACTUAL INVENTORY | G4: JAN. ACTUAL | H4: REMARKS | I4: VARIANCE - QUANTITY | J4: VARIANCE - COST | K4: REMARKS / CAUSE OF VARIANCE
B5: 70016 | C5: PRINTING BONUS LONG | D5: 99.30 | E5: 99 | F5: 109 | G5: 9830.7 | H5: 10823.7 | I5: -10 | J5: -993
B6: 70017 | C6: PRINTING BONUS SHORT | D6: 84.00 | E6: 116 | F6: 123 | G6: 9744 | H6: 10332 | I6: -7 | J6: -588
B7: 70170 | C7: PRINTING CLIENTS ID | D7: 1.50 | E7: 3650 | F7: 4000 | G7: 5475 | H7: 6000 | I7: -350 | J7: -525
B8: 70054 | C8: PRINTING DOUBLE SIDED TAPE | D8: 28.00 | E8: 20 | F8: 21 | G8: 560 | H8: 588 | I8: -1 | J8: -28
B9: 70085 | C9: PRINTING FOLDER LONG WHITE | D9: 2.70 | E9: 2294 | F9: 2760 | G9: 6193.8 | H9: 7452 | I9: -466 | J9: -1258.2
B10: 70173 | C10: PRINTING FORMS BONUS LONG | D10: 115.85 | E10: 20 | F10: 21 | G10: 2317 | H10: 2432.85 | I10: -1 | J10: -115.85
B11: 70306 | C11: PRINTING GATOR CORRECTION TAPE | D11: 24.00 | E11: 192 | F11: 196 | G11: 4608 | H11: 4704 | I11: -4 | J11: -96
B12: 70124 | C12: PRINTING PERFECT PRINT SHORT | D12: 126.00 | E12: 185 | F12: 186 | G12: 23310 | H12: 23436 | I12: -1 | J12: -126
B13: 70168 | C13: PRINTING WORX BONDPAPER LONG | D13: 32.00 | E13: 18 | F13: 19 | G13: 576 | H13: 608 | I13: -1 | J13: -32
B14: 70169 | C14: PRINTING WORX BONDPAPER SHORT | D14: 34.00 | E14: 92 | F14: 94 | G14: 3128 | H14: 3196 | I14: -2 | J14: -68
I42: =SUM(I5:I41) -> -843 | J42: =SUM(J5:J41) -> -3830.05
B44: RETURN
B45: BARCODE | C45: PRODUCT NAME | D45: UNIT COST | G45: VARIANCE - QUANTITY | H45: VARIANCE - COST | I45: REMARKS / CAUSE OF VARIANCE
H46: =D46*G46 -> 0
G47: =SUM(G46:G46) -> 0 | H47: =SUM(H46:H46) -> 0 | I47: =SUM(I46:I46) -> 0
B48: SHORT
B49: BARCODE | C49: PRODUCT NAME | D49: UNIT COST | E49: QUANTITY PER RECORD / ACCPOS | F49: ACTUAL INVENTORY | G49: JAN. ACTUAL | H49: REMARKS | I49: VARIANCE - QUANTITY | J49: VARIANCE - COST | K49: REMARKS / CAUSE OF VARIANCE
I75: =SUM(I50:I74) -> 0 | J75: =SUM(J50:J74) -> 0
B79: SHORT
B80: BARCODE | C80: PRODUCT NAME | D80: SRP | E80: QUANTITY PER RECORD / ACCPOS | F80: ACTUAL INVENTORY | G80: TOTAL COST - RECORD | H80: TOTAL COST - ACTUAL INVENTORY | I80: VARIANCE - QUANTITY | J80: VARIANCE - COST | K80: REMARKS / CAUSE OF VARIANCE
I84: =SUM(I81:I83) -> 0 | J84: =SUM(J81:J83) -> 0

Sheet CONVIE - final
B1: INVENTORY REPORT
B2: =PRINTING!B2 -> AS OF JUNE 2026
B3: COOP STORE
U4: STORE | W4: BODEGA 1 | Y4: BODEGA 2 | AA4: BO - COUNTER | AD4: EXPIRED
B5: SHELF NO. | C5: SHELF DESCRIPTION | D5: BARCODE | E5: PRODUCT NAME | F5: UNIT COST | G5: Actual Count May 2026 | H5: KINALANGUYAN STORE/Adjustment | I5: PURCHASES/ RETAIL | J5: PULL OUT | K5: SALES | L5: TOTAL | M5: ACTUAL INVENTORY | N5: TOTAL COST - RECORD | O5: TOTAL COST - ACTUAL INVENTORY | P5: VARIANCE - QUANTITY | Q5: VARIANCE - COST | R5: REMARKS / CAUSE OF VARIANCE | U5: QTY | V5: REMARKS | W5: QTY | X5: REMARKS | Y5: QTY | Z5: REMARKS | AA5: QTY | AB5: REMARKS | AD5: QTY | AE5: AMOUNT
B6: 1 | C6: CHIPS & SNACK | D6: 4800631001928 | E6: BOY BAWANG ASSORTED NUTS 85G | F6: 18.53 | G6: 11 | H6: 20 | K6: 30 | L6: =G6+I6-J6-K6+H6 -> 1 | M6: 1 | N6: =F6*L6 -> 18.53 | O6: =M6*F6 -> 18.53 | P6: =L6-M6 -> 0 | Q6: =N6-O6 -> 0 | S6: =U6+Y6+W6+AA6 -> 5 | T6: =M6-S6 -> -4 | U6: 5
B7: 1 | C7: CHIPS & SNACK | D7: 4809011 681392 | E7: BOY BAWANG CHILI CHEESE 100G | F7: 16.03 | G7: 23 | K7: 8 | L7: =G7+I7-J7-K7+H7 -> 15 | M7: 15 | N7: =F7*L7 -> 240.45 | O7: =M7*F7 -> 240.45 | P7: =L7-M7 -> 0 | Q7: =N7-O7 -> 0 | S7: =U7+Y7+W7+AA7 -> 26 | T7: =M7-S7 -> -11 | U7: 26
B8: 1 | C8: CHIPS & SNACK | D8: 4809011681095 | E8: BOY BAWANG CORNICK ADOBO 100G | F8: 16.03 | G8: 17 | K8: 4 | L8: =G8+I8-J8-K8+H8 -> 13 | M8: =10+2 -> 12 | N8: =F8*L8 -> 208.39 | O8: =M8*F8 -> 192.36 | P8: =L8-M8 -> 1 | Q8: =N8-O8 -> 16.03 | S8: =U8+Y8+W8+AA8 -> 23 | T8: =M8-S8 -> -11 | U8: 23
B9: 1 | C9: CHIPS & SNACK | D9: 4809011681507 | E9: BOY BAWANG CORNICK BBQ FLAVOR 100G | F9: 16.03 | G9: 70 | K9: 4 | L9: =G9+I9-J9-K9+H9 -> 66 | M9: =28+37 -> 65 | N9: =F9*L9 -> 1057.98 | O9: =M9*F9 -> 1041.95 | P9: =L9-M9 -> 1 | Q9: =N9-O9 -> 16.03 | S9: =U9+Y9+W9+AA9 -> 33 | T9: =M9-S9 -> 32 | U9: 33
B10: 1 | C10: CHIPS & SNACK | D10: 4800631681311 | E10: BOY BAWANG CORNICK LECHON MANOK FLAVOR | F10: 16.03 | G10: 25 | K10: 1 | L10: =G10+I10-J10-K10+H10 -> 24 | M10: =23+1 -> 24 | N10: =F10*L10 -> 384.72 | O10: =M10*F10 -> 384.72 | P10: =L10-M10 -> 0 | Q10: =N10-O10 -> 0 | S10: =U10+Y10+W10+AA10 -> 27 | T10: =M10-S10 -> -3 | U10: 27
B11: 1 | C11: CHIPS & SNACK | D11: 4800631000419 | E11: BOY BAWANG CRACKER NUTS 85G | F11: 17.95 | G11: 3 | K11: 3 | L11: =G11+I11-J11-K11+H11 -> 0 | N11: =F11*L11 -> 0 | O11: =M11*F11 -> 0 | P11: =L11-M11 -> 0 | Q11: =N11-O11 -> 0 | R11: over 3 sales | S11: =U11+Y11+W11+AA11 -> 5 | T11: =M11-S11 -> -5 | U11: 5
B12: 1 | C12: CHIPS & SNACK | D12: 4809011681378 | E12: BOY BAWANG GARLIC FLAVOR 100G | F12: 16.03 | G12: 58 | K12: 2 | L12: =G12+I12-J12-K12+H12 -> 56 | M12: 56 | N12: =F12*L12 -> 897.68 | O12: =M12*F12 -> 897.68 | P12: =L12-M12 -> 0 | Q12: =N12-O12 -> 0 | S12: =U12+Y12+W12+AA12 -> 19 | T12: =M12-S12 -> 37 | U12: 19
B13: 1 | C13: CHIPS & SNACK | D13: 4809011681194 | E13: BOY BAWANG HOT GARLIC 100G | F13: 16.03 | G13: 0 | L13: =G13+I13-J13-K13+H13 -> 0 | N13: =F13*L13 -> 0 | O13: =M13*F13 -> 0 | P13: =L13-M13 -> 0 | Q13: =N13-O13 -> 0 | S13: =U13+Y13+W13+AA13 -> 0 | T13: =M13-S13 -> 0
B14: 1 | C14: CHIPS & SNACK | D14: 4800631000488 | E14: BOY BAWANG MIXED NUTS GARLIC FLAVOR 100G | F14: 32.13 | G14: 36 | K14: 6 | L14: =G14+I14-J14-K14+H14 -> 30 | M14: 30 | N14: =F14*L14 -> 963.9 | O14: =M14*F14 -> 963.9 | P14: =L14-M14 -> 0 | Q14: =N14-O14 -> 0 | R14: 1-Expired 4/15/2025 | S14: =U14+Y14+W14+AA14 -> 4 | T14: =M14-S14 -> 26 | U14: 4
B15: 1 | C15: CHIPS & SNACK | D15: 4800631001867 | E15: BOY BAWANG SNACK MIX W/ REAL GARLIC CHIPS 85G | F15: 18.53 | G15: 19 | K15: 7 | L15: =G15+I15-J15-K15+H15 -> 12 | M15: 12 | N15: =F15*L15 -> 222.36 | O15: =M15*F15 -> 222.36 | P15: =L15-M15 -> 0 | Q15: =N15-O15 -> 0 | S15: =U15+Y15+W15+AA15 -> 27 | T15: =M15-S15 -> -15 | U15: 27
B16: 1 | C16: CHIPS & SNACK | D16: 4800194104128 | E16: CHEEZ ON CHIPS CHEESE FLAVOR 22G | F16: 6.18 | G16: 92 | K16: 1 | L16: =G16+I16-J16-K16+H16 -> 91 | M16: 91 | N16: =F16*L16 -> 562.38 | O16: =M16*F16 -> 562.38 | P16: =L16-M16 -> 0 | Q16: =N16-O16 -> 0 | R16: over 1 sales | S16: =U16+Y16+W16+AA16 -> 94 | T16: =M16-S16 -> -3 | U16: 6 | W16: =37+50+1 -> 88 | X16: EXPIRED 2024 MAY 2026-50 | AD16: 50 | AE16: =AD16*F16 -> 309
B17: 1 | C17: CHIPS & SNACK | D17: 4800216125919 | E17: CHEEZY CORN CRUNCH CHEESE 150G | F17: 51.54 | G17: 1 | L17: =G17+I17-J17-K17+H17 -> 1 | M17: 1 | N17: =F17*L17 -> 51.54 | O17: =M17*F17 -> 51.54 | P17: =L17-M17 -> 0 | Q17: =N17-O17 -> 0 | S17: =U17+Y17+W17+AA17 -> 1 | T17: =M17-S17 -> 0 | U17: 1
B18: 1 | C18: CHIPS & SNACK | D18: 4800216121041 | E18: CHEEZY CORN CRUNCH CHEESE 24G | F18: 7.4 | G18: 10 | L18: =G18+I18-J18-K18+H18 -> 10 | M18: 10 | N18: =F18*L18 -> 74 | O18: =M18*F18 -> 74 | P18: =L18-M18 -> 0 | Q18: =N18-O18 -> 0 | S18: =U18+Y18+W18+AA18 -> 10 | T18: =M18-S18 -> 0 | U18: 10
B19: 1 | C19: CHIPS & SNACK | D19: 4800216121058 | E19: CHEEZY CORN CRUNCH CHEESE 70G | F19: 26.09 | G19: 19 | K19: 2 | L19: =G19+I19-J19-K19+H19 -> 17 | M19: 17 | N19: =F19*L19 -> 443.53 | O19: =M19*F19 -> 443.53 | P19: =L19-M19 -> 0 | Q19: =N19-O19 -> 0 | S19: =U19+Y19+W19+AA19 -> 23 | T19: =M19-S19 -> -6 | U19: 23
B20: 1 | C20: CHIPS & SNACK | D20: 4800216121911 | E20: CHEEZY CORN CRUNCH RED HOT 22G | F20: 7.4 | L20: =G20+I20-J20-K20+H20 -> 0 | N20: =F20*L20 -> 0 | O20: =M20*F20 -> 0 | P20: =L20-M20 -> 0 | Q20: =N20-O20 -> 0 | S20: =U20+Y20+W20+AA20 -> 0 | T20: =M20-S20 -> 0
B21: 1 | C21: CHIPS & SNACK | D21: 4800216122437 | E21: CHEEZY CORN CRUNCH RED HOT 70G | F21: 26.09 | G21: 11 | K21: 1 | L21: =G21+I21-J21-K21+H21 -> 10 | M21: 10 | N21: =F21*L21 -> 260.9 | O21: =M21*F21 -> 260.9 | P21: =L21-M21 -> 0 | Q21: =N21-O21 -> 0 | S21: =U21+Y21+W21+AA21 -> 12 | T21: =M21-S21 -> -2 | U21: 12
B22: 1 | C22: CHIPS & SNACK | D22: 4800016115424 | E22: CHICHARRON NI MANG JUAN KLASIK CHICHARON 90G | F22: 17.1 | L22: =G22+I22-J22-K22+H22 -> 0 | N22: =F22*L22 -> 0 | O22: =M22*F22 -> 0 | P22: =L22-M22 -> 0 | Q22: =N22-O22 -> 0 | S22: =U22+Y22+W22+AA22 -> 0 | T22: =M22-S22 -> 0
B23: 1 | C23: CHIPS & SNACK | D23: 4800016110535 | E23: CHICHARRON NI MANG JUAN PAOMBONG 26G | F23: 6.83 | G23: 31 | H23: 20 | K23: 22 | L23: =G23+I23-J23-K23+H23 -> 29 | M23: 28 | N23: =F23*L23 -> 198.07 | O23: =M23*F23 -> 191.24 | P23: =L23-M23 -> 1 | Q23: =N23-O23 -> 6.83 | S23: =U23+Y23+W23+AA23 -> 35 | T23: =M23-S23 -> -7 | U23: 35
B24: 1 | C24: CHIPS & SNACK | D24: 4800016110511 | E24: CHICHARRON NI MANG JUAN PAOMBONG 90G | F24: 19.4 | L24: =G24+I24-J24-K24+H24 -> 0 | N24: =F24*L24 -> 0 | O24: =M24*F24 -> 0 | P24: =L24-M24 -> 0 | Q24: =N24-O24 -> 0 | S24: =U24+Y24+W24+AA24 -> 0 | T24: =M24-S24 -> 0
B25: 1 | C25: CHIPS & SNACK | D25: 4800016110542 | E25: CHICHARRON NI MANG JUAN SUKAT SILI 26G | F25: 6.83 | G25: 33 | K25: 3 | L25: =G25+I25-J25-K25+H25 -> 30 | M25: 29 | N25: =F25*L25 -> 204.9 | O25: =M25*F25 -> 198.07 | P25: =L25-M25 -> 1 | Q25: =N25-O25 -> 6.83 | S25: =U25+Y25+W25+AA25 -> 36 | T25: =M25-S25 -> -7 | U25: 36
B26: 1 | C26: CHIPS & SNACK | D26: 4800016110528 | E26: CHICHARRON NI MANG JUAN SUKAT SILI 90G | F26: 19.4 | L26: =G26+I26-J26-K26+H26 -> 0 | N26: =F26*L26 -> 0 | O26: =M26*F26 -> 0 | P26: =L26-M26 -> 0 | Q26: =N26-O26 -> 0 | S26: =U26+Y26+W26+AA26 -> 0 | T26: =M26-S26 -> 0
B27: 1 | C27: CHIPS & SNACK | D27: 4806505854423 | E27: CHICK BOY CALIFORNIA CRUNCH ONION & GARLIC FLAVOR 100G | F27: 17.65 | G27: 2 | H27: 10 | K27: 10 | L27: =G27+I27-J27-K27+H27 -> 2 | M27: 2 | N27: =F27*L27 -> 35.3 | O27: =M27*F27 -> 35.3 | P27: =L27-M27 -> 0 | Q27: =N27-O27 -> 0 | S27: =U27+Y27+W27+AA27 -> 6 | T27: =M27-S27 -> -4 | U27: 6
B28: 1 | C28: CHIPS & SNACK | D28: 4806505854225 | E28: CHICK BOY CHEESE FLAVOR 100G | F28: 17.65 | G28: 9 | K28: 1 | L28: =G28+I28-J28-K28+H28 -> 8 | M28: 8 | N28: =F28*L28 -> 141.2 | O28: =M28*F28 -> 141.2 | P28: =L28-M28 -> 0 | Q28: =N28-O28 -> 0 | S28: =U28+Y28+W28+AA28 -> 10 | T28: =M28-S28 -> -2 | U28: 10
B29: 1 | C29: CHIPS & SNACK | D29: 4806505854232 | E29: CHICK BOY SWEET CORN FLAVOR 100G | F29: 17.65 | G29: 15 | H29: 10 | K29: 19 | L29: =G29+I29-J29-K29+H29 -> 6 | M29: 6 | N29: =F29*L29 -> 105.9 | O29: =M29*F29 -> 105.9 | P29: =L29-M29 -> 0 | Q29: =N29-O29 -> 0 | S29: =U29+Y29+W29+AA29 -> 1 | T29: =M29-S29 -> 5 | U29: 1
B30: 1 | C30: CHIPS & SNACK | D30: 4806505854416 | E30: CHICK BOY TEXAS SMOKED BBQ FLAVOR 100G | F30: 17.65 | G30: 2 | H30: 10 | K30: 12 | L30: =G30+I30-J30-K30+H30 -> 0 | N30: =F30*L30 -> 0 | O30: =M30*F30 -> 0 | P30: =L30-M30 -> 0 | Q30: =N30-O30 -> 0 | S30: =U30+Y30+W30+AA30 -> 1 | T30: =M30-S30 -> -1 | U30: 1
B31: 1 | C31: CHIPS & SNACK | D31: 4800016115011 | E31: CHICKN SKIN NI MANG JUAN 17G | F31: 7.06 | H31: 35 | L31: =G31+I31-J31-K31+H31 -> 35 | M31: 35 | N31: =F31*L31 -> 247.1 | O31: =M31*F31 -> 247.1 | P31: =L31-M31 -> 0 | Q31: =N31-O31 -> 0 | S31: =U31+Y31+W31+AA31 -> 0 | T31: =M31-S31 -> 35
B32: 1 | C32: CHIPS & SNACK | D32: 4800016115011 | E32: CHICKN SKIN NI MANG JUAN 17G | F32: 7.056 | I32: 100 | K32: 40 | L32: =G32+I32-J32-K32+H32 -> 60 | M32: 60 | N32: =F32*L32 -> 423.36 | O32: =M32*F32 -> 423.36 | P32: =L32-M32 -> 0 | Q32: =N32-O32 -> 0 | S32: =U32+Y32+W32+AA32 -> 0 | T32: =M32-S32 -> 60
B33: 1 | C33: CHIPS & SNACK | D33: 4800016115257 | E33: CHICKN SKIN NI MANG JUAN 70G | F33: 18.03 | G33: 27 | J33: 27 | L33: =G33+I33-J33-K33+H33 -> 0 | N33: =F33*L33 -> 0 | O33: =M33*F33 -> 0 | P33: =L33-M33 -> 0 | Q33: =N33-O33 -> 0 | S33: =U33+Y33+W33+AA33 -> 28 | T33: =M33-S33 -> -28 | U33: 28
B34: 1 | C34: CHIPS & SNACK | D34: 4800016643095 | E34: CHIPPY BBQ FLAVOR 110G | F34: 22.68 | G34: 16 | K34: 3 | L34: =G34+I34-J34-K34+H34 -> 13 | M34: 13 | N34: =F34*L34 -> 294.84 | O34: =M34*F34 -> 294.84 | P34: =L34-M34 -> 0 | Q34: =N34-O34 -> 0 | S34: =U34+Y34+W34+AA34 -> 23 | T34: =M34-S34 -> -10 | U34: 23
B35: 1 | C35: CHIPS & SNACK | D35: 4800016643095 | E35: CHIPPY BBQ FLAVOR 110G | F35: 23.07 | L35: =G35+I35-J35-K35+H35 -> 0 | N35: =F35*L35 -> 0 | O35: =M35*F35 -> 0 | P35: =L35-M35 -> 0 | Q35: =N35-O35 -> 0 | S35: =U35+Y35+W35+AA35 -> 0 | T35: =M35-S35 -> 0
B36: 1 | C36: CHIPS & SNACK | D36: 4800016642029 | E36: CHIPPY BBQ FLAVOR 27G | F36: 6.71 | G36: 3 | H36: 1 | J36: 1 | K36: 2 | L36: =G36+I36-J36-K36+H36 -> 1 | M36: 1 | N36: =F36*L36 -> 6.71 | O36: =M36*F36 -> 6.71 | P36: =L36-M36 -> 0 | Q36: =N36-O36 -> 0 | S36: =U36+Y36+W36+AA36 -> 7 | T36: =M36-S36 -> -6 | U36: 7
B37: 1 | C37: CHIPS & SNACK | D37: 4800016642029 | E37: CHIPPY BBQ FLAVOR 27G | F37: 6.83 | L37: =G37+I37-J37-K37+H37 -> 0 | N37: =F37*L37 -> 0 | O37: =M37*F37 -> 0 | P37: =L37-M37 -> 0 | Q37: =N37-O37 -> 0 | S37: =U37+Y37+W37+AA37 -> 0 | T37: =M37-S37 -> 0
B38: 1 | C38: CHIPS & SNACK | D38: 4800194117326 | E38: CHOCO FLAKES CEREALS 22G | F38: 6.18 | G38: 141 | L38: =G38+I38-J38-K38+H38 -> 141 | M38: =57+50+34 -> 141 | N38: =F38*L38 -> 871.38 | O38: =M38*F38 -> 871.38 | P38: =L38-M38 -> 0 | Q38: =N38-O38 -> 0 | R38: 46143 | S38: =U38+Y38+W38+AA38 -> 141 | T38: =M38-S38 -> 0 | U38: 34 | W38: =57+50 -> 107 | X38: EXPIRED 2024 & MAY 2026-50 | AD38: 57 | AE38: =AD38*F38 -> 352.26
B39: 1 | C39: CHIPS & SNACK | D39: 4800216110045 | E39: CLOVER CHEESE 145G | F39: 51.06 | G39: 24 | H39: 1 | L39: =G39+I39-J39-K39+H39 -> 25 | M39: 25 | N39: =F39*L39 -> 1276.5 | O39: =M39*F39 -> 1276.5 | P39: =L39-M39 -> 0 | Q39: =N39-O39 -> 0 | R39: 45343 | S39: =U39+Y39+W39+AA39 -> 25 | T39: =M39-S39 -> 0 | W39: 25 | X39: EXPIRED 2024 | AD39: =W39 -> 25 | AE39: =AD39*F39 -> 1276.5
B40: 1 | C40: CHIPS & SNACK | D40: 4800216120013 | E40: CLOVER CHEESE 24G | F40: 7.51 | G40: 94 | K40: 8 | L40: =G40+I40-J40-K40+H40 -> 86 | M40: =64+20 -> 84 | N40: =F40*L40 -> 645.86 | O40: =M40*F40 -> 630.84 | P40: =L40-M40 -> 2 | Q40: =N40-O40 -> 15.02 | R40: 20-EXPIRED 8/21/2024 | S40: =U40+Y40+W40+AA40 -> 99 | T40: =M40-S40 -> -15 | U40: 79 | W40: 20 | X40: EXPIRED 2024 | AD40: =W40 -> 20 | AE40: =AD40*F40 -> 150.2
...

Sheet VB-final
A1: VARIANCE BREAKDOWN (CONVIE)
A2: =PRINTING!B2 -> AS OF JUNE 2026
A3: OVER
A4: BARCODE | B4: PRODUCT NAME | C4: UNIT COST | D4: TOTAL | E4: ACTUAL | F4: VARIANCE - QUANTITY | G4: VARIANCE - COST | H4: REMARKS / CAUSE OF VARIANCE
A5: 4800888139283 | B5: CREAMSILK GREEN 11ML | C5: 6.17 | D5: 1 | E5: 2 | F5: -1 | G5: -6.17
A6: 4800888217523 | B6: DOVE SERUM CONDITIONER AMINO RESTORE 10ML | C6: 6.48 | D6: 306 | E6: 311 | F6: -5 | G6: -32.4
A7: 4801234146078 | B7: GLADE SG FRESH LEMON 180G VALUE PACK | C7: 267 | D7: 5 | E7: 6 | F7: -1 | G7: -267
A8: 4902430522809 | B8: HEAD & SHOULDER ANTI-DANDRUFF SHAMPOO ULTRA MEN COOL MENTHOL 12ML | C8: 6.82 | D8: 4 | E8: 5 | F8: -1 | G8: -6.82
A9: 4801010342717 | B9: MODESS REGULAR W/ WINGS 9+1 PADS | C9: 37.25 | D9: 13 | E9: 14 | F9: -1 | G9: -37.25
A10: 4808888004181 | B10: PALMOLIVE VIOLET BUY 11 GET 1 FREE | C10: 57.77 | D10: 114 | E10: 115 | F10: -1 | G10: -57.77
A11: 4902430634014 | B11: PANTENE HAIR FALL CONTROL SUPPLEMENT CONDITIONER 13ML | C11: 7.33 | D11: 140 | E11: 141 | F11: -1 | G11: -7.33
A12: 4800888151100 | B12: REXONA WOMEN DEO LOTION PASSION 3ML | C12: 6.6 | D12: 9 | E12: 10 | F12: -1 | G12: -6.6
A13: 4902430935616 | B13: SAFEGUARD FLORAL PINK W/ ALOE 130G | C13: 47.2 | D13: 38 | E13: 39 | F13: -1 | G13: -47.2
A14: 4902430381772 | B14: SAFEGUARD IVORY WHITE CARE 60G | C14: 18.64 | D14: 133 | E14: 136 | F14: -3 | G14: -55.92
A15: 4902430934800 | B15: SAFEGUARD PURE WHITE 130G | C15: 47.2 | D15: 40 | E15: 47 | F15: -7 | G15: -330.4
A16: 4902430222891 | B16: SAFEGUARD PURE WHITE SUPER SAVINGS PACK 175G | C16: 55.86 | D16: 21 | E16: 31 | F16: -10 | G16: -558.6
... A52: 200049 | B52: HBW MATRIX BALLPEN RED | C52: 5 | D52: 19 | E52: 20 | F52: -1 | G52: -5
D53: =SUM(D5:D52) -> 3127 | E53: =SUM(E5:E52) -> 3777 | F53: =SUM(F5:F52) -> -650 | G53: =SUM(G5:G52) -> -11977.6
A54: RETURN
A55: BARCODE | B55: PRODUCT NAME | C55: UNIT COST | F55: VARIANCE - QUANTITY | G55: VARIANCE - COST | H55: REMARKS / CAUSE OF VARIANCE
F57: =SUM(F56:F56) -> 0 | G57: =SUM(G56:G56) -> 0
A59: SHORT
A60: BARCODE | B60: PRODUCT NAME | C60: UNIT COST | D60: TOTAL | E60: ACTUAL | F60: VARIANCE - QUANTITY | G60: VARIANCE - COST | H60: REMARKS / CAUSE OF VARIANCE
A61: 4809011681095 | B61: BOY BAWANG CORNICK ADOBO 100G | C61: 16.03 | D61: 13 | E61: 12 | F61: 1 | G61: 16.03
A62: 4809011681507 | B62: BOY BAWANG CORNICK BBQ FLAVOR 100G | C62: 16.03 | D62: 66 | E62: 65 | F62: 1 | G62: 16.03
A63: 4800016110535 | B63: CHICHARRON NI MANG JUAN PAOMBONG 26G | C63: 6.83 | D63: 29 | E63: 28 | F63: 1 | G63: 6.83
A64: 4800016110542 | B64: CHICHARRON NI MANG JUAN SUKAT SILI 26G | C64: 6.83 | D64: 30 | E64: 29 | F64: 1 | G64: 6.83
A65: 4800216120013 | B65: CLOVER CHEESE 24G | C65: 7.51 | D65: 86 | E65: 84 | F65: 2 | G65: 15.02
A66: 4800216110069 | B66: CLOVER CHIPS CHEESE 55G | C66: 22.19 | D66: 3 | F66: 3 | G66: 66.57
A67: 4800194116114 | B67: CORN OLE BARBECUE FLAVOR 22G | C67: 6.18 | D67: 77 | E67: 73 | F67: 4 | G67: 24.72
A68: 4800016680540 | B68: HONEY BUTTER POTATO CHIPS 22G | C68: 16.58 | D68: 95 | E68: 94 | F68: 1 | G68: 16.58
A69: 4800361028639 | B69: NESTLE KOKO KRUNCH 20G | C69: 11.78 | D69: 1 | F69: 1 | G69: 11.78
A70: 4800194177962 | B70: OISHI PRAWN CRACKERS SPICY FLAVOR 90G | C70: 21.97 | D70: 17 | E70: 16 | F70: 1 | G70: 21.97
A71: 4800116099020 | B71: BUTTER CREAM ENSAYMADA CRACKERS 10X25G | C71: 58.45 | D71: 9 | E71: 8 | F71: 1 | G71: 58.45
A72: 4800552888059 | B72: CHIPS DELIGHT CHOCOLATE CHIP COOKIES 80G | C72: 30.04 | D72: 9 | E72: 8 | F72: 1 | G72: 30.04
A73: 4800016627262 | B73: CHOCO KNOTS CHOCOLATE 28G | C73: 7.48 | D73: 24 | E73: 22 | F73: 2 | G73: 14.96
A74: 4806502726822 | B74: GAR NEUBAKE WHITE BREAD 450G | C74: 53.9 | D74: 2 | E74: 1 | F74: 1 | G74: 53.9
A75: 8998389124184 | B75: KUKIS KELAPA COCONUT 60G | C75: 12.77 | D75: 1 | F75: 1 | G75: 12.77
A76: 4800016083778 | B76: MAGIC CHIPS SOUR CREAM AND ONION 28G | C76: 6.8 | D76: 3 | F76: 3 | G76: 20.4
A77: 4807770100703 | B77: NISSIN BREAD STIX 20G | C77: 5.68 | D77: 1 | F77: 1 | G77: 5.68
...

Sheet JUNE SALES-
A1: SALES
A2: =PRINTING!B2 -> AS OF JUNE 2026
A3: DATE | B3: PARTICULAR | C3: TRANSACTION NO: | D3: DESCRIPTION | E3: QTY. | F3: COST PRICE | G3: UNIT PRICE | H3: CASH SALE | I3: ACCOUNT RECEIVABLE | J3: SALES DISCOUNT | K3: NET SALES | L3: COGS
A4: 06/01/2026 | B4: 4800631001928 | C4: 0-144075 | D4: BOY BAWANG ASSORTED NUTS 85G | E4: 2 | F4: 19.1 | G4: 22 | H4: =E4*G4 -> 44 | J4: 0 | K4: =H4+I4-J4 -> 44 | L4: =E4*F4 -> 38.2
A5: 06/01/2026 | B5: 8998866605076 | C5: 0-144076 | D5: WINGS TOTAL CARE W/ LAUNDRY SANITIZER 60G | E5: 2 | F5: 5 | G5: 5.75 | H5: =E5*G5 -> 11.5 | J5: 0 | K5: =H5+I5-J5 -> 11.5 | L5: =E5*F5 -> 10
A6: 06/01/2026 | B6: 4800047841040 | C6: 0-144076 | D6: DEL FABCON BLOSSOM RUSH 22ML | E6: 6 | F6: 3.72 | G6: 4.5 | H6: =E6*G6 -> 27 | J6: 0 | K6: =H6+I6-J6 -> 27 | L6: =E6*F6 -> 22.32
A7: 06/01/2026 | B7: 4800010075922 | C7: 0-144076 | D7: PRESTO CREAMS PEANUT BUTTER 300G | E7: 1 | F7: 59.51 | G7: 68.5 | H7: =E7*G7 -> 68.5 | J7: 0 | K7: =H7+I7-J7 -> 68.5 | L7: =E7*F7 -> 59.51
A8: 06/01/2026 | B8: 4800888221049 | C8: 0-144076 | D8: SURF POWDER ROSE FRESH 6+1 | E8: 1 | F8: 38.25 | G8: 44 | H8: =E8*G8 -> 44 | J8: 0 | K8: =H8+I8-J8 -> 44 | L8: =E8*F8 -> 38.25
A9: 06/01/2026 | B9: 4800116135001 | C9: 0-144078 | D9: OTC BUTTER CREAM CHOCOLATE SPREAD 17G | E9: 1 | F9: 4.12 | G9: 5.25 | H9: =E9*G9 -> 5.25 | J9: 0 | K9: =H9+I9-J9 -> 5.25 | L9: =E9*F9 -> 4.12
A10: 06/01/2026 | B10: 4807770122705 | C10: 0-144078 | D10: OTC MONDE CHOCO PUFF | E10: 1 | F10: 8.15 | G10: 9.5 | H10: =E10*G10 -> 9.5 | J10: 0 | K10: =H10+I10-J10 -> 9.5 | L10: =E10*F10 -> 8.15
A11: 06/01/2026 | B11: 8998389124184 | C11: 0-144079 | D11: KUKIS KELAPA COCONUT 60G | E11: 1 | F11: 12.77 | G11: 14.75 | H11: =E11*G11 -> 14.75 | J11: 0 | K11: =H11+I11-J11 -> 14.75 | L11: =E11*F11 -> 12.77
A12: 06/01/2026 | B12: 888123456781304 | C12: 0-144079 | D12: PANI-PEANUT | E12: 1 | F12: 90 | G12: 120 | H12: =E12*G12 -> 120 | J12: 0 | K12: =H12+I12-J12 -> 120 | L12: =E12*F12 -> 90
A13: 06/01/2026 | B13: 4800216121058 | C13: 0-144080 | D13: CHEEZY CORN CRUNCH CHEESE 70G | E13: 1 | F13: 27.5 | G13: 30 | H13: =E13*G13 -> 30 | J13: 0 | K13: =H13+I13-J13 -> 30 | L13: =E13*F13 -> 27.5
A14: 06/01/2026 | B14: 4800888151100 | C14: 0-144080 | D14: REXONA WOMEN DEO LOTION PASSION 3ML | E14: 2 | F14: 6.6 | G14: 7.75 | H14: =E14*G14 -> 15.5 | J14: 0 | K14: =H14+I14-J14 -> 15.5 | L14: =E14*F14 -> 13.2
A15: 06/01/2026 | B15: 4800888147240 | C15: 0-144080 | D15: CLOSE UP MENTHOL FRESH 2X11G | E15: 1 | F15: 7.75 | G15: 9 | H15: =E15*G15 -> 9 | J15: 0 | K15: =H15+I15-J15 -> 9 | L15: =E15*F15 -> 7.75
... A37: 06/02/2026 | B37: 4800888602725 | C37: 0-144102 | D37: KNORR PORK BROTH CUBE 10G | E37: 2 | F37: 6.02 | G37: 7.25 | H37: =E37*G37 -> 14.5 | J37: 0 | K37: =H37+I37-J37 -> 14.5 | L37: =E37*F37 -> 12.04
A38: 06/02/2026 | B38: 4800361393645 | C38: 0-144103 | D38: NESCAFE CLASSIC RESEALABLE 50G | E38: 1 | G38: 58 | H38: =E38*G38 -> 58 | J38: 0 | K38: =H38+I38-J38 -> 58 | L38: =E38*F38 -> 0
A39: 06/02/2026 | B39: 4800631001928 | C39: 0-144104 | D39: BOY BAWANG ASSORTED NUTS 85G | E39: 2 | F39: 19.1 | G39: 22 | H39: =E39*G39 -> 44 | J39: 0 | K39: =H39+I39-J39 -> 44 | L39: =E39*F39 -> 38.2
A40: 06/02/2026 | B40: 4800361415347 | C40: 0-144105 | D40: NESCAFE ORIGINAL TWIN PACK 56G | E40: 1 | F40: 13.32 | G40: 15.5 | H40: =E40*G40 -> 15.5 | J40: 0 | K40: =H40+I40-J40 -> 15.5 | L40: =E40*F40 -> 13.32
A41: 06/02/2026 | B41: 888123456781858 | C41: 0-144106 | D41: OTC DYNAMITE MELON MINT RETAIL | E41: 5 | F41: 0.76 | G41: 1 | H41: =E41*G41 -> 5 | J41: 0 | K41: =H41+I41-J41 -> 5 | L41: =E41*F41 -> 3.8
A42: 06/02/2026 | B42: 8998666001702 | C42: 0-144107 | D42: KOPIKO BLACK 3IN1 TWINPACK 60G | E42: 1 | F42: 12.56 | G42: 14.25 | H42: =E42*G42 -> 14.25 | J42: 0 | K42: =H42+I42-J42 -> 14.25 | L42: =E42*F42 -> 12.56
A43: 06/02/2026 | B43: 4808680221250 | C43: 0-144110 | D43: KNORR CREAM OF MUSHROOM SOUP MIX 70G | E43: 1 | F43: 51.97 | G43: 60 | H43: =E43*G43 -> 60 | J43: 0 | K43: =H43+I43-J43 -> 60 | L43: =E43*F43 -> 51.97
A44: 06/02/2026 | B44: 4800888218940 | C44: 0-144110 | D44: SURF POWDER ANTIBACTERIAL 60G | E44: 2 | F44: 6.37 | G44: 7.5 | H44: =E44*G44 -> 15 | J44: 0 | K44: =H44+I44-J44 -> 15 | L44: =E44*F44 -> 12.74
A45: 06/02/2026 | B45: 4801958250006 | C45: 0-144110 | D45: AJI-NO-MOTO UMAMI SEASONING 250G | E45: 3 | F45: 60.4 | G45: 70 | H45: =E45*G45 -> 210 | J45: 0 | K45: =H45+I45-J45 -> 210 | L45: =E45*F45 -> 181.2
A46: 06/02/2026 | B46: 4800024570611 | C46: 0-144110 | D46: DM PINEAPPLE TIDBITS 115G | E46: 3 | F46: 15.91 | G46: 18.5 | H46: =E46*G46 -> 55.5 | J46: 0 | K46: =H46+I46-J46 -> 55.5 | L46: =E46*F46 -> 47.73
A47: 06/02/2026 | B47: 4801668500224 | C47: 0-144110 | D47: DATU PUTI SOY SAUCE 1L | E47: 3 | F47: 51 | G47: 60.25 | H47: =E47*G47 -> 180.75 | J47: 0 | K47: =H47+I47-J47 -> 180.75 | L47: =E47*F47 -> 153
A48: 06/02/2026 | B48: 4808647020094 | C48: 0-144110 | D48: EDEN CHEESE ORIGINAL 160G | E48: 1 | F48: 53.81 | G48: 62 | H48: =E48*G48 -> 62 | J48: 0 | K48: =H48+I48-J48 -> 62 | L48: =E48*F48 -> 53.81
A49: 06/02/2026 | B49: 4800361061322 | C49: 0-144110 | D49: NESTLE ALL PURPOSE CREAM 250ML | E49: 1 | F49: 67.29 | G49: 77.5 | H49: =E49*G49 -> 77.5 | J49: 0 | K49: =H49+I49-J49 -> 77.5 | L49: =E49*F49 -> 67.29
A50: 06/02/2026 | B50: 4800361419307 | C50: 0-144110 | D50: NESTLE CARNATION CONDENSADA 300ML | E50: 1 | F50: 64.49 | G50: 74.25 | H50: =E50*G50 -> 74.25 | J50: 0 | K50: =H50+I50-J50 -> 74.25 | L50: =E50*F50 -> 64.49
... A102: 06/03/2026 | B102: 4800575140370 | C102: 0-144148 | D102: ALASKA EVAPORADA CREAMER 360ML | E102: 1 | F102: 35.15 | G102: 41 | H102: =E102*G102 -> 41 | J102: 0 | K102: =H102+I102-J102 -> 41 | L102: =E102*F102 -> 35.15
A103: 06/03/2026 | B103: 748485800011 | C103: 0-144148 | D103: ARGENTINA CORN BEEF 175G | E103: 1 | G103: 47.5 | H103: =E103*G103 -> 47.5 | J103: 0 | K103: =H103+I103-J103 -> 47.5 | L103: =E103*F103 -> 0
A104: 06/03/2026 | B104: 4800888602718 | C104: 0-144148 | D104: KNORR CHICKEN BROTH CUBE 10G | E104: 1 | F104: 6.02 | G104: 7.25 | H104: =E104*G104 -> 7.25 | J104: 0 | K104: =H104+I104-J104 -> 7.25 | L104: =E104*F104 -> 6.02
A105: 06/03/2026 | B105: 4800054111228 | C105: 0-144149 | D105: GROWERS GARLIC FLAVOR PEANUTS 30G | E105: 1 | F105: 12.69 | G105: 14.75 | H105: =E105*G105 -> 14.75 | J105: 0 | K105: =H105+I105-J105 -> 14.75 | L105: =E105*F105 -> 12.69
A106: 06/03/2026 | B106: 888123456781258 | C106: 0-144150 | D106: OTC MAXX CHERRY | E106: 6 | F106: 0.76 | G106: 1 | H106: =E106*G106 -> 6 | J106: 0 | K106: =H106+I106-J106 -> 6 | L106: =E106*F106 -> 4.56
A107: 06/03/2026 | B107: 888123456781549 | C107: 0-144152 | D107: OTC DYNAMITE CHOCO MINT RETAIL | E107: 1 | F107: 0.76 | G107: 1 | H107: =E107*G107 -> 1 | J107: 0 | K107: =H107+I107-J107 -> 1 | L107: =E107*F107 -> 0.76
A108: 06/03/2026 | B108: 888123456781858 | C108: 0-144152 | D108: OTC DYNAMITE MELON MINT RETAIL | E108: 4 | F108: 0.76 | G108: 1 | H108: =E108*G108 -> 4 | J108: 0 | K108: =H108+I108-J108 -> 4 | L108: =E108*F108 -> 3.04
A109: 06/03/2026 | B109: 4806500472639 | C109: 0-144155 | D109: FAVORITO PANCIT CANTON 400G | E109: 2 | F109: 48.6 | G109: 56 | H109: =E109*G109 -> 112 | J109: 0 | K109: =H109+I109-J109 -> 112 | L109: =E109*F109 -> 97.2
A110: 06/03/2026 | B110: 4800361410816 | C110: 0-144157 | D110: NESTLE BEARBRAND SWAK PACK 33G | E110: 2 | F110: 10.64 | G110: 12.25 | H110: =E110*G110 -> 24.5 | J110: 0 | K110: =H110+I110-J110 -> 24.5 | L110: =E110*F110 -> 21.28
A111: 06/03/2026 | B111: 888123456781858 | C111: 0-144158 | D111: OTC DYNAMITE MELON MINT RETAIL | E111: 2 | F111: 0.76 | G111: 1 | H111: =E111*G111 -> 2 | J111: 0 | K111: =H111+I111-J111 -> 2 | L111: =E111*F111 -> 1.52
A112: 06/03/2026 | B112: 748485401492 | C112: 0-144160 | D112: BIRCH TREE 33G | E112: 1 | F112: 7.85 | G112: 12 | H112: =E112*G112 -> 12 | J112: 0 | K112: =H112+I112-J112 -> 12 | L112: =E112*F112 -> 7.85
...

Sheet VARIANCE-checking
A1: SHORT
A2: SHELF NO. | B2: BARCODE | C2: PRODUCT NAME | D2: UNIT COST | E2: Actual Count May 2026 | F2: PURCHASES/ RETAIL | G2: PULL OUT | H2: SALES | I2: TOTAL | J2: ACTUAL INVENTORY | K2: VARIANCE - QUANTITY | L2: VARIANCE - COST | M2: REMARKS / CAUSE OF VARIANCE
A3: 1 | B3: 4809011681095 | C3: BOY BAWANG CORNICK ADOBO 100G | D3: 16.03 | E3: 17 | H3: 4 | I3: 13 | J3: 12 | K3: 1 | L3: 16.03
A4: 1 | B4: 4809011681507 | C4: BOY BAWANG CORNICK BBQ FLAVOR 100G | D4: 16.03 | E4: 70 | H4: 4 | I4: 66 | J4: 65 | K4: 1 | L4: 16.03
A5: 1 | B5: 4800631000488 | C5: BOY BAWANG MIXED NUTS GARLIC FLAVOR 100G | D5: 32.13 | E5: 36 | H5: 6 | I5: 30 | J5: 16 | K5: 14 | L5: 449.82 | M5: 1-Expired 4/15/2025
A6: 1 | B6: 4800016110542 | C6: CHICHARRON NI MANG JUAN SUKAT SILI 26G | D6: 6.83 | E6: 33 | H6: 3 | I6: 30 | J6: 29 | K6: 1 | L6: 6.83
A7: 1 | B7: 4800216120013 | C7: CLOVER CHEESE 24G | D7: 7.51 | E7: 94 | H7: 8 | I7: 86 | J7: 84 | K7: 2 | L7: 15.02 | M7: 20-EXPIRED 8/21/2024
A8: 1 | B8: 4800216126800 | C8: CLOVER CHIPS CHILI&CHEESE 55G | D8: 21.34 | E8: 7 | I8: 7 | J8: 5 | K8: 2 | L8: 42.68 | M8: 45903
A9: 1 | B9: 4800194116114 | C9: CORN OLE BARBECUE FLAVOR 22G | D9: 6.18 | E9: 228 | I9: 228 | J9: 73 | K9: 155 | L9: 957.9
A10: 1 | B10: 4800054111280 | C10: GROWERS GARLIC FLAVOR PEANUTS 80G | D10: 34.38 | E10: 5 | H10: 2 | I10: 3 | J10: 2 | K10: 1 | L10: 34.38
A11: 1 | B11: 4800054123283 | C11: GROWERS MIX NUTS 80G | D11: 61.5 | E11: 19 | H11: 3 | I11: 16 | J11: 15 | K11: 1 | L11: 61.5
A12: 1 | B12: 4800054121227 | C12: GROWERS SALTED CASHEW NUTS | D12: 30.77 | E12: 25 | I12: 25 | K12: 25 | L12: 769.25
A13: 1 | B13: 4800054125287 | C13: GROWERS SALTED PISTACHIO NUTS 80G | D13: 114.79 | E13: 22 | I13: 22 | J13: 21 | K13: 1 | L13: 114.79
A14: 1 | B14: 4800054112287 | C14: GROWERS SAVOURY HOT PEANUTS 80G | D14: 36.58 | E14: 22 | H14: 1 | I14: 21 | K14: 21 | L14: 768.18
A15: 1 | B15: 4800054122224 | C15: GROWERS TOASTED CASHEW NUTS 28G | D15: 30.77 | E15: 9 | I15: 9 | K15: 9 | L15: 276.93
A16: 1 | B16: 4800016680540 | C16: HONEY BUTTER POTATO CHIPS 22G | D16: 16.58 | E16: 18 | F16: 80 | H16: 3 | I16: 95 | J16: 94 | K16: 1 | L16: 16.58
A17: 1 | B17: 4800016680267 | C17: HONEY BUTTER POTATO CHIPS 60G | D17: 39.48 | E17: 23 | H17: 8 | I17: 15 | K17: 15 | L17: 592.2
A18: 1 | B18: 4800361028639 | C18: NESTLE KOKO KRUNCH 20G | D18: 11.78 | E18: 1 | I18: 1 | K18: 1 | L18: 11.78
A19: 1 | B19: 4800194177962 | C19: OISHI PRAWN CRACKERS SPICY FLAVOR 90G | D19: 21.97 | E19: 17 | I19: 17 | J19: 16 | K19: 1 | L19: 21.97 | M19: 15-expired 5/2026
A20: 1 | B20: 4800016603259 | C20: VCUT CHEESE 25G | D20: 15.65 | E20: 129 | H20: 1 | I20: 128 | J20: 75 | K20: 53 | L20: 829.45 | M20: 23-EXPIRED 11/24/2025
A21: 2 | B21: 4800220608750 | C21: EMBASSY PREMIUM BLENDED WHISKY 750ML | D21: 147.75 | E21: 3 | I21: 3 | K21: 3 | L21: 443.25
A22: 2 | B22: 8410028901289 | C22: VINO FONTANA SWEET RED 750ML | D22: 239.94 | E22: 7 | I22: 7 | K22: 7 | L22: 1679.58
A23: 3 | B23: 4807770100611 | C23: BINGO DOUBLE CHOCO 280G | D23: 57.25 | E23: 7 | H23: 2 | I23: 5 | J23: 1 | K23: 4 | L23: 229
A24: 3 | B24: 4800194173223 | C24: BREAD PAN CHEESE&ONION 42G | D24: 10.75 | E24: 50 | I24: 50 | K24: 50 | L24: 537.5
A25: 3 | B25: 4800116099020 | C25: BUTTER CREAM ENSAYMADA CRACKERS 10X25G | D25: 58.45 | E25: 11 | G25: 1 | H25: 1 | I25: 9 | J25: 8 | K25: 1 | L25: 58.45
A26: 3 | B26: 4800552888059 | C26: CHIPS DELIGHT CHOCOLATE CHIP COOKIES 80G | D26: 30.04 | E26: 11 | H26: 2 | I26: 9 | J26: 8 | K26: 1 | L26: 30.04
A27: 3 | B27: 4800016627262 | C27: CHOCO KNOTS CHOCOLATE 28G | D27: 7.48 | E27: 10 | F27: 25 | G27: 8 | H27: 3 | I27: 24 | J27: 22 | K27: 2 | L27: 14.96
A28: 3 | B28: 4806502726532 | C28: GAR BANANA CHOCO MUFFIN 45G | D28: 22.85 | E28: 6 | H28: 1 | I28: 5 | K28: 5 | L28: 114.25
A29: 3 | B29: 4806502726129 | C29: GAR CHEESE BUNS 250G | D29: 65 | E29: 1 | F29: 4 | H29: 2 | I29: 3 | J29: 1 | K29: 2 | L29: 130
A30: 3 | B30: 4806502720301 | C30: GAR HIGH FIBER WHEAT BREAD 600G | D30: 100 | E30: 2 | F30: 3 | H30: 2 | I30: 3 | K30: 3 | L30: 300
A31: 3 | B31: 4806502725894 | C31: GAR HIGH FIBER WHEAT RAISIN LOAF 400G | D31: 89.1 | E31: 2 | I31: 2 | K31: 2 | L31: 178.2
A32: 3 | B32: 4806502725900 | C32: GAR HIGH FIBER WHEAT RAISIN LOAF 600G | D32: 113.65 | E32: 1 | I32: 1 | K32: 1 | L32: 113.65
A33: 3 | B33: 4806502725900 | C33: GAR HIGH FIBER WHEAT RAISIN LOAF 600G | D33: 125 | E33: 1 | I33: 1 | K33: 1 | L33: 125
A34: 3 | B34: 4806502726907 | C34: GAR NEUBAKE CLASSIC WHITE BREAD SUPER SLICE 300G | D34: 41.15 | E34: 1 | F34: 2 | G34: 2 | I34: 1 | K34: 1 | L34: 41.15
A35: 3 | B35: 4806502726822 | C35: GAR NEUBAKE WHITE BREAD 450G | D35: 53.9 | E35: 2 | F35: 5 | G35: 3 | H35: 2 | I35: 2 | J35: 1 | K35: 1 | L35: 53.9
A36: 3 | B36: 8850338005206 | C36: HALLS FRESH LIME 140G | D36: 41.46 | E36: 1 | I36: 1 | K36: 1 | L36: 41.46
A37: 3 | B37: 4800016079559 | C37: HELLO CHOCO COATED WAFER SANDWICH 15GX10 | D37: 49.65 | E37: 2 | I37: 2 | K37: 2 | L37: 99.3
A38: 3 | B38: 8998389124184 | C38: KUKIS KELAPA COCONUT 60G | D38: 12.77 | E38: 10 | H38: 9 | I38: 1 | K38: 1 | L38: 12.77
A39: 3 | B39: 4800016087622 | C39: MAGIC CREAM BUTTER | D39: 53.87 | E39: 2 | I39: 2 | K39: 2 | L39: 107.74
A40: 3 | B40: 4800016628283 | C40: MINI CHOCO PRETZELS 28G | D40: 7.41 | E40: 3 | F40: 25 | G40: 4 | H40: 8 | I40: 16 | J40: 3 | K40: 13 | L40: 96.33
...

Sheet KINALANGUYAN
A1: DATE | B1: PARTICULAR | C1: TRANSACTION NO: | D1: DESCRIPTION | E1: QTY. | F1: COST PRICE | G1: UNIT PRICE | H1: CASH SALE | I1: ACCOUNT RECEIVABLE | J1: SALES DISCOUNT | K1: NET SALES | L1: COGS
A2: 46190 | B2: 4800016012273 | C2: 0-144673 | D2: GREAT TASTE PREMIUM 50G | E2: 10 | F2: 47.73 | G2: 55 | I2: 550 | J2: 0 | K2: =H2+I2-J2 -> 550 | L2: =E2*F2 -> 477.3
A3: 46190 | B3: 4801668602034 | C3: 0-144673 | D3: DATU PUTI SOY SAUCE 200ML | E3: 15 | F3: 10 | G3: 12.5 | I3: 187.5 | J3: 0 | K3: =H3+I3-J3 -> 187.5 | L3: =E3*F3 -> 150
A4: 46190 | B4: 4800888285355 | C4: 0-144673 | D4: KNORR CHICKEN BROTH CUBE 10G 6+2 | E4: 3 | F4: 34.88 | G4: 40.25 | I4: 120.75 | J4: 0 | K4: =H4+I4-J4 -> 120.75 | L4: =E4*F4 -> 104.64
A5: 46190 | B5: 4800888607959 | C5: 0-144673 | D5: KNORR SHRIMP BROTH CUBE 10G | E5: 24 | F5: 6.02 | G5: 7.25 | I5: 174 | J5: 0 | K5: =H5+I5-J5 -> 174 | L5: =E5*F5 -> 144.48
A6: 46190 | B6: 4800888602725 | C6: 0-144673 | D6: KNORR PORK BROTH CUBE 10G | E6: 24 | F6: 6.02 | G6: 7.25 | I6: 174 | J6: 0 | K6: =H6+I6-J6 -> 174 | L6: =E6*F6 -> 144.48
A7: 46190 | B7: 4800888602732 | C7: 0-144673 | D7: KNORR BEEF BROTH CUBE 10G | E7: 24 | F7: 6.02 | G7: 7.25 | I7: 174 | J7: 0 | K7: =H7+I7-J7 -> 174 | L7: =E7*F7 -> 144.48
A8: 46190 | B8: 748485150079 | C8: 0-144673 | D8: COCO MAMA FRESH GATA 200ML | E8: 10 | F8: 32.86 | G8: 38 | I8: 380 | J8: 0 | K8: =H8+I8-J8 -> 380 | L8: =E8*F8 -> 328.6
A9: 46190 | B9: 748485150093 | C9: 0-144673 | D9: COCO MAMA FRESH GATA 400ML | E9: 6 | F9: 65.95 | G9: 76 | I9: 456 | J9: 0 | K9: =H9+I9-J9 -> 456 | L9: =E9*F9 -> 395.7
A10: 46190 | B10: 888123456781868 | C10: 0-144673 | D10: FAVORITO RIDGE&SHELL MACARONI 1/2 | E10: 10 | F10: 25.8 | G10: 29.75 | I10: 297.5 | J10: 0 | K10: =H10+I10-J10 -> 297.5 | L10: =E10*F10 -> 258
A11: 46190 | B11: 4800888207234 | C11: 0-144673 | D11: SUNSILK PINK (11+1) | E11: 5 | F11: 63.95 | G11: 73.75 | I11: 368.75 | J11: 0 | K11: =H11+I11-J11 -> 368.75 | L11: =E11*F11 -> 319.75
A12: 46190 | B12: 4800888194268 | C12: 0-144673 | D12: SUNSILK GREEN (11+1) | E12: 10 | F12: 63.95 | G12: 73.75 | I12: 737.5 | J12: 0 | K12: =H12+I12-J12 -> 737.5 | L12: =E12*F12 -> 639.5
A13: 46190 | B13: 4800528456282 | C13: 0-144673 | D13: HOBE BIHON 454G | E13: 12 | F13: 29.17 | G13: 33.75 | I13: 405 | J13: 0 | K13: =H13+I13-J13 -> 405 | L13: =E13*F13 -> 350.04
... A53: 46190 | B53: 750515017450 | C53: 0-144673 | D53: FITA CRACKERS 30GX10S | E53: 5 | F53: 56.5 | G53: 63 | I53: 315 | J53: 0 | K53: =H53+I53-J53 -> 315 | L53: =E53*F53 -> 282.5
A54: 46190 | B54: 750515018501 | C54: 0-144673 | D54: SKYFLAKES CRACKERS 25GX10S | E54: 5 | G54: 73.25 | I54: 366.25 | J54: 0 | K54: =H54+I54-J54 -> 366.25 | L54: =E54*F54 -> 0
A55: 46190 | B55: 4800818809880 | C55: 0-144673 | D55: VFRESH WINTER COOL GUM 165G | E55: 3 | F55: 34.27 | G55: 39.5 | I55: 118.5 | J55: 0 | K55: =H55+I55-J55 -> 118.5 | L55: =E55*F55 -> 102.81
A56: 46190 | B56: 4800818808302 | C56: 0-144673 | D56: FRUTOS ASSORTED SOFT CHEWY CANDIES 180G | E56: 2 | F56: 34.27 | G56: 39.5 | I56: 79 | J56: 0 | K56: =H56+I56-J56 -> 79 | L56: =E56*F56 -> 68.54
A57: 46190 | B57: 4800818810817 | C57: 0-144673 | D57: FRUTOS CHEWY SAMPALOK 175G | E57: 1 | F57: 34.27 | G57: 39.5 | I57: 39.5 | J57: 0 | K57: =H57+I57-J57 -> 39.5 | L57: =E57*F57 -> 34.27
A58: 46190 | B58: 4800818809712 | C58: 0-144673 | D58: CHAMPI CHOCOFILLED CHEWY CHOCOLATE CANDY 165G | E58: 3 | F58: 36.11 | G58: 41.75 | I58: 125.25 | J58: 0 | K58: =H58+I58-J58 -> 125.25 | L58: =E58*F58 -> 108.33
A59: 46190 | B59: 8935001727668 | C59: 0-144673 | D59: MENTOS MINT FLAVOR 50+5 PCS. | E59: 3 | F59: 38 | G59: 43.75 | I59: 131.25 | J59: 0 | K59: =H59+I59-J59 -> 131.25 | L59: =E59*F59 -> 114
A60: 46190 | B60: 4800016303081 | C60: 0-144673 | D60: MAXX DALANDAN ORANGE 200G | E60: 2 | F60: 38 | G60: 43.75 | I60: 87.5 | J60: 0 | K60: =H60+I60-J60 -> 87.5 | L60: =E60*F60 -> 76
A61: 46190 | B61: 4800016307010 | C61: 0-144673 | D61: MAXX EUCALYPTUS MENTHOL CANDY 200G | E61: 2 | F61: 38 | G61: 43.75 | I61: 87.5 | J61: 0 | K61: =H61+I61-J61 -> 87.5 | L61: =E61*F61 -> 76
A62: 46190 | B62: 4800818902017 | C62: 0-144673 | D62: LUVLOV BUDDY BERRY MILK PACK 15PCSX15G | E62: 1 | F62: 58.14 | G62: 67 | I62: 67 | J62: 0 | K62: =H62+I62-J62 -> 67 | L62: =E62*F62 -> 58.14
A63: 46190 | B63: 4800818809750 | C63: 0-144673 | D63: ICOOL MENTHOLATED GUM 182G | E63: 2 | F63: 34.27 | G63: 39.5 | I63: 79 | J63: 0 | K63: =H63+I63-J63 -> 79 | L63: =E63*F63 -> 68.54
A64: 46190 | B64: 8998666001726 | C64: 0-144673 | D64: KOPIKO BLANCA TWINPACK 52G | E64: 61 | F64: 12.66 | G64: 14.25 | I64: 869.25 | J64: 0 | K64: =H64+I64-J64 -> 869.25 | L64: =E64*F64 -> 772.26
A65: 46190 | B65: 748485401492 | C65: 0-144673 | D65: BIRCH TREE 33G | E65: 28 | F65: 7.85 | G65: 12 | I65: 336 | J65: 0 | K65: =H65+I65-J65 -> 336 | L65: =E65*F65 -> 219.8
A66: 46190 | B66: 4806505854416 | C66: 0-144673 | D66: CHICK BOY TEXAS SMOKED BBQ FLAVOR 100G | E66: 10 | F66: 17.65 | G66: 18.75 | I66: 187.5 | J66: 0 | K66: =H66+I66-J66 -> 187.5 | L66: =E66*F66 -> 176.5
... A113: 46190 | B113: 4800016012266 | C113: 0-144673 | D113: GREAT TASTE PREMIUM 25G | E113: 48 | F113: 24.35 | G113: 28 | I113: 1344 | J113: 0 | K113: =H113+I113-J113 -> 1344 | L113: =E113*F113 -> 1168.8
A114: 46190 | B114: 4800010012033 | C114: 0-144673 | D114: GREAT TASTE GRANULES 50G | E114: 2 | G114: 56.25 | I114: =E114*G114 -> 112.5 | J114: 0 | K114: =H114+I114-J114 -> 112.5 | L114: =E114*F114 -> 0
A115: 46190 | B115: 4800010012033 | C115: 0-144673 | D115: GREAT TASTE GRANULES 50G | E115: 4 | F115: 48.8 | G115: 56.25 | I115: =E115*G115 -> 225 | J115: 0 | K115: =H115+I115-J115 -> 225 | L115: =E115*F115 -> 195.2
A116: 46190 | B116: 4800016012280 | C116: 0-144673 | D116: GREAT TASTE PREMIUM 100G | E116: 10 | F116: 94.58 | G116: 109 | I116: 1090 | J116: 0 | K116: =H116+I116-J116 -> 1090 | L116: =E116*F116 -> 945.8
A117: 46190 | B117: 4800010012019 | C117: 0-144673 | D117: GREAT TASTE GRANULES 100G | E117: 6 | F117: 96.67 | G117: 111.25 | I117: 667.5 | J117: 0 | K117: =H117+I117-J117 -> 667.5 | L117: =E117*F117 -> 580.02
A118: 46190 | B118: 4807770271175 | C118: 0-144673 | D118: LM GO CUP BULALO 40G | E118: 3 | F118: 21.5 | G118: 24.75 | I118: 74.25 | J118: 0 | K118: =H118+I118-J118 -> 74.25 | L118: =E118*F118 -> 64.5
A119: 46190 | B119: 4807770273612 | C119: 0-144673 | D119: LM GO CUP SPICY BULALO 40G | E119: 2 | F119: 21.5 | G119: 24.75 | I119: 49.5 | J119: 0 | K119: =H119+I119-J119 -> 49.5 | L119: =E119*F119 -> 43
A120: 46190 | B120: 4807770271168 | C120: 0-144673 | D120: LM GO CUP BATCHOY 40G | E120: 3 | F120: 21.5 | G120: 24.75 | I120: 74.25 | J120: 0 | K120: =H120+I120-J120 -> 74.25 | L120: =E120*F120 -> 64.5
A121: 46190 | B121: 4807770273810 | C121: 0-144673 | D121: LM GO CUP SPICY BATCHOY 40G | E121: 3 | F121: 21.5 | G121: 24.75 | I121: 74.25 | J121: 0 | K121: =H121+I121-J121 -> 74.25 | L121: =E121*F121 -> 64.5
A122: 46190 | B122: 4800016561498 | C122: 0-144673 | D122: NISSIN CUP NOODLES CHEESY SEAFOOD 50G | E122: 6 | F122: 23.32 | G122: 27 | I122: 162 | J122: 0 | K122: =H122+I122-J122 -> 162 | L122: =E122*F122 -> 139.92
A123: 46190 | B123: 4800016561184 | C123: 0-144673 | D123: NISSIN CUP NOODLES CREAMY SEAFOOD 45G | E123: 6 | F123: 20.55 | G123: 23.75 | I123: 142.5 | J123: 0 | K123: =H123+I123-J123 -> 142.5 | L123: =E123*F123 -> 123.3
A124: 46190 | B124: 4800016551857 | C124: 0-144673 | D124: NISSIN CUP NOODLES SPICY SEAFOOD 40G | E124: 6 | F124: 21.17 | G124: 24.5 | I124: 147 | J124: 0 | K124: =H124+I124-J124 -> 147 | L124: =E124*F124 -> 127.02
A125: 46190 | B125: 4800016560927 | C125: 0-144673 | D125: NISSIN CUP NOODLES SPICY HOT BEEF 45G | E125: 6 | F125: 21.17 | G125: 24.5 | I125: 147 | J125: 0 | K125: =H125+I125-J125 -> 147 | L125: =E125*F125 -> 127.02
...

Sheet PURCHASES+
A1: PURCHASES
A2: =PRINTING!B2 -> AS OF JUNE 2026
A3: DATE | B3: PARTICULARS | C3: BARCODE | D3: CV No. | E3: DESCRIPTION | F3: QTY | G3: UNIT | H3: UNIT PRICE | I3: PURCHASES
A4: 46182 | B4: WING-AN MARKETING INC. | C4: 4801234107727 | D4: 2002 | E4: BAYGON MULTI INSECT KILLER ODORLESS 500ML | F4: 8 | G4: PC/S | H4: 360.65 | I4: =F4*H4 -> 2885.2
A5: 46182 | B5: WING-AN MARKETING INC. | C5: 4801234107826 | D5: 2002 | E5: BAYGON SHIELD PROTECTOR 500ML | F5: 8 | G5: PC/S | H5: 333.8 | I5: =F5*H5 -> 2670.4
A6: 46182 | B6: WING-AN MARKETING INC. | C6: 4800034017243 | D6: 2002 | E6: HAPEE EXPLOSIVE MENTHOL RED 55G | F6: 36 | G6: PC/S | H6: 10.95 | I6: =F6*H6 -> 394.2
A7: 46182 | B7: WING-AN MARKETING INC. | C7: 9780201379617 | D7: 2002 | E7: HOME RECIPE - PEANUT BUTTER 560G | F7: 16 | G7: PC/S | H7: 132.8 | I7: =F7*H7 -> 2124.8
A8: 46182 | B8: PROS MARKETING & PHARMAPLUS DRUGSTORE | C8: 4804888804868 | D8: 2003 | E8: MAMA SITAS OYSTER SAUCE 4.2KG | F8: 1 | G8: PC/S | H8: 723.8 | I8: =F8*H8 -> 723.8
A9: 46182 | B9: PROS MARKETING & PHARMAPLUS DRUGSTORE | C9: 4807770100536 | D9: 2003 | E9: BINGO ORANGE 280G | F9: 7 | G9: PC/S | H9: 59.5 | I9: =F9*H9 -> 416.5
A10: 46182 | B10: PROS MARKETING & PHARMAPLUS DRUGSTORE | C10: 4807770100963 | D10: 2003 | E10: NISSIN EGGNOG COOKIES 18G PACK | F10: 6 | G10: PC/S | H10: 58.8 | I10: =F10*H10 -> 352.8
A11: 46182 | B11: PROS MARKETING & PHARMAPLUS DRUGSTORE | C11: 4807770122712 | D11: 2003 | E11: MONDE CHOCO PUFF 240G | F11: 3 | G11: PC/S | H11: 81.5 | I11: =F11*H11 -> 244.5
A12: 46182 | B12: PROS MARKETING & PHARMAPLUS DRUGSTORE | C12: 4807770120770 | D12: 2003 | E12: SUMO MINI COOKIES&CREAM 10X20G | F12: 6 | G12: PC/S | H12: 58.95 | I12: =F12*H12 -> 353.7
A13: 46182 | B13: PROS MARKETING & PHARMAPLUS DRUGSTORE | C13: 4807770121661 | D13: 2003 | E13: MONDE SPECIAL MAMON CLASSIC SAVER PACK 12X43G | F13: 3 | G13: PC/S | H13: 177.9 | I13: =F13*H13 -> 533.7
A14: 46183 | B14: IBEST CORPORATION | C14: 4800024575722 | D14: 2004 | E14: DM PARTY COMBO PCK SWEET STYLE | F14: 16 | G14: PC/S | H14: 140 | I14: =F14*H14 -> 2240
A15: 46183 | B15: ACRO DISTRIBUTION AND LOGISTICS, INC. | C15: 4808680021805 | D15: 2005 | E15: LADYS CHOICE REAL MAYONNAISE 3.5L | F15: 4 | G15: PC/S | H15: 1160.3525 | I15: =F15*H15 -> 4641.41
... A44: 46184 | B44: CHIP ACCENDO ENTERPRISES INC. | C44: 4806533327128 | D44: 2007 | E44: DELFI TREASURES GOLDEN ALMOND 36G 2+1 | F44: 8 | G44: PC/S | H44: 109.965 | I44: =F44*H44 -> 879.72
A45: 46191 | B45: CYNTHIA CABRERA | C45: 999055 | D45: 2012 | E45: CONVIE SWIVEL CHAIR | F45: 4 | G45: PC/S | H45: 3500 | I45: =F45*H45 -> 14000
A46: 46191 | B46: PADSA ENTERPRISES CORPORATION | C46: 4806500802221 | D46: 2013 | E46: MAGIC PANTS PULL-UPS MEDIUM 10PCS | F46: 12 | G46: PACK/S | H46: 60.28 | I46: =F46*H46 -> 723.36
A47: 46191 | B47: PADSA ENTERPRISES CORPORATION | C47: 4806500802320 | D47: 2013 | E47: MAGIC PANTS PULL-UPS LARGE 10S | F47: 12 | G47: PACK/S | H47: 65.77 | I47: =F47*H47 -> 789.24
A48: 46191 | B48: PADSA ENTERPRISES CORPORATION | C48: 4806500802429 | D48: 2013 | E48: MAGIC PANTS PULL-UPS XL 10S | F48: 12 | G48: PACK/S | H48: 71.25 | I48: =F48*H48 -> 855
A49: 46191 | B49: PADSA ENTERPRISES CORPORATION | C49: 4806500802658 | D49: 2013 | E49: MAGIC PANTS DIAPERS PULL-UPS 30PCS-XXXL | F49: 4 | G49: PC/S | H49: 261.51 | I49: =F49*H49 -> 1046.04
A50: 46191 | B50: PADSA ENTERPRISES CORPORATION | C50: 4806500802252 | D50: 2013 | E50: MAGIC PANTS DIAPERS PULL-UPS 30PCS-MEDIUM | F50: 4 | G50: PC/S | H50: 180.86 | I50: =F50*H50 -> 723.44
A51: 46191 | B51: PADSA ENTERPRISES CORPORATION | C51: 4806500802351 | D51: 2013 | E51: MAGIC PANTS DIAPERS PULL-UPS 30PCS-LARGE | F51: 4 | G51: PC/S | H51: 197.3 | I51: =F51*H51 -> 789.2
A52: 46191 | B52: PADSA ENTERPRISES CORPORATION | C52: 4806500802450 | D52: 2013 | E52: MAGIC PANTS DIAPERS PULL-UPS 30S-XL | F52: 4 | G52: PC/S | H52: 213.74 | I52: =F52*H52 -> 854.96
A53: 46191 | B53: PADSA ENTERPRISES CORPORATION | C53: 4806500802559 | D53: 2013 | E53: MAGIC PANTS DIAPERS PULL-UPS 30PCS-XXL | F53: 4 | G53: PC/S | H53: 230.19 | I53: =F53*H53 -> 920.76
A54: 46191 | B54: PADSA ENTERPRISES CORPORATION | C54: 4806500802627 | D54: 2013 | E54: MAGIC PANTS PULL-UPS 10S-XXXL | F54: 12 | G54: PACK/S | H54: 87.17 | I54: =F54*H54 -> 1046.04
A55: 46191 | B55: PADSA ENTERPRISES CORPORATION | C55: 4806506150258 | D55: 2013 | E55: SOFT N WHITE EASY PACK 2PLY 40PULLS | F55: 24 | G55: PACK/S | H55: 8.75 | I55: =F55*H55 -> 210
A56: 46191 | B56: PADSA ENTERPRISES CORPORATION | C56: 4806506151118 | D56: 2013 | E56: SOFT N WHITE TRAVEL PACK 2PLY 50PULLS | F56: 24 | G56: PC/S | H56: 14.5 | I56: =F56*H56 -> 348
A57: 46192 | B57: AS-LS DISTRIBUTOR | C57: 4806502720615 | D57: 2016 | E57: GAR CLASSIC WHITE BREAD 600G REGULAR SLICE | F57: 3 | G57: PC/S | H57: 84.8 | I57: =F57*H57 -> 254.4
... A132: 46203 | B132: EDELIAS MARKETING | C132: 4806526070093 | D132: 2027 | E132: HELLO KITTY SOFT CANDY 30PCS | F132: 10 | G132: PC/S | H132: 25 | I132: =F132*H132 -> 250
F133: =SUM(F4:F132) -> 4042 | H133: =SUM(H4:H132) -> 15456.593 | I133: =SUM(I4:I132) -> 125669.26

Sheet RETAIL+
A1: RETAIL
A2: =PRINTING!B2 -> AS OF JUNE 2026
A3: DATE | B3: SUPPLIER | C3: BARCODE | D3: PARTICULAR | E3: QTY | F3: UNIT
A4: 46178 | B4: KIMBERLIN ENTERPRISES | C4: 888123456781258 | D4: OTC MAXX CHERRY | E4: 50 | F4: PCS
A5: 46178 | B5: KIMBERLIN ENTERPRISES | C5: 888123456781549 | D5: OTC DYNAMITE CHOCO MINT RETAIL | E5: 50 | F5: PCS
A6: 46178 | B6: PROS MARKETING & PHARMAPLUS DRUGSTORE | C6: 75051030176 | D6: OTC SKYFLAKES ONION & CHIVES | E6: 10 | F6: PCS
A7: 46178 | B7: PROS MARKETING & PHARMAPLUS DRUGSTORE | C7: 4807770121326 | D7: OTC MONDE SPECIAL MAMON CLASSIC 43G | E7: 12 | F7: PCS
A8: 46182 | B8: PROS MARKETING & PHARMAPLUS DRUGSTORE | C8: 750515030152 | D8: OTC SKYFLAKES GARLIC 25G | E8: 10 | F8: PCS
A9: 46182 | B9: PROS MARKETING & PHARMAPLUS DRUGSTORE | C9: 750515030176 | D9: OTC SKYFLAKES ONION & CHIVES 25G | E9: 10 | F9: PCS
A10: 46182 | B10: PROS MARKETING & PHARMAPLUS DRUGSTORE | C10: 750515031067 | D10: OTC SKYFLAKES SWEET BUTTER 30G | E10: 10 | F10: PCS
A11: 46182 | B11: PROS MARKETING & PHARMAPLUS DRUGSTORE | C11: 750515031029 | D11: OTC SKYFLAKES TSOKOLATE | E11: 10 | F11: PCS
A12: 46183 | B12: AS-LS DISTRIBUTOR | C12: 4806502720172 | D12: GAR BUTTER TOAST 2-SLICE PACK 50G | E12: 10 | F12: PCS
A13: 46190 | B13: EDELIAS MARKETING | C13: 4800116099006 | D13: OTC BUTTER CREAM ENSAYMADA 25G | E13: 10 | F13: PCS
A14: 46190 | B14: EDELIAS MARKETING | C14: 4800116077004 | D14: OTC BUTTER CREAM CHOCOLATE CRACKERS 25G | E14: 10 | F14: PCS
A15: 46190 | B15: EDELIAS MARKETING | C15: 888123456782039 | D15: OTC SUPERLAMIG PEPPERMINT | E15: 50 | F15: PCS
... A20: 46197 | B20: PROS MARKETING & PHARMAPLUS DRUGSTORE | C20: 750515031043 | D20: OTC SKYFLAKES CONDENSADA | E20: 10 | F20: PCS
A21: ADJUSTMENT SHORT
C22: 4800888158925 | D22: REXONA WOMEN DEO-ROLL ON POWDER DRY 25ML | E22: 1
C23: 00006 | D23: CONVIE COKE IN CAN ORIGINAL 320ML | E23: 1
C24: 4800016087608 | D24: MAGIC CREAM BUTTER 28GX10 | E24: 1
C25: 888123456781858 | D25: OTC DYNAMITE MELON MINT RETAIL | E25: 11
C26: 4800142118290 | D26: EMPERADOR DOUBLE LIGHT 1L | E26: 48
C27: 4800067600474 | D27: ALBATROSS KIWI 50G | E27: 1
C28: 4902430381765 | D28: SAFEGUARD IVORY WHITE CARE 135G | E28: 1
C29: 4800034017441 | D29: HAPEE TOOTPASTE BLUE CHILL 55G | E29: 4
E30: =SUM(E4:E29) -> 416

Sheet PULL OUT-
A1: PULL OUT
A2: =PRINTING!B2 -> AS OF JUNE 2026
A3: RETAIL
A4: DATE | B4: SUPPLIER | C4: BARCODE | D4: PARTICULAR | E4: QTY | F4: UNIT
A5: 46178 | B5: KIMBERLIN ENTERPRISES | C5: 4800016304019 | D5: MAXX CHERRY 200G | E5: 1 | F5: PACK
A6: 46178 | B6: KIMBERLIN ENTERPRISES | C6: 4800016307041 | D6: DYNAMITE CHOCO MINT CANDY 200G | E6: 1 | F6: PACK
A7: 46178 | B7: PROS MARKETING & PHARMAPLUS DRUGSTORE | C7: 750515030251 | D7: SKYFLAKES ONION& CHIVES 10S | E7: 1 | F7: PACK
A8: 46178 | B8: PROS MARKETING & PHARMAPLUS DRUGSTORE | C8: 4807770121661 | D8: MONDE SPECIAL MAMON CLASSIC SAVER PACK 12X43G | E8: 1 | F8: PACK
A9: 46182 | B9: PROS MARKETING & PHARMAPLUS DRUGSTORE | C9: 750515030206 | D9: SKYFLAKES GARLIC 10S 250G | E9: 1 | F9: PACK
A10: 46182 | B10: PROS MARKETING & PHARMAPLUS DRUGSTORE | C10: 750515030251 | D10: SKYFLAKES ONION& CHIVES 10S | E10: 1 | F10: PACK
A11: 46182 | B11: PROS MARKETING & PHARMAPLUS DRUGSTORE | C11: 750515031555 | D11: SKYFLAKES MANTIKILYA 30GX10S | E11: 1 | F11: PACK
A12: 46182 | B12: PROS MARKETING & PHARMAPLUS DRUGSTORE | C12: 750515031517 | D12: SKYFLAKES TSOKOLATE 30GX10S | E12: 1 | F12: PACK
A13: 46183 | B13: AS-LS DISTRIBUTOR | C13: 4806502720189 | D13: GAR BUTTER TOAST 2-SLICE PACK 50GX10 | E13: 1 | F13: PACK
A14: 46190 | B14: EDELIAS MARKETING | C14: 4800116099020 | D14: BUTTER CREAM ENSAYMADA CRACKERS 10X25G | E14: 1 | F14: PACK
A15: 46190 | B15: EDELIAS MARKETING | C15: 4800116077028 | D15: BUTTER CREAM CHOCOLATE CRACKERS 10X25G | E15: 1 | F15: PACK
A16: 46190 | B16: EDELIAS MARKETING | C16: 4800620110051 | D16: SUPERLAMIG CANDY | E16: 1 | F16: PACK
... A21: 46197 | B21: PROS MARKETING & PHARMAPLUS DRUGSTORE | C21: 750515030206 | D21: SKYFLAKES GARLIC 10S 250G | E21: 1 | F21: PACK
A23: PULL OUR BAD ORDER | C23: ACTUAL
A24: 46178 | B24: WING-AN MARKETING INC. | C24: 4801234108021 | D24: BAYGON MULTI INSECT KILLER KILLING ACTION 500ML | E24: 1
C25: 4801234108229 | D25: BAYGON MULTI INSECT KILLER WATERBASED 500ML | E25: 1
C26: 4801234107727 | D26: BAYGON MULTI INSECT KILLER ODORLESS 500ML | E26: 4
C27: 4801234107826 | D27: BAYGON SHIELD PROTECTOR 500ML | E27: 5
A28: 46182 | B28: AS-LS DISTRIBUTOR | C28: 4806502721452 | D28: GAR HIGH FIBER WHEAT BREAD 400G | E28: 1
C29: 4806502720165 | D29: GAR DOUBLE DELIGHTS (UBE & CHEESE) 400G | E29: 1
C30: 4806502720080 | D30: GAR PREMIUM PANDESAL 350G | E30: 1
C31: 4806502726907 | D31: GAR NEUBAKE CLASSIC WHITE BREAD SUPER SLICE 300G | E31: 2
C32: 4806502725726 | D32: GAR SOFT DELIGHT PANDESAL 300G | E32: 1
C33: 4806502720080 | D33: GAR PREMIUM PANDESAL 350G | E33: 1
C34: 4806502726914 | D34: GAR NEUBAKE WHEATEN BREAD SUPER SLICE 300G | E34: 1
B35: ROVEN 168 CORP | C35: 8851932478502 | D35: WALLS BITES STRAW YOGHURT 14G | E35: 9
C36: 4800086044372 | D36: SEL BDAY BASO CHOCO 400ML | E36: 2
C37: 4800086047472 | D37: SEL BOOM BOOM COOKIES & CREAM 60ML | E37: 7
C38: 4800086045751 | D38: SEL BOOM BOOM CHOCOLATE 60ML | E38: 5
C39: 4800086045676 | D39: SEL CORNETTO DISC WHITE CHOCO COOKIES & CREAM 115ML | E39: 14
C40: 4800086046482 | D40: SEL CORNETTO DISC BLACK CHOCO COOKIE 115ML | E40: 20
C41: 4800086134325 | D41: SEL CORNETTO CLASSIC CHOCO 110ML | E41: 29
C42: 4800086043306 | D42: SEL CORNETTO COOKIES & DREAM 110ML | E42: 6
C43: 4800086034670 | D43: SEL CORNETTO VANILLA 110ML | E43: 16
C44: 4800086049452 | D44: SELECTA COOKIES N CREAM 100ML | E44: 12
C45: 8999999035624 | D45: MAGNUM MINI VANILLA CLASSIC 45ML | E45: 36
...
